/*
 *** MADE BY MITHION'S .SCHEMATIC TO JAVA CONVERTING TOOLv0.1 ***
 */

package techguy.mods.undead.common;
import java.util.Random;

import net.minecraft.block.Block;
import net.minecraft.world.World;
import net.minecraft.world.gen.feature.WorldGenerator;

public class ModUndeadWorldGenJackBoat extends WorldGenerator
{
	public ModUndeadWorldGenJackBoat() { }

	public boolean generate(World world, Random rand, int i, int j, int k) 
	{
		if(world.getBlockId(i, j - 1, k) == Block.waterStill.blockID && world.getBlockId(i, j, k) == 0)
		{
		world.setBlock(i + 0, j + 10, k + 45, 44);
		world.setBlockMetadata(i + 0, j + 10, k + 45, 10);
		world.setBlock(i + 0, j + 10, k + 46, 44);
		world.setBlockMetadata(i + 0, j + 10, k + 46, 10);
		world.setBlock(i + 0, j + 10, k + 47, 44);
		world.setBlockMetadata(i + 0, j + 10, k + 47, 10);
		world.setBlock(i + 0, j + 10, k + 48, 44);
		world.setBlockMetadata(i + 0, j + 10, k + 48, 10);
		world.setBlock(i + 0, j + 10, k + 49, 44);
		world.setBlockMetadata(i + 0, j + 10, k + 49, 10);
		world.setBlock(i + 0, j + 10, k + 50, 44);
		world.setBlockMetadata(i + 0, j + 10, k + 50, 10);
		world.setBlock(i + 0, j + 11, k + 44, 85);
		world.setBlock(i + 0, j + 11, k + 45, 85);
		world.setBlock(i + 0, j + 11, k + 46, 85);
		world.setBlock(i + 0, j + 11, k + 47, 85);
		world.setBlock(i + 0, j + 11, k + 48, 85);
		world.setBlock(i + 0, j + 11, k + 49, 85);
		world.setBlock(i + 0, j + 11, k + 50, 85);
		world.setBlock(i + 0, j + 11, k + 51, 85);
		world.setBlock(i + 0, j + 17, k + 40, 35);
		world.setBlockMetadata(i + 0, j + 17, k + 40, 13);
		world.setBlock(i + 0, j + 18, k + 39, 35);
		world.setBlockMetadata(i + 0, j + 18, k + 39, 13);
		world.setBlock(i + 0, j + 19, k + 38, 35);
		world.setBlockMetadata(i + 0, j + 19, k + 38, 13);
		world.setBlock(i + 0, j + 20, k + 38, 35);
		world.setBlockMetadata(i + 0, j + 20, k + 38, 13);
		world.setBlock(i + 0, j + 21, k + 39, 35);
		world.setBlockMetadata(i + 0, j + 21, k + 39, 13);
		world.setBlock(i + 0, j + 22, k + 39, 35);
		world.setBlockMetadata(i + 0, j + 22, k + 39, 13);
		world.setBlock(i + 0, j + 23, k + 40, 17);
		world.setBlockMetadata(i + 0, j + 23, k + 40, 3);
		world.setBlock(i + 1, j + 6, k + 29, 44);
		world.setBlockMetadata(i + 1, j + 6, k + 29, 10);
		world.setBlock(i + 1, j + 6, k + 30, 44);
		world.setBlockMetadata(i + 1, j + 6, k + 30, 10);
		world.setBlock(i + 1, j + 6, k + 31, 44);
		world.setBlockMetadata(i + 1, j + 6, k + 31, 10);
		world.setBlock(i + 1, j + 6, k + 32, 44);
		world.setBlockMetadata(i + 1, j + 6, k + 32, 10);
		world.setBlock(i + 1, j + 6, k + 33, 44);
		world.setBlockMetadata(i + 1, j + 6, k + 33, 10);
		world.setBlock(i + 1, j + 6, k + 34, 44);
		world.setBlockMetadata(i + 1, j + 6, k + 34, 10);
		world.setBlock(i + 1, j + 6, k + 35, 44);
		world.setBlockMetadata(i + 1, j + 6, k + 35, 10);
		world.setBlock(i + 1, j + 6, k + 36, 44);
		world.setBlockMetadata(i + 1, j + 6, k + 36, 10);
		world.setBlock(i + 1, j + 6, k + 37, 44);
		world.setBlockMetadata(i + 1, j + 6, k + 37, 10);
		world.setBlock(i + 1, j + 6, k + 38, 44);
		world.setBlockMetadata(i + 1, j + 6, k + 38, 10);
		world.setBlock(i + 1, j + 6, k + 39, 44);
		world.setBlockMetadata(i + 1, j + 6, k + 39, 10);
		world.setBlock(i + 1, j + 6, k + 40, 44);
		world.setBlockMetadata(i + 1, j + 6, k + 40, 10);
		world.setBlock(i + 1, j + 7, k + 28, 85);
		world.setBlock(i + 1, j + 7, k + 29, 85);
		world.setBlock(i + 1, j + 7, k + 30, 85);
		world.setBlock(i + 1, j + 7, k + 31, 85);
		world.setBlock(i + 1, j + 7, k + 32, 85);
		world.setBlock(i + 1, j + 7, k + 33, 85);
		world.setBlock(i + 1, j + 7, k + 34, 85);
		world.setBlock(i + 1, j + 7, k + 35, 85);
		world.setBlock(i + 1, j + 7, k + 36, 85);
		world.setBlock(i + 1, j + 7, k + 37, 85);
		world.setBlock(i + 1, j + 7, k + 38, 85);
		world.setBlock(i + 1, j + 7, k + 39, 85);
		world.setBlock(i + 1, j + 7, k + 40, 85);
		world.setBlock(i + 1, j + 10, k + 38, 35);
		world.setBlockMetadata(i + 1, j + 10, k + 38, 13);
		world.setBlock(i + 1, j + 10, k + 44, 43);
		world.setBlockMetadata(i + 1, j + 10, k + 44, 2);
		world.setBlock(i + 1, j + 10, k + 45, 44);
		world.setBlockMetadata(i + 1, j + 10, k + 45, 2);
		world.setBlock(i + 1, j + 10, k + 46, 44);
		world.setBlockMetadata(i + 1, j + 10, k + 46, 2);
		world.setBlock(i + 1, j + 10, k + 47, 44);
		world.setBlockMetadata(i + 1, j + 10, k + 47, 2);
		world.setBlock(i + 1, j + 10, k + 48, 44);
		world.setBlockMetadata(i + 1, j + 10, k + 48, 2);
		world.setBlock(i + 1, j + 10, k + 49, 44);
		world.setBlockMetadata(i + 1, j + 10, k + 49, 2);
		world.setBlock(i + 1, j + 10, k + 50, 44);
		world.setBlockMetadata(i + 1, j + 10, k + 50, 2);
		world.setBlock(i + 1, j + 10, k + 51, 44);
		world.setBlockMetadata(i + 1, j + 10, k + 51, 10);
		world.setBlock(i + 1, j + 11, k + 38, 35);
		world.setBlockMetadata(i + 1, j + 11, k + 38, 13);
		world.setBlock(i + 1, j + 11, k + 44, 85);
		world.setBlock(i + 1, j + 11, k + 51, 85);
		world.setBlock(i + 1, j + 11, k + 52, 85);
		world.setBlock(i + 1, j + 12, k + 37, 35);
		world.setBlockMetadata(i + 1, j + 12, k + 37, 13);
		world.setBlock(i + 1, j + 13, k + 32, 35);
		world.setBlockMetadata(i + 1, j + 13, k + 32, 13);
		world.setBlock(i + 1, j + 13, k + 38, 35);
		world.setBlockMetadata(i + 1, j + 13, k + 38, 13);
		world.setBlock(i + 1, j + 14, k + 32, 35);
		world.setBlockMetadata(i + 1, j + 14, k + 32, 13);
		world.setBlock(i + 1, j + 14, k + 38, 35);
		world.setBlockMetadata(i + 1, j + 14, k + 38, 13);
		world.setBlock(i + 1, j + 15, k + 31, 35);
		world.setBlockMetadata(i + 1, j + 15, k + 31, 13);
		world.setBlock(i + 1, j + 15, k + 39, 17);
		world.setBlockMetadata(i + 1, j + 15, k + 39, 3);
		world.setBlock(i + 1, j + 16, k + 32, 35);
		world.setBlockMetadata(i + 1, j + 16, k + 32, 13);
		world.setBlock(i + 1, j + 17, k + 32, 35);
		world.setBlockMetadata(i + 1, j + 17, k + 32, 13);
		world.setBlock(i + 1, j + 17, k + 39, 35);
		world.setBlockMetadata(i + 1, j + 17, k + 39, 13);
		world.setBlock(i + 1, j + 18, k + 33, 17);
		world.setBlockMetadata(i + 1, j + 18, k + 33, 3);
		world.setBlock(i + 1, j + 18, k + 38, 35);
		world.setBlockMetadata(i + 1, j + 18, k + 38, 13);
		world.setBlock(i + 1, j + 19, k + 37, 35);
		world.setBlockMetadata(i + 1, j + 19, k + 37, 13);
		world.setBlock(i + 1, j + 20, k + 37, 35);
		world.setBlockMetadata(i + 1, j + 20, k + 37, 13);
		world.setBlock(i + 1, j + 21, k + 38, 35);
		world.setBlockMetadata(i + 1, j + 21, k + 38, 13);
		world.setBlock(i + 1, j + 22, k + 38, 35);
		world.setBlockMetadata(i + 1, j + 22, k + 38, 13);
		world.setBlock(i + 1, j + 23, k + 39, 17);
		world.setBlockMetadata(i + 1, j + 23, k + 39, 3);
		world.setBlock(i + 2, j + 3, k + 31, 5);
		world.setBlock(i + 2, j + 3, k + 32, 5);
		world.setBlock(i + 2, j + 3, k + 33, 5);
		world.setBlock(i + 2, j + 3, k + 34, 5);
		world.setBlock(i + 2, j + 3, k + 35, 5);
		world.setBlock(i + 2, j + 3, k + 36, 5);
		world.setBlock(i + 2, j + 3, k + 37, 5);
		world.setBlock(i + 2, j + 3, k + 38, 5);
		world.setBlock(i + 2, j + 3, k + 39, 5);
		world.setBlock(i + 2, j + 3, k + 40, 5);
		world.setBlock(i + 2, j + 3, k + 41, 5);
		world.setBlock(i + 2, j + 3, k + 42, 5);
		world.setBlock(i + 2, j + 3, k + 43, 5);
		world.setBlock(i + 2, j + 3, k + 44, 5);
		world.setBlock(i + 2, j + 3, k + 45, 5);
		world.setBlock(i + 2, j + 3, k + 46, 5);
		world.setBlock(i + 2, j + 3, k + 47, 5);
		world.setBlock(i + 2, j + 4, k + 31, 17);
		world.setBlockMetadata(i + 2, j + 4, k + 31, 3);
		world.setBlock(i + 2, j + 4, k + 32, 17);
		world.setBlockMetadata(i + 2, j + 4, k + 32, 3);
		world.setBlock(i + 2, j + 4, k + 33, 17);
		world.setBlock(i + 2, j + 4, k + 34, 17);
		world.setBlockMetadata(i + 2, j + 4, k + 34, 3);
		world.setBlock(i + 2, j + 4, k + 36, 17);
		world.setBlockMetadata(i + 2, j + 4, k + 36, 3);
		world.setBlock(i + 2, j + 4, k + 37, 17);
		world.setBlock(i + 2, j + 4, k + 38, 17);
		world.setBlockMetadata(i + 2, j + 4, k + 38, 3);
		world.setBlock(i + 2, j + 4, k + 40, 17);
		world.setBlockMetadata(i + 2, j + 4, k + 40, 3);
		world.setBlock(i + 2, j + 4, k + 41, 17);
		world.setBlock(i + 2, j + 4, k + 42, 17);
		world.setBlockMetadata(i + 2, j + 4, k + 42, 3);
		world.setBlock(i + 2, j + 4, k + 44, 17);
		world.setBlockMetadata(i + 2, j + 4, k + 44, 3);
		world.setBlock(i + 2, j + 4, k + 45, 17);
		world.setBlock(i + 2, j + 4, k + 46, 17);
		world.setBlockMetadata(i + 2, j + 4, k + 46, 3);
		world.setBlock(i + 2, j + 4, k + 47, 17);
		world.setBlockMetadata(i + 2, j + 4, k + 47, 3);
		world.setBlock(i + 2, j + 4, k + 48, 17);
		world.setBlockMetadata(i + 2, j + 4, k + 48, 3);
		world.setBlock(i + 2, j + 5, k + 29, 5);
		world.setBlock(i + 2, j + 5, k + 30, 5);
		world.setBlock(i + 2, j + 5, k + 31, 5);
		world.setBlock(i + 2, j + 5, k + 32, 5);
		world.setBlock(i + 2, j + 5, k + 33, 5);
		world.setBlock(i + 2, j + 5, k + 34, 5);
		world.setBlock(i + 2, j + 5, k + 35, 5);
		world.setBlock(i + 2, j + 5, k + 36, 5);
		world.setBlock(i + 2, j + 5, k + 37, 5);
		world.setBlock(i + 2, j + 5, k + 38, 5);
		world.setBlock(i + 2, j + 5, k + 39, 5);
		world.setBlock(i + 2, j + 5, k + 40, 5);
		world.setBlock(i + 2, j + 5, k + 41, 5);
		world.setBlock(i + 2, j + 5, k + 42, 5);
		world.setBlock(i + 2, j + 5, k + 43, 5);
		world.setBlock(i + 2, j + 5, k + 44, 5);
		world.setBlock(i + 2, j + 5, k + 45, 5);
		world.setBlock(i + 2, j + 5, k + 46, 5);
		world.setBlock(i + 2, j + 5, k + 47, 5);
		world.setBlock(i + 2, j + 5, k + 48, 5);
		world.setBlock(i + 2, j + 5, k + 49, 53);
		world.setBlockMetadata(i + 2, j + 5, k + 49, 7);
		world.setBlock(i + 2, j + 6, k + 26, 44);
		world.setBlockMetadata(i + 2, j + 6, k + 26, 10);
		world.setBlock(i + 2, j + 6, k + 27, 44);
		world.setBlockMetadata(i + 2, j + 6, k + 27, 10);
		world.setBlock(i + 2, j + 6, k + 28, 44);
		world.setBlockMetadata(i + 2, j + 6, k + 28, 10);
		world.setBlock(i + 2, j + 6, k + 29, 44);
		world.setBlockMetadata(i + 2, j + 6, k + 29, 2);
		world.setBlock(i + 2, j + 6, k + 30, 44);
		world.setBlockMetadata(i + 2, j + 6, k + 30, 2);
		world.setBlock(i + 2, j + 6, k + 31, 44);
		world.setBlockMetadata(i + 2, j + 6, k + 31, 2);
		world.setBlock(i + 2, j + 6, k + 32, 44);
		world.setBlockMetadata(i + 2, j + 6, k + 32, 2);
		world.setBlock(i + 2, j + 6, k + 33, 44);
		world.setBlockMetadata(i + 2, j + 6, k + 33, 2);
		world.setBlock(i + 2, j + 6, k + 34, 44);
		world.setBlockMetadata(i + 2, j + 6, k + 34, 2);
		world.setBlock(i + 2, j + 6, k + 35, 44);
		world.setBlockMetadata(i + 2, j + 6, k + 35, 2);
		world.setBlock(i + 2, j + 6, k + 36, 44);
		world.setBlockMetadata(i + 2, j + 6, k + 36, 2);
		world.setBlock(i + 2, j + 6, k + 37, 44);
		world.setBlockMetadata(i + 2, j + 6, k + 37, 2);
		world.setBlock(i + 2, j + 6, k + 38, 44);
		world.setBlockMetadata(i + 2, j + 6, k + 38, 2);
		world.setBlock(i + 2, j + 6, k + 39, 44);
		world.setBlockMetadata(i + 2, j + 6, k + 39, 2);
		world.setBlock(i + 2, j + 6, k + 40, 5);
		world.setBlock(i + 2, j + 6, k + 41, 17);
		world.setBlockMetadata(i + 2, j + 6, k + 41, 3);
		world.setBlock(i + 2, j + 6, k + 42, 17);
		world.setBlockMetadata(i + 2, j + 6, k + 42, 3);
		world.setBlock(i + 2, j + 6, k + 43, 17);
		world.setBlockMetadata(i + 2, j + 6, k + 43, 3);
		world.setBlock(i + 2, j + 6, k + 44, 17);
		world.setBlockMetadata(i + 2, j + 6, k + 44, 3);
		world.setBlock(i + 2, j + 6, k + 45, 17);
		world.setBlockMetadata(i + 2, j + 6, k + 45, 3);
		world.setBlock(i + 2, j + 6, k + 46, 17);
		world.setBlockMetadata(i + 2, j + 6, k + 46, 3);
		world.setBlock(i + 2, j + 6, k + 47, 17);
		world.setBlockMetadata(i + 2, j + 6, k + 47, 3);
		world.setBlock(i + 2, j + 6, k + 48, 17);
		world.setBlockMetadata(i + 2, j + 6, k + 48, 3);
		world.setBlock(i + 2, j + 6, k + 49, 17);
		world.setBlockMetadata(i + 2, j + 6, k + 49, 3);
		world.setBlock(i + 2, j + 6, k + 50, 17);
		world.setBlockMetadata(i + 2, j + 6, k + 50, 3);
		world.setBlock(i + 2, j + 7, k + 25, 85);
		world.setBlock(i + 2, j + 7, k + 26, 85);
		world.setBlock(i + 2, j + 7, k + 27, 85);
		world.setBlock(i + 2, j + 7, k + 28, 85);
		world.setBlock(i + 2, j + 7, k + 40, 85);
		world.setBlock(i + 2, j + 7, k + 41, 85);
		world.setBlock(i + 2, j + 7, k + 42, 17);
		world.setBlockMetadata(i + 2, j + 7, k + 42, 3);
		world.setBlock(i + 2, j + 7, k + 43, 17);
		world.setBlockMetadata(i + 2, j + 7, k + 43, 3);
		world.setBlock(i + 2, j + 7, k + 44, 17);
		world.setBlockMetadata(i + 2, j + 7, k + 44, 3);
		world.setBlock(i + 2, j + 7, k + 45, 17);
		world.setBlockMetadata(i + 2, j + 7, k + 45, 3);
		world.setBlock(i + 2, j + 7, k + 46, 5);
		world.setBlock(i + 2, j + 7, k + 47, 5);
		world.setBlock(i + 2, j + 7, k + 48, 17);
		world.setBlockMetadata(i + 2, j + 7, k + 48, 3);
		world.setBlock(i + 2, j + 7, k + 49, 102);
		world.setBlock(i + 2, j + 7, k + 50, 5);
		world.setBlock(i + 2, j + 8, k + 41, 85);
		world.setBlock(i + 2, j + 8, k + 42, 85);
		world.setBlock(i + 2, j + 8, k + 43, 17);
		world.setBlockMetadata(i + 2, j + 8, k + 43, 3);
		world.setBlock(i + 2, j + 8, k + 44, 17);
		world.setBlockMetadata(i + 2, j + 8, k + 44, 3);
		world.setBlock(i + 2, j + 8, k + 45, 17);
		world.setBlockMetadata(i + 2, j + 8, k + 45, 3);
		world.setBlock(i + 2, j + 8, k + 46, 5);
		world.setBlock(i + 2, j + 8, k + 47, 5);
		world.setBlock(i + 2, j + 8, k + 48, 17);
		world.setBlockMetadata(i + 2, j + 8, k + 48, 3);
		world.setBlock(i + 2, j + 8, k + 49, 102);
		world.setBlock(i + 2, j + 8, k + 50, 5);
		world.setBlock(i + 2, j + 9, k + 42, 85);
		world.setBlock(i + 2, j + 9, k + 43, 85);
		world.setBlock(i + 2, j + 9, k + 44, 17);
		world.setBlockMetadata(i + 2, j + 9, k + 44, 3);
		world.setBlock(i + 2, j + 9, k + 45, 17);
		world.setBlockMetadata(i + 2, j + 9, k + 45, 3);
		world.setBlock(i + 2, j + 9, k + 46, 5);
		world.setBlock(i + 2, j + 9, k + 47, 5);
		world.setBlock(i + 2, j + 9, k + 48, 17);
		world.setBlockMetadata(i + 2, j + 9, k + 48, 3);
		world.setBlock(i + 2, j + 9, k + 49, 17);
		world.setBlockMetadata(i + 2, j + 9, k + 49, 3);
		world.setBlock(i + 2, j + 9, k + 50, 17);
		world.setBlockMetadata(i + 2, j + 9, k + 50, 3);
		world.setBlock(i + 2, j + 10, k + 38, 35);
		world.setBlockMetadata(i + 2, j + 10, k + 38, 13);
		world.setBlock(i + 2, j + 10, k + 43, 85);
		world.setBlock(i + 2, j + 10, k + 44, 85);
		world.setBlock(i + 2, j + 10, k + 51, 44);
		world.setBlockMetadata(i + 2, j + 10, k + 51, 2);
		world.setBlock(i + 2, j + 10, k + 52, 44);
		world.setBlockMetadata(i + 2, j + 10, k + 52, 10);
		world.setBlock(i + 2, j + 11, k + 38, 35);
		world.setBlockMetadata(i + 2, j + 11, k + 38, 13);
		world.setBlock(i + 2, j + 11, k + 44, 85);
		world.setBlock(i + 2, j + 11, k + 52, 85);
		world.setBlock(i + 2, j + 11, k + 53, 85);
		world.setBlock(i + 2, j + 12, k + 37, 35);
		world.setBlockMetadata(i + 2, j + 12, k + 37, 13);
		world.setBlock(i + 2, j + 13, k + 32, 35);
		world.setBlockMetadata(i + 2, j + 13, k + 32, 13);
		world.setBlock(i + 2, j + 13, k + 38, 35);
		world.setBlockMetadata(i + 2, j + 13, k + 38, 13);
		world.setBlock(i + 2, j + 14, k + 32, 35);
		world.setBlockMetadata(i + 2, j + 14, k + 32, 13);
		world.setBlock(i + 2, j + 14, k + 38, 35);
		world.setBlockMetadata(i + 2, j + 14, k + 38, 13);
		world.setBlock(i + 2, j + 15, k + 31, 35);
		world.setBlockMetadata(i + 2, j + 15, k + 31, 13);
		world.setBlock(i + 2, j + 15, k + 39, 17);
		world.setBlockMetadata(i + 2, j + 15, k + 39, 3);
		world.setBlock(i + 2, j + 16, k + 32, 35);
		world.setBlockMetadata(i + 2, j + 16, k + 32, 13);
		world.setBlock(i + 2, j + 17, k + 32, 35);
		world.setBlockMetadata(i + 2, j + 17, k + 32, 13);
		world.setBlock(i + 2, j + 17, k + 39, 35);
		world.setBlockMetadata(i + 2, j + 17, k + 39, 13);
		world.setBlock(i + 2, j + 18, k + 33, 17);
		world.setBlockMetadata(i + 2, j + 18, k + 33, 3);
		world.setBlock(i + 2, j + 18, k + 38, 35);
		world.setBlockMetadata(i + 2, j + 18, k + 38, 13);
		world.setBlock(i + 2, j + 19, k + 37, 35);
		world.setBlockMetadata(i + 2, j + 19, k + 37, 13);
		world.setBlock(i + 2, j + 20, k + 37, 35);
		world.setBlockMetadata(i + 2, j + 20, k + 37, 13);
		world.setBlock(i + 2, j + 21, k + 38, 35);
		world.setBlockMetadata(i + 2, j + 21, k + 38, 13);
		world.setBlock(i + 2, j + 22, k + 38, 35);
		world.setBlockMetadata(i + 2, j + 22, k + 38, 13);
		world.setBlock(i + 2, j + 23, k + 39, 17);
		world.setBlockMetadata(i + 2, j + 23, k + 39, 3);
		world.setBlock(i + 3, j + 2, k + 31, 5);
		world.setBlock(i + 3, j + 2, k + 32, 53);
		world.setBlockMetadata(i + 3, j + 2, k + 32, 1);
		world.setBlock(i + 3, j + 2, k + 33, 5);
		world.setBlock(i + 3, j + 2, k + 34, 53);
		world.setBlockMetadata(i + 3, j + 2, k + 34, 1);
		world.setBlock(i + 3, j + 2, k + 35, 5);
		world.setBlock(i + 3, j + 2, k + 36, 53);
		world.setBlockMetadata(i + 3, j + 2, k + 36, 1);
		world.setBlock(i + 3, j + 2, k + 37, 5);
		world.setBlock(i + 3, j + 2, k + 38, 53);
		world.setBlockMetadata(i + 3, j + 2, k + 38, 1);
		world.setBlock(i + 3, j + 2, k + 39, 5);
		world.setBlock(i + 3, j + 2, k + 40, 53);
		world.setBlockMetadata(i + 3, j + 2, k + 40, 1);
		world.setBlock(i + 3, j + 2, k + 41, 5);
		world.setBlock(i + 3, j + 2, k + 42, 53);
		world.setBlockMetadata(i + 3, j + 2, k + 42, 1);
		world.setBlock(i + 3, j + 2, k + 43, 5);
		world.setBlock(i + 3, j + 2, k + 44, 53);
		world.setBlockMetadata(i + 3, j + 2, k + 44, 1);
		world.setBlock(i + 3, j + 2, k + 45, 5);
		world.setBlock(i + 3, j + 2, k + 46, 53);
		world.setBlockMetadata(i + 3, j + 2, k + 46, 1);
		world.setBlock(i + 3, j + 2, k + 47, 5);
		world.setBlock(i + 3, j + 3, k + 29, 5);
		world.setBlock(i + 3, j + 3, k + 30, 5);
		world.setBlock(i + 3, j + 3, k + 35, 5);
		world.setBlock(i + 3, j + 3, k + 39, 5);
		world.setBlock(i + 3, j + 3, k + 43, 5);
		world.setBlock(i + 3, j + 3, k + 48, 5);
		world.setBlock(i + 3, j + 4, k + 28, 17);
		world.setBlockMetadata(i + 3, j + 4, k + 28, 3);
		world.setBlock(i + 3, j + 4, k + 29, 17);
		world.setBlockMetadata(i + 3, j + 4, k + 29, 3);
		world.setBlock(i + 3, j + 4, k + 30, 17);
		world.setBlockMetadata(i + 3, j + 4, k + 30, 3);
		world.setBlock(i + 3, j + 4, k + 35, 23);
		world.setBlockMetadata(i + 3, j + 4, k + 35, 4);
		world.setBlock(i + 3, j + 4, k + 39, 23);
		world.setBlockMetadata(i + 3, j + 4, k + 39, 4);
		world.setBlock(i + 3, j + 4, k + 43, 23);
		world.setBlockMetadata(i + 3, j + 4, k + 43, 4);
		world.setBlock(i + 3, j + 4, k + 49, 17);
		world.setBlockMetadata(i + 3, j + 4, k + 49, 3);
		world.setBlock(i + 3, j + 5, k + 26, 5);
		world.setBlock(i + 3, j + 5, k + 27, 5);
		world.setBlock(i + 3, j + 5, k + 28, 5);
		world.setBlock(i + 3, j + 5, k + 29, 5);
		world.setBlock(i + 3, j + 5, k + 30, 5);
		world.setBlock(i + 3, j + 5, k + 31, 44);
		world.setBlockMetadata(i + 3, j + 5, k + 31, 10);
		world.setBlock(i + 3, j + 5, k + 32, 44);
		world.setBlockMetadata(i + 3, j + 5, k + 32, 10);
		world.setBlock(i + 3, j + 5, k + 33, 5);
		world.setBlock(i + 3, j + 5, k + 34, 5);
		world.setBlock(i + 3, j + 5, k + 35, 44);
		world.setBlockMetadata(i + 3, j + 5, k + 35, 10);
		world.setBlock(i + 3, j + 5, k + 36, 44);
		world.setBlockMetadata(i + 3, j + 5, k + 36, 10);
		world.setBlock(i + 3, j + 5, k + 37, 44);
		world.setBlockMetadata(i + 3, j + 5, k + 37, 10);
		world.setBlock(i + 3, j + 5, k + 38, 44);
		world.setBlockMetadata(i + 3, j + 5, k + 38, 10);
		world.setBlock(i + 3, j + 5, k + 39, 44);
		world.setBlockMetadata(i + 3, j + 5, k + 39, 10);
		world.setBlock(i + 3, j + 5, k + 40, 44);
		world.setBlockMetadata(i + 3, j + 5, k + 40, 10);
		world.setBlock(i + 3, j + 5, k + 41, 44);
		world.setBlockMetadata(i + 3, j + 5, k + 41, 10);
		world.setBlock(i + 3, j + 5, k + 42, 44);
		world.setBlockMetadata(i + 3, j + 5, k + 42, 10);
		world.setBlock(i + 3, j + 5, k + 43, 44);
		world.setBlockMetadata(i + 3, j + 5, k + 43, 10);
		world.setBlock(i + 3, j + 5, k + 44, 44);
		world.setBlockMetadata(i + 3, j + 5, k + 44, 10);
		world.setBlock(i + 3, j + 5, k + 45, 44);
		world.setBlockMetadata(i + 3, j + 5, k + 45, 10);
		world.setBlock(i + 3, j + 5, k + 46, 44);
		world.setBlockMetadata(i + 3, j + 5, k + 46, 10);
		world.setBlock(i + 3, j + 5, k + 47, 44);
		world.setBlockMetadata(i + 3, j + 5, k + 47, 10);
		world.setBlock(i + 3, j + 5, k + 48, 44);
		world.setBlockMetadata(i + 3, j + 5, k + 48, 10);
		world.setBlock(i + 3, j + 5, k + 49, 5);
		world.setBlock(i + 3, j + 5, k + 50, 44);
		world.setBlockMetadata(i + 3, j + 5, k + 50, 10);
		world.setBlock(i + 3, j + 5, k + 51, 44);
		world.setBlockMetadata(i + 3, j + 5, k + 51, 10);
		world.setBlock(i + 3, j + 6, k + 25, 44);
		world.setBlockMetadata(i + 3, j + 6, k + 25, 10);
		world.setBlock(i + 3, j + 6, k + 26, 44);
		world.setBlockMetadata(i + 3, j + 6, k + 26, 2);
		world.setBlock(i + 3, j + 6, k + 27, 44);
		world.setBlockMetadata(i + 3, j + 6, k + 27, 2);
		world.setBlock(i + 3, j + 6, k + 28, 44);
		world.setBlockMetadata(i + 3, j + 6, k + 28, 2);
		world.setBlock(i + 3, j + 6, k + 41, 53);
		world.setBlockMetadata(i + 3, j + 6, k + 41, 2);
		world.setBlock(i + 3, j + 6, k + 42, 5);
		world.setBlockMetadata(i + 3, j + 6, k + 42, 3);
		world.setBlock(i + 3, j + 6, k + 43, 5);
		world.setBlockMetadata(i + 3, j + 6, k + 43, 3);
		world.setBlock(i + 3, j + 6, k + 44, 5);
		world.setBlock(i + 3, j + 6, k + 51, 17);
		world.setBlockMetadata(i + 3, j + 6, k + 51, 3);
		world.setBlock(i + 3, j + 7, k + 24, 85);
		world.setBlock(i + 3, j + 7, k + 25, 85);
		world.setBlock(i + 3, j + 7, k + 42, 53);
		world.setBlockMetadata(i + 3, j + 7, k + 42, 2);
		world.setBlock(i + 3, j + 7, k + 43, 5);
		world.setBlockMetadata(i + 3, j + 7, k + 43, 3);
		world.setBlock(i + 3, j + 7, k + 44, 5);
		world.setBlock(i + 3, j + 7, k + 51, 17);
		world.setBlockMetadata(i + 3, j + 7, k + 51, 3);
		world.setBlock(i + 3, j + 8, k + 43, 53);
		world.setBlockMetadata(i + 3, j + 8, k + 43, 2);
		world.setBlock(i + 3, j + 8, k + 44, 5);
		world.setBlock(i + 3, j + 8, k + 51, 17);
		world.setBlockMetadata(i + 3, j + 8, k + 51, 3);
		world.setBlock(i + 3, j + 9, k + 44, 53);
		world.setBlockMetadata(i + 3, j + 9, k + 44, 2);
		world.setBlock(i + 3, j + 9, k + 45, 17);
		world.setBlockMetadata(i + 3, j + 9, k + 45, 3);
		world.setBlock(i + 3, j + 9, k + 46, 53);
		world.setBlockMetadata(i + 3, j + 9, k + 46, 5);
		world.setBlock(i + 3, j + 9, k + 47, 53);
		world.setBlockMetadata(i + 3, j + 9, k + 47, 5);
		world.setBlock(i + 3, j + 9, k + 48, 17);
		world.setBlockMetadata(i + 3, j + 9, k + 48, 3);
		world.setBlock(i + 3, j + 9, k + 49, 53);
		world.setBlockMetadata(i + 3, j + 9, k + 49, 5);
		world.setBlock(i + 3, j + 9, k + 50, 53);
		world.setBlockMetadata(i + 3, j + 9, k + 50, 5);
		world.setBlock(i + 3, j + 9, k + 51, 17);
		world.setBlockMetadata(i + 3, j + 9, k + 51, 3);
		world.setBlock(i + 3, j + 10, k + 37, 35);
		world.setBlockMetadata(i + 3, j + 10, k + 37, 13);
		world.setBlock(i + 3, j + 10, k + 52, 44);
		world.setBlockMetadata(i + 3, j + 10, k + 52, 2);
		world.setBlock(i + 3, j + 10, k + 53, 44);
		world.setBlockMetadata(i + 3, j + 10, k + 53, 10);
		world.setBlock(i + 3, j + 11, k + 37, 35);
		world.setBlockMetadata(i + 3, j + 11, k + 37, 13);
		world.setBlock(i + 3, j + 11, k + 53, 85);
		world.setBlock(i + 3, j + 12, k + 36, 35);
		world.setBlockMetadata(i + 3, j + 12, k + 36, 13);
		world.setBlock(i + 3, j + 13, k + 31, 35);
		world.setBlockMetadata(i + 3, j + 13, k + 31, 13);
		world.setBlock(i + 3, j + 13, k + 37, 35);
		world.setBlockMetadata(i + 3, j + 13, k + 37, 13);
		world.setBlock(i + 3, j + 14, k + 31, 35);
		world.setBlockMetadata(i + 3, j + 14, k + 31, 13);
		world.setBlock(i + 3, j + 14, k + 37, 35);
		world.setBlockMetadata(i + 3, j + 14, k + 37, 13);
		world.setBlock(i + 3, j + 15, k + 30, 35);
		world.setBlockMetadata(i + 3, j + 15, k + 30, 13);
		world.setBlock(i + 3, j + 15, k + 38, 17);
		world.setBlockMetadata(i + 3, j + 15, k + 38, 3);
		world.setBlock(i + 3, j + 16, k + 31, 35);
		world.setBlockMetadata(i + 3, j + 16, k + 31, 13);
		world.setBlock(i + 3, j + 17, k + 31, 35);
		world.setBlockMetadata(i + 3, j + 17, k + 31, 13);
		world.setBlock(i + 3, j + 17, k + 38, 35);
		world.setBlockMetadata(i + 3, j + 17, k + 38, 13);
		world.setBlock(i + 3, j + 18, k + 32, 17);
		world.setBlockMetadata(i + 3, j + 18, k + 32, 3);
		world.setBlock(i + 3, j + 18, k + 37, 35);
		world.setBlockMetadata(i + 3, j + 18, k + 37, 13);
		world.setBlock(i + 3, j + 19, k + 36, 35);
		world.setBlockMetadata(i + 3, j + 19, k + 36, 13);
		world.setBlock(i + 3, j + 20, k + 36, 35);
		world.setBlockMetadata(i + 3, j + 20, k + 36, 13);
		world.setBlock(i + 3, j + 21, k + 37, 35);
		world.setBlockMetadata(i + 3, j + 21, k + 37, 13);
		world.setBlock(i + 3, j + 22, k + 37, 35);
		world.setBlockMetadata(i + 3, j + 22, k + 37, 13);
		world.setBlock(i + 3, j + 23, k + 38, 17);
		world.setBlockMetadata(i + 3, j + 23, k + 38, 3);
		world.setBlock(i + 4, j + 1, k + 31, 5);
		world.setBlock(i + 4, j + 1, k + 32, 5);
		world.setBlock(i + 4, j + 1, k + 33, 5);
		world.setBlock(i + 4, j + 1, k + 34, 5);
		world.setBlock(i + 4, j + 1, k + 35, 5);
		world.setBlock(i + 4, j + 1, k + 36, 5);
		world.setBlock(i + 4, j + 1, k + 37, 5);
		world.setBlock(i + 4, j + 1, k + 38, 5);
		world.setBlock(i + 4, j + 1, k + 39, 5);
		world.setBlock(i + 4, j + 1, k + 40, 5);
		world.setBlock(i + 4, j + 1, k + 41, 5);
		world.setBlock(i + 4, j + 1, k + 42, 5);
		world.setBlock(i + 4, j + 1, k + 43, 5);
		world.setBlock(i + 4, j + 1, k + 44, 5);
		world.setBlock(i + 4, j + 1, k + 45, 5);
		world.setBlock(i + 4, j + 1, k + 46, 5);
		world.setBlock(i + 4, j + 1, k + 47, 5);
		world.setBlock(i + 4, j + 2, k + 28, 5);
		world.setBlock(i + 4, j + 2, k + 29, 5);
		world.setBlock(i + 4, j + 2, k + 30, 5);
		world.setBlock(i + 4, j + 2, k + 31, 44);
		world.setBlockMetadata(i + 4, j + 2, k + 31, 2);
		world.setBlock(i + 4, j + 2, k + 32, 44);
		world.setBlockMetadata(i + 4, j + 2, k + 32, 2);
		world.setBlock(i + 4, j + 2, k + 33, 44);
		world.setBlockMetadata(i + 4, j + 2, k + 33, 2);
		world.setBlock(i + 4, j + 2, k + 34, 44);
		world.setBlockMetadata(i + 4, j + 2, k + 34, 2);
		world.setBlock(i + 4, j + 2, k + 35, 44);
		world.setBlockMetadata(i + 4, j + 2, k + 35, 2);
		world.setBlock(i + 4, j + 2, k + 36, 44);
		world.setBlockMetadata(i + 4, j + 2, k + 36, 2);
		world.setBlock(i + 4, j + 2, k + 37, 44);
		world.setBlockMetadata(i + 4, j + 2, k + 37, 2);
		world.setBlock(i + 4, j + 2, k + 38, 44);
		world.setBlockMetadata(i + 4, j + 2, k + 38, 2);
		world.setBlock(i + 4, j + 2, k + 39, 44);
		world.setBlockMetadata(i + 4, j + 2, k + 39, 2);
		world.setBlock(i + 4, j + 2, k + 40, 44);
		world.setBlockMetadata(i + 4, j + 2, k + 40, 2);
		world.setBlock(i + 4, j + 2, k + 41, 44);
		world.setBlockMetadata(i + 4, j + 2, k + 41, 2);
		world.setBlock(i + 4, j + 2, k + 42, 44);
		world.setBlockMetadata(i + 4, j + 2, k + 42, 2);
		world.setBlock(i + 4, j + 2, k + 43, 44);
		world.setBlockMetadata(i + 4, j + 2, k + 43, 2);
		world.setBlock(i + 4, j + 2, k + 44, 44);
		world.setBlockMetadata(i + 4, j + 2, k + 44, 2);
		world.setBlock(i + 4, j + 2, k + 45, 44);
		world.setBlockMetadata(i + 4, j + 2, k + 45, 2);
		world.setBlock(i + 4, j + 2, k + 46, 44);
		world.setBlockMetadata(i + 4, j + 2, k + 46, 2);
		world.setBlock(i + 4, j + 2, k + 47, 44);
		world.setBlockMetadata(i + 4, j + 2, k + 47, 2);
		world.setBlock(i + 4, j + 2, k + 48, 5);
		world.setBlock(i + 4, j + 3, k + 27, 5);
		world.setBlock(i + 4, j + 3, k + 28, 5);
		world.setBlock(i + 4, j + 3, k + 49, 5);
		world.setBlock(i + 4, j + 4, k + 26, 17);
		world.setBlockMetadata(i + 4, j + 4, k + 26, 3);
		world.setBlock(i + 4, j + 4, k + 27, 17);
		world.setBlockMetadata(i + 4, j + 4, k + 27, 3);
		world.setBlock(i + 4, j + 4, k + 50, 17);
		world.setBlockMetadata(i + 4, j + 4, k + 50, 3);
		world.setBlock(i + 4, j + 5, k + 25, 5);
		world.setBlock(i + 4, j + 5, k + 26, 5);
		world.setBlock(i + 4, j + 5, k + 27, 5);
		world.setBlock(i + 4, j + 5, k + 28, 44);
		world.setBlockMetadata(i + 4, j + 5, k + 28, 10);
		world.setBlock(i + 4, j + 5, k + 29, 44);
		world.setBlockMetadata(i + 4, j + 5, k + 29, 10);
		world.setBlock(i + 4, j + 5, k + 30, 44);
		world.setBlockMetadata(i + 4, j + 5, k + 30, 10);
		world.setBlock(i + 4, j + 5, k + 31, 44);
		world.setBlockMetadata(i + 4, j + 5, k + 31, 10);
		world.setBlock(i + 4, j + 5, k + 32, 5);
		world.setBlock(i + 4, j + 5, k + 35, 5);
		world.setBlock(i + 4, j + 5, k + 36, 44);
		world.setBlockMetadata(i + 4, j + 5, k + 36, 10);
		world.setBlock(i + 4, j + 5, k + 37, 44);
		world.setBlockMetadata(i + 4, j + 5, k + 37, 10);
		world.setBlock(i + 4, j + 5, k + 38, 44);
		world.setBlockMetadata(i + 4, j + 5, k + 38, 10);
		world.setBlock(i + 4, j + 5, k + 39, 44);
		world.setBlockMetadata(i + 4, j + 5, k + 39, 10);
		world.setBlock(i + 4, j + 5, k + 40, 44);
		world.setBlockMetadata(i + 4, j + 5, k + 40, 10);
		world.setBlock(i + 4, j + 5, k + 41, 44);
		world.setBlockMetadata(i + 4, j + 5, k + 41, 10);
		world.setBlock(i + 4, j + 5, k + 42, 44);
		world.setBlockMetadata(i + 4, j + 5, k + 42, 10);
		world.setBlock(i + 4, j + 5, k + 43, 44);
		world.setBlockMetadata(i + 4, j + 5, k + 43, 10);
		world.setBlock(i + 4, j + 5, k + 44, 44);
		world.setBlockMetadata(i + 4, j + 5, k + 44, 10);
		world.setBlock(i + 4, j + 5, k + 45, 44);
		world.setBlockMetadata(i + 4, j + 5, k + 45, 10);
		world.setBlock(i + 4, j + 5, k + 46, 44);
		world.setBlockMetadata(i + 4, j + 5, k + 46, 10);
		world.setBlock(i + 4, j + 5, k + 47, 44);
		world.setBlockMetadata(i + 4, j + 5, k + 47, 10);
		world.setBlock(i + 4, j + 5, k + 48, 44);
		world.setBlockMetadata(i + 4, j + 5, k + 48, 10);
		world.setBlock(i + 4, j + 5, k + 49, 44);
		world.setBlockMetadata(i + 4, j + 5, k + 49, 10);
		world.setBlock(i + 4, j + 5, k + 50, 5);
		world.setBlock(i + 4, j + 5, k + 51, 53);
		world.setBlockMetadata(i + 4, j + 5, k + 51, 7);
		world.setBlock(i + 4, j + 6, k + 24, 44);
		world.setBlockMetadata(i + 4, j + 6, k + 24, 10);
		world.setBlock(i + 4, j + 6, k + 25, 44);
		world.setBlockMetadata(i + 4, j + 6, k + 25, 2);
		world.setBlock(i + 4, j + 6, k + 30, 44);
		world.setBlockMetadata(i + 4, j + 6, k + 30, 2);
		world.setBlock(i + 4, j + 6, k + 31, 44);
		world.setBlockMetadata(i + 4, j + 6, k + 31, 2);
		world.setBlock(i + 4, j + 6, k + 32, 44);
		world.setBlockMetadata(i + 4, j + 6, k + 32, 2);
		world.setBlock(i + 4, j + 6, k + 35, 44);
		world.setBlockMetadata(i + 4, j + 6, k + 35, 2);
		world.setBlock(i + 4, j + 6, k + 36, 44);
		world.setBlockMetadata(i + 4, j + 6, k + 36, 2);
		world.setBlock(i + 4, j + 6, k + 37, 44);
		world.setBlockMetadata(i + 4, j + 6, k + 37, 2);
		world.setBlock(i + 4, j + 6, k + 38, 44);
		world.setBlockMetadata(i + 4, j + 6, k + 38, 2);
		world.setBlock(i + 4, j + 6, k + 41, 17);
		world.setBlockMetadata(i + 4, j + 6, k + 41, 3);
		world.setBlock(i + 4, j + 6, k + 42, 5);
		world.setBlockMetadata(i + 4, j + 6, k + 42, 3);
		world.setBlock(i + 4, j + 6, k + 43, 5);
		world.setBlockMetadata(i + 4, j + 6, k + 43, 3);
		world.setBlock(i + 4, j + 6, k + 44, 5);
		world.setBlock(i + 4, j + 6, k + 48, 44);
		world.setBlockMetadata(i + 4, j + 6, k + 48, 10);
		world.setBlock(i + 4, j + 6, k + 51, 17);
		world.setBlockMetadata(i + 4, j + 6, k + 51, 3);
		world.setBlock(i + 4, j + 7, k + 24, 85);
		world.setBlock(i + 4, j + 7, k + 41, 85);
		world.setBlock(i + 4, j + 7, k + 42, 17);
		world.setBlockMetadata(i + 4, j + 7, k + 42, 3);
		world.setBlock(i + 4, j + 7, k + 43, 5);
		world.setBlockMetadata(i + 4, j + 7, k + 43, 3);
		world.setBlock(i + 4, j + 7, k + 44, 5);
		world.setBlock(i + 4, j + 7, k + 51, 102);
		world.setBlock(i + 4, j + 7, k + 57, 44);
		world.setBlockMetadata(i + 4, j + 7, k + 57, 13);
		world.setBlock(i + 4, j + 7, k + 58, 109);
		world.setBlockMetadata(i + 4, j + 7, k + 58, 4);
		world.setBlock(i + 4, j + 7, k + 59, 44);
		world.setBlockMetadata(i + 4, j + 7, k + 59, 13);
		world.setBlock(i + 4, j + 8, k + 42, 85);
		world.setBlock(i + 4, j + 8, k + 43, 17);
		world.setBlockMetadata(i + 4, j + 8, k + 43, 3);
		world.setBlock(i + 4, j + 8, k + 44, 5);
		world.setBlock(i + 4, j + 8, k + 51, 102);
		world.setBlock(i + 4, j + 8, k + 57, 101);
		world.setBlock(i + 4, j + 8, k + 58, 101);
		world.setBlock(i + 4, j + 8, k + 59, 101);
		world.setBlock(i + 4, j + 9, k + 43, 85);
		world.setBlock(i + 4, j + 9, k + 44, 17);
		world.setBlockMetadata(i + 4, j + 9, k + 44, 3);
		world.setBlock(i + 4, j + 9, k + 45, 17);
		world.setBlockMetadata(i + 4, j + 9, k + 45, 3);
		world.setBlock(i + 4, j + 9, k + 46, 44);
		world.setBlockMetadata(i + 4, j + 9, k + 46, 10);
		world.setBlock(i + 4, j + 9, k + 47, 44);
		world.setBlockMetadata(i + 4, j + 9, k + 47, 10);
		world.setBlock(i + 4, j + 9, k + 48, 17);
		world.setBlockMetadata(i + 4, j + 9, k + 48, 3);
		world.setBlock(i + 4, j + 9, k + 49, 44);
		world.setBlockMetadata(i + 4, j + 9, k + 49, 10);
		world.setBlock(i + 4, j + 9, k + 50, 44);
		world.setBlockMetadata(i + 4, j + 9, k + 50, 10);
		world.setBlock(i + 4, j + 9, k + 51, 17);
		world.setBlockMetadata(i + 4, j + 9, k + 51, 3);
		world.setBlock(i + 4, j + 9, k + 57, 44);
		world.setBlockMetadata(i + 4, j + 9, k + 57, 5);
		world.setBlock(i + 4, j + 9, k + 58, 109);
		world.setBlock(i + 4, j + 9, k + 59, 44);
		world.setBlockMetadata(i + 4, j + 9, k + 59, 5);
		world.setBlock(i + 4, j + 10, k + 37, 35);
		world.setBlockMetadata(i + 4, j + 10, k + 37, 13);
		world.setBlock(i + 4, j + 10, k + 44, 85);
		world.setBlock(i + 4, j + 10, k + 48, 44);
		world.setBlockMetadata(i + 4, j + 10, k + 48, 2);
		world.setBlock(i + 4, j + 10, k + 49, 44);
		world.setBlockMetadata(i + 4, j + 10, k + 49, 2);
		world.setBlock(i + 4, j + 10, k + 50, 44);
		world.setBlockMetadata(i + 4, j + 10, k + 50, 2);
		world.setBlock(i + 4, j + 10, k + 52, 44);
		world.setBlockMetadata(i + 4, j + 10, k + 52, 2);
		world.setBlock(i + 4, j + 10, k + 53, 44);
		world.setBlockMetadata(i + 4, j + 10, k + 53, 10);
		world.setBlock(i + 4, j + 11, k + 20, 35);
		world.setBlockMetadata(i + 4, j + 11, k + 20, 13);
		world.setBlock(i + 4, j + 11, k + 21, 35);
		world.setBlockMetadata(i + 4, j + 11, k + 21, 13);
		world.setBlock(i + 4, j + 11, k + 37, 35);
		world.setBlockMetadata(i + 4, j + 11, k + 37, 13);
		world.setBlock(i + 4, j + 11, k + 53, 85);
		world.setBlock(i + 4, j + 12, k + 21, 35);
		world.setBlockMetadata(i + 4, j + 12, k + 21, 13);
		world.setBlock(i + 4, j + 12, k + 22, 35);
		world.setBlockMetadata(i + 4, j + 12, k + 22, 13);
		world.setBlock(i + 4, j + 12, k + 36, 35);
		world.setBlockMetadata(i + 4, j + 12, k + 36, 13);
		world.setBlock(i + 4, j + 13, k + 22, 35);
		world.setBlockMetadata(i + 4, j + 13, k + 22, 13);
		world.setBlock(i + 4, j + 13, k + 23, 35);
		world.setBlockMetadata(i + 4, j + 13, k + 23, 13);
		world.setBlock(i + 4, j + 13, k + 31, 35);
		world.setBlockMetadata(i + 4, j + 13, k + 31, 13);
		world.setBlock(i + 4, j + 13, k + 37, 35);
		world.setBlockMetadata(i + 4, j + 13, k + 37, 13);
		world.setBlock(i + 4, j + 14, k + 23, 35);
		world.setBlockMetadata(i + 4, j + 14, k + 23, 13);
		world.setBlock(i + 4, j + 14, k + 24, 35);
		world.setBlockMetadata(i + 4, j + 14, k + 24, 13);
		world.setBlock(i + 4, j + 14, k + 31, 35);
		world.setBlockMetadata(i + 4, j + 14, k + 31, 13);
		world.setBlock(i + 4, j + 14, k + 37, 35);
		world.setBlockMetadata(i + 4, j + 14, k + 37, 13);
		world.setBlock(i + 4, j + 15, k + 24, 35);
		world.setBlockMetadata(i + 4, j + 15, k + 24, 13);
		world.setBlock(i + 4, j + 15, k + 25, 35);
		world.setBlockMetadata(i + 4, j + 15, k + 25, 13);
		world.setBlock(i + 4, j + 15, k + 30, 35);
		world.setBlockMetadata(i + 4, j + 15, k + 30, 13);
		world.setBlock(i + 4, j + 15, k + 38, 17);
		world.setBlockMetadata(i + 4, j + 15, k + 38, 3);
		world.setBlock(i + 4, j + 16, k + 25, 35);
		world.setBlockMetadata(i + 4, j + 16, k + 25, 13);
		world.setBlock(i + 4, j + 16, k + 31, 35);
		world.setBlockMetadata(i + 4, j + 16, k + 31, 13);
		world.setBlock(i + 4, j + 17, k + 31, 35);
		world.setBlockMetadata(i + 4, j + 17, k + 31, 13);
		world.setBlock(i + 4, j + 17, k + 37, 35);
		world.setBlockMetadata(i + 4, j + 17, k + 37, 13);
		world.setBlock(i + 4, j + 18, k + 32, 17);
		world.setBlockMetadata(i + 4, j + 18, k + 32, 3);
		world.setBlock(i + 4, j + 18, k + 37, 35);
		world.setBlockMetadata(i + 4, j + 18, k + 37, 13);
		world.setBlock(i + 4, j + 19, k + 36, 35);
		world.setBlockMetadata(i + 4, j + 19, k + 36, 13);
		world.setBlock(i + 4, j + 20, k + 36, 35);
		world.setBlockMetadata(i + 4, j + 20, k + 36, 13);
		world.setBlock(i + 4, j + 21, k + 37, 35);
		world.setBlockMetadata(i + 4, j + 21, k + 37, 13);
		world.setBlock(i + 4, j + 22, k + 37, 35);
		world.setBlockMetadata(i + 4, j + 22, k + 37, 13);
		world.setBlock(i + 4, j + 23, k + 38, 17);
		world.setBlockMetadata(i + 4, j + 23, k + 38, 3);
		world.setBlock(i + 4, j + 27, k + 37, 53);
		world.setBlockMetadata(i + 4, j + 27, k + 37, 4);
		world.setBlock(i + 4, j + 28, k + 37, 44);
		world.setBlockMetadata(i + 4, j + 28, k + 37, 2);
		world.setBlock(i + 4, j + 32, k + 32, 35);
		world.setBlockMetadata(i + 4, j + 32, k + 32, 15);
		world.setBlock(i + 4, j + 33, k + 32, 35);
		world.setBlockMetadata(i + 4, j + 33, k + 32, 8);
		world.setBlock(i + 4, j + 34, k + 32, 35);
		world.setBlockMetadata(i + 4, j + 34, k + 32, 15);
		world.setBlock(i + 4, j + 35, k + 32, 35);
		world.setBlockMetadata(i + 4, j + 35, k + 32, 8);
		world.setBlock(i + 4, j + 36, k + 32, 35);
		world.setBlockMetadata(i + 4, j + 36, k + 32, 15);
		world.setBlock(i + 5, j + 0, k + 29, 5);
		world.setBlock(i + 5, j + 0, k + 30, 5);
		world.setBlock(i + 5, j + 0, k + 31, 5);
		world.setBlock(i + 5, j + 0, k + 32, 5);
		world.setBlock(i + 5, j + 0, k + 33, 5);
		world.setBlock(i + 5, j + 0, k + 34, 5);
		world.setBlock(i + 5, j + 0, k + 35, 5);
		world.setBlock(i + 5, j + 0, k + 36, 5);
		world.setBlock(i + 5, j + 0, k + 37, 5);
		world.setBlock(i + 5, j + 0, k + 38, 5);
		world.setBlock(i + 5, j + 0, k + 39, 5);
		world.setBlock(i + 5, j + 0, k + 40, 5);
		world.setBlock(i + 5, j + 0, k + 41, 5);
		world.setBlock(i + 5, j + 0, k + 42, 5);
		world.setBlock(i + 5, j + 0, k + 43, 5);
		world.setBlock(i + 5, j + 0, k + 44, 5);
		world.setBlock(i + 5, j + 0, k + 45, 5);
		world.setBlock(i + 5, j + 0, k + 46, 5);
		world.setBlock(i + 5, j + 0, k + 47, 5);
		world.setBlock(i + 5, j + 1, k + 27, 5);
		world.setBlock(i + 5, j + 1, k + 28, 5);
		world.setBlock(i + 5, j + 1, k + 29, 5);
		world.setBlock(i + 5, j + 1, k + 30, 5);
		world.setBlock(i + 5, j + 1, k + 31, 5);
		world.setBlock(i + 5, j + 1, k + 32, 5);
		world.setBlock(i + 5, j + 1, k + 33, 5);
		world.setBlock(i + 5, j + 1, k + 34, 5);
		world.setBlock(i + 5, j + 1, k + 35, 5);
		world.setBlock(i + 5, j + 1, k + 36, 5);
		world.setBlock(i + 5, j + 1, k + 37, 5);
		world.setBlock(i + 5, j + 1, k + 38, 5);
		world.setBlock(i + 5, j + 1, k + 39, 5);
		world.setBlock(i + 5, j + 1, k + 40, 5);
		world.setBlock(i + 5, j + 1, k + 41, 5);
		world.setBlock(i + 5, j + 1, k + 42, 5);
		world.setBlock(i + 5, j + 1, k + 43, 5);
		world.setBlock(i + 5, j + 1, k + 44, 5);
		world.setBlock(i + 5, j + 1, k + 45, 5);
		world.setBlock(i + 5, j + 1, k + 46, 5);
		world.setBlock(i + 5, j + 1, k + 47, 5);
		world.setBlock(i + 5, j + 1, k + 48, 5);
		world.setBlock(i + 5, j + 1, k + 51, 85);
		world.setBlock(i + 5, j + 1, k + 52, 5);
		world.setBlock(i + 5, j + 2, k + 26, 5);
		world.setBlock(i + 5, j + 2, k + 27, 5);
		world.setBlock(i + 5, j + 2, k + 31, 17);
		world.setBlockMetadata(i + 5, j + 2, k + 31, 3);
		world.setBlock(i + 5, j + 2, k + 32, 5);
		world.setBlock(i + 5, j + 2, k + 33, 44);
		world.setBlockMetadata(i + 5, j + 2, k + 33, 2);
		world.setBlock(i + 5, j + 2, k + 34, 44);
		world.setBlockMetadata(i + 5, j + 2, k + 34, 2);
		world.setBlock(i + 5, j + 2, k + 35, 44);
		world.setBlockMetadata(i + 5, j + 2, k + 35, 2);
		world.setBlock(i + 5, j + 2, k + 36, 44);
		world.setBlockMetadata(i + 5, j + 2, k + 36, 2);
		world.setBlock(i + 5, j + 2, k + 37, 17);
		world.setBlockMetadata(i + 5, j + 2, k + 37, 3);
		world.setBlock(i + 5, j + 2, k + 38, 44);
		world.setBlockMetadata(i + 5, j + 2, k + 38, 2);
		world.setBlock(i + 5, j + 2, k + 39, 44);
		world.setBlockMetadata(i + 5, j + 2, k + 39, 2);
		world.setBlock(i + 5, j + 2, k + 40, 44);
		world.setBlockMetadata(i + 5, j + 2, k + 40, 2);
		world.setBlock(i + 5, j + 2, k + 41, 44);
		world.setBlockMetadata(i + 5, j + 2, k + 41, 2);
		world.setBlock(i + 5, j + 2, k + 42, 44);
		world.setBlockMetadata(i + 5, j + 2, k + 42, 2);
		world.setBlock(i + 5, j + 2, k + 43, 44);
		world.setBlockMetadata(i + 5, j + 2, k + 43, 2);
		world.setBlock(i + 5, j + 2, k + 44, 44);
		world.setBlockMetadata(i + 5, j + 2, k + 44, 2);
		world.setBlock(i + 5, j + 2, k + 45, 44);
		world.setBlockMetadata(i + 5, j + 2, k + 45, 2);
		world.setBlock(i + 5, j + 2, k + 46, 44);
		world.setBlockMetadata(i + 5, j + 2, k + 46, 2);
		world.setBlock(i + 5, j + 2, k + 47, 44);
		world.setBlockMetadata(i + 5, j + 2, k + 47, 2);
		world.setBlock(i + 5, j + 2, k + 48, 5);
		world.setBlock(i + 5, j + 2, k + 49, 5);
		world.setBlock(i + 5, j + 2, k + 51, 85);
		world.setBlock(i + 5, j + 2, k + 52, 5);
		world.setBlock(i + 5, j + 2, k + 53, 5);
		world.setBlock(i + 5, j + 3, k + 25, 5);
		world.setBlock(i + 5, j + 3, k + 26, 5);
		world.setBlock(i + 5, j + 3, k + 31, 17);
		world.setBlockMetadata(i + 5, j + 3, k + 31, 3);
		world.setBlock(i + 5, j + 3, k + 32, 5);
		world.setBlock(i + 5, j + 3, k + 37, 17);
		world.setBlockMetadata(i + 5, j + 3, k + 37, 3);
		world.setBlock(i + 5, j + 3, k + 49, 5);
		world.setBlock(i + 5, j + 3, k + 50, 5);
		world.setBlock(i + 5, j + 3, k + 51, 85);
		world.setBlock(i + 5, j + 3, k + 52, 5);
		world.setBlock(i + 5, j + 3, k + 53, 53);
		world.setBlockMetadata(i + 5, j + 3, k + 53, 3);
		world.setBlock(i + 5, j + 4, k + 13, 44);
		world.setBlockMetadata(i + 5, j + 4, k + 13, 10);
		world.setBlock(i + 5, j + 4, k + 23, 53);
		world.setBlockMetadata(i + 5, j + 4, k + 23, 6);
		world.setBlock(i + 5, j + 4, k + 24, 17);
		world.setBlockMetadata(i + 5, j + 4, k + 24, 3);
		world.setBlock(i + 5, j + 4, k + 25, 17);
		world.setBlockMetadata(i + 5, j + 4, k + 25, 3);
		world.setBlock(i + 5, j + 4, k + 26, 5);
		world.setBlock(i + 5, j + 4, k + 31, 17);
		world.setBlockMetadata(i + 5, j + 4, k + 31, 3);
		world.setBlock(i + 5, j + 4, k + 32, 5);
		world.setBlock(i + 5, j + 4, k + 37, 17);
		world.setBlockMetadata(i + 5, j + 4, k + 37, 3);
		world.setBlock(i + 5, j + 4, k + 50, 17);
		world.setBlockMetadata(i + 5, j + 4, k + 50, 3);
		world.setBlock(i + 5, j + 4, k + 51, 85);
		world.setBlock(i + 5, j + 4, k + 52, 53);
		world.setBlockMetadata(i + 5, j + 4, k + 52, 3);
		world.setBlock(i + 5, j + 5, k + 13, 89);
		world.setBlock(i + 5, j + 5, k + 21, 44);
		world.setBlockMetadata(i + 5, j + 5, k + 21, 10);
		world.setBlock(i + 5, j + 5, k + 22, 53);
		world.setBlockMetadata(i + 5, j + 5, k + 22, 6);
		world.setBlock(i + 5, j + 5, k + 23, 5);
		world.setBlock(i + 5, j + 5, k + 24, 5);
		world.setBlock(i + 5, j + 5, k + 25, 5);
		world.setBlock(i + 5, j + 5, k + 26, 5);
		world.setBlock(i + 5, j + 5, k + 27, 44);
		world.setBlockMetadata(i + 5, j + 5, k + 27, 10);
		world.setBlock(i + 5, j + 5, k + 28, 44);
		world.setBlockMetadata(i + 5, j + 5, k + 28, 10);
		world.setBlock(i + 5, j + 5, k + 29, 44);
		world.setBlockMetadata(i + 5, j + 5, k + 29, 10);
		world.setBlock(i + 5, j + 5, k + 30, 44);
		world.setBlockMetadata(i + 5, j + 5, k + 30, 10);
		world.setBlock(i + 5, j + 5, k + 31, 17);
		world.setBlockMetadata(i + 5, j + 5, k + 31, 3);
		world.setBlock(i + 5, j + 5, k + 32, 5);
		world.setBlock(i + 5, j + 5, k + 35, 5);
		world.setBlock(i + 5, j + 5, k + 36, 44);
		world.setBlockMetadata(i + 5, j + 5, k + 36, 10);
		world.setBlock(i + 5, j + 5, k + 37, 17);
		world.setBlockMetadata(i + 5, j + 5, k + 37, 3);
		world.setBlock(i + 5, j + 5, k + 38, 44);
		world.setBlockMetadata(i + 5, j + 5, k + 38, 10);
		world.setBlock(i + 5, j + 5, k + 39, 44);
		world.setBlockMetadata(i + 5, j + 5, k + 39, 10);
		world.setBlock(i + 5, j + 5, k + 40, 44);
		world.setBlockMetadata(i + 5, j + 5, k + 40, 10);
		world.setBlock(i + 5, j + 5, k + 41, 44);
		world.setBlockMetadata(i + 5, j + 5, k + 41, 10);
		world.setBlock(i + 5, j + 5, k + 42, 44);
		world.setBlockMetadata(i + 5, j + 5, k + 42, 10);
		world.setBlock(i + 5, j + 5, k + 43, 44);
		world.setBlockMetadata(i + 5, j + 5, k + 43, 10);
		world.setBlock(i + 5, j + 5, k + 44, 5);
		world.setBlock(i + 5, j + 5, k + 45, 44);
		world.setBlockMetadata(i + 5, j + 5, k + 45, 10);
		world.setBlock(i + 5, j + 5, k + 46, 44);
		world.setBlockMetadata(i + 5, j + 5, k + 46, 10);
		world.setBlock(i + 5, j + 5, k + 47, 44);
		world.setBlockMetadata(i + 5, j + 5, k + 47, 10);
		world.setBlock(i + 5, j + 5, k + 48, 44);
		world.setBlockMetadata(i + 5, j + 5, k + 48, 10);
		world.setBlock(i + 5, j + 5, k + 49, 44);
		world.setBlockMetadata(i + 5, j + 5, k + 49, 10);
		world.setBlock(i + 5, j + 5, k + 50, 43);
		world.setBlockMetadata(i + 5, j + 5, k + 50, 2);
		world.setBlock(i + 5, j + 5, k + 51, 44);
		world.setBlockMetadata(i + 5, j + 5, k + 51, 10);
		world.setBlock(i + 5, j + 6, k + 13, 101);
		world.setBlock(i + 5, j + 6, k + 16, 44);
		world.setBlockMetadata(i + 5, j + 6, k + 16, 10);
		world.setBlock(i + 5, j + 6, k + 17, 44);
		world.setBlockMetadata(i + 5, j + 6, k + 17, 10);
		world.setBlock(i + 5, j + 6, k + 18, 43);
		world.setBlockMetadata(i + 5, j + 6, k + 18, 2);
		world.setBlock(i + 5, j + 6, k + 19, 44);
		world.setBlockMetadata(i + 5, j + 6, k + 19, 2);
		world.setBlock(i + 5, j + 6, k + 20, 44);
		world.setBlockMetadata(i + 5, j + 6, k + 20, 2);
		world.setBlock(i + 5, j + 6, k + 21, 44);
		world.setBlockMetadata(i + 5, j + 6, k + 21, 2);
		world.setBlock(i + 5, j + 6, k + 22, 5);
		world.setBlock(i + 5, j + 6, k + 23, 5);
		world.setBlock(i + 5, j + 6, k + 24, 43);
		world.setBlockMetadata(i + 5, j + 6, k + 24, 2);
		world.setBlock(i + 5, j + 6, k + 30, 44);
		world.setBlockMetadata(i + 5, j + 6, k + 30, 2);
		world.setBlock(i + 5, j + 6, k + 31, 17);
		world.setBlockMetadata(i + 5, j + 6, k + 31, 3);
		world.setBlock(i + 5, j + 6, k + 32, 44);
		world.setBlockMetadata(i + 5, j + 6, k + 32, 2);
		world.setBlock(i + 5, j + 6, k + 35, 44);
		world.setBlockMetadata(i + 5, j + 6, k + 35, 2);
		world.setBlock(i + 5, j + 6, k + 36, 44);
		world.setBlockMetadata(i + 5, j + 6, k + 36, 2);
		world.setBlock(i + 5, j + 6, k + 37, 17);
		world.setBlockMetadata(i + 5, j + 6, k + 37, 3);
		world.setBlock(i + 5, j + 6, k + 38, 44);
		world.setBlockMetadata(i + 5, j + 6, k + 38, 2);
		world.setBlock(i + 5, j + 6, k + 48, 43);
		world.setBlockMetadata(i + 5, j + 6, k + 48, 2);
		world.setBlock(i + 5, j + 6, k + 49, 53);
		world.setBlockMetadata(i + 5, j + 6, k + 49, 2);
		world.setBlock(i + 5, j + 6, k + 51, 17);
		world.setBlockMetadata(i + 5, j + 6, k + 51, 3);
		world.setBlock(i + 5, j + 6, k + 58, 44);
		world.setBlockMetadata(i + 5, j + 6, k + 58, 13);
		world.setBlock(i + 5, j + 7, k + 13, 43);
		world.setBlockMetadata(i + 5, j + 7, k + 13, 2);
		world.setBlock(i + 5, j + 7, k + 14, 44);
		world.setBlockMetadata(i + 5, j + 7, k + 14, 10);
		world.setBlock(i + 5, j + 7, k + 15, 43);
		world.setBlockMetadata(i + 5, j + 7, k + 15, 2);
		world.setBlock(i + 5, j + 7, k + 16, 44);
		world.setBlockMetadata(i + 5, j + 7, k + 16, 2);
		world.setBlock(i + 5, j + 7, k + 22, 5);
		world.setBlock(i + 5, j + 7, k + 24, 85);
		world.setBlock(i + 5, j + 7, k + 31, 17);
		world.setBlockMetadata(i + 5, j + 7, k + 31, 3);
		world.setBlock(i + 5, j + 7, k + 37, 17);
		world.setBlockMetadata(i + 5, j + 7, k + 37, 3);
		world.setBlock(i + 5, j + 7, k + 51, 102);
		world.setBlock(i + 5, j + 7, k + 57, 109);
		world.setBlockMetadata(i + 5, j + 7, k + 57, 6);
		world.setBlock(i + 5, j + 7, k + 58, 43);
		world.setBlockMetadata(i + 5, j + 7, k + 58, 5);
		world.setBlock(i + 5, j + 7, k + 59, 109);
		world.setBlockMetadata(i + 5, j + 7, k + 59, 7);
		world.setBlock(i + 5, j + 8, k + 11, 44);
		world.setBlockMetadata(i + 5, j + 8, k + 11, 2);
		world.setBlock(i + 5, j + 8, k + 12, 44);
		world.setBlockMetadata(i + 5, j + 8, k + 12, 2);
		world.setBlock(i + 5, j + 8, k + 13, 44);
		world.setBlockMetadata(i + 5, j + 8, k + 13, 2);
		world.setBlock(i + 5, j + 8, k + 16, 35);
		world.setBlockMetadata(i + 5, j + 8, k + 16, 7);
		world.setBlock(i + 5, j + 8, k + 22, 86);
		world.setBlockMetadata(i + 5, j + 8, k + 22, 2);
		world.setBlock(i + 5, j + 8, k + 31, 17);
		world.setBlockMetadata(i + 5, j + 8, k + 31, 3);
		world.setBlock(i + 5, j + 8, k + 37, 17);
		world.setBlockMetadata(i + 5, j + 8, k + 37, 3);
		world.setBlock(i + 5, j + 8, k + 44, 5);
		world.setBlock(i + 5, j + 8, k + 51, 102);
		world.setBlock(i + 5, j + 8, k + 57, 101);
		world.setBlock(i + 5, j + 8, k + 58, 89);
		world.setBlock(i + 5, j + 8, k + 59, 101);
		world.setBlock(i + 5, j + 9, k + 17, 35);
		world.setBlockMetadata(i + 5, j + 9, k + 17, 7);
		world.setBlock(i + 5, j + 9, k + 31, 17);
		world.setBlockMetadata(i + 5, j + 9, k + 31, 3);
		world.setBlock(i + 5, j + 9, k + 37, 17);
		world.setBlockMetadata(i + 5, j + 9, k + 37, 3);
		world.setBlock(i + 5, j + 9, k + 45, 17);
		world.setBlockMetadata(i + 5, j + 9, k + 45, 3);
		world.setBlock(i + 5, j + 9, k + 46, 44);
		world.setBlockMetadata(i + 5, j + 9, k + 46, 10);
		world.setBlock(i + 5, j + 9, k + 47, 44);
		world.setBlockMetadata(i + 5, j + 9, k + 47, 10);
		world.setBlock(i + 5, j + 9, k + 48, 17);
		world.setBlockMetadata(i + 5, j + 9, k + 48, 3);
		world.setBlock(i + 5, j + 9, k + 49, 44);
		world.setBlockMetadata(i + 5, j + 9, k + 49, 10);
		world.setBlock(i + 5, j + 9, k + 50, 44);
		world.setBlockMetadata(i + 5, j + 9, k + 50, 10);
		world.setBlock(i + 5, j + 9, k + 51, 17);
		world.setBlockMetadata(i + 5, j + 9, k + 51, 3);
		world.setBlock(i + 5, j + 9, k + 57, 109);
		world.setBlockMetadata(i + 5, j + 9, k + 57, 2);
		world.setBlock(i + 5, j + 9, k + 58, 98);
		world.setBlock(i + 5, j + 9, k + 59, 109);
		world.setBlockMetadata(i + 5, j + 9, k + 59, 3);
		world.setBlock(i + 5, j + 10, k + 18, 35);
		world.setBlockMetadata(i + 5, j + 10, k + 18, 7);
		world.setBlock(i + 5, j + 10, k + 31, 17);
		world.setBlockMetadata(i + 5, j + 10, k + 31, 3);
		world.setBlock(i + 5, j + 10, k + 36, 35);
		world.setBlockMetadata(i + 5, j + 10, k + 36, 13);
		world.setBlock(i + 5, j + 10, k + 37, 17);
		world.setBlockMetadata(i + 5, j + 10, k + 37, 3);
		world.setBlock(i + 5, j + 10, k + 44, 85);
		world.setBlock(i + 5, j + 10, k + 48, 44);
		world.setBlockMetadata(i + 5, j + 10, k + 48, 2);
		world.setBlock(i + 5, j + 10, k + 49, 17);
		world.setBlockMetadata(i + 5, j + 10, k + 49, 3);
		world.setBlock(i + 5, j + 10, k + 50, 44);
		world.setBlockMetadata(i + 5, j + 10, k + 50, 2);
		world.setBlock(i + 5, j + 10, k + 52, 44);
		world.setBlockMetadata(i + 5, j + 10, k + 52, 2);
		world.setBlock(i + 5, j + 10, k + 53, 44);
		world.setBlockMetadata(i + 5, j + 10, k + 53, 10);
		world.setBlock(i + 5, j + 10, k + 58, 101);
		world.setBlock(i + 5, j + 11, k + 19, 35);
		world.setBlockMetadata(i + 5, j + 11, k + 19, 13);
		world.setBlock(i + 5, j + 11, k + 20, 35);
		world.setBlockMetadata(i + 5, j + 11, k + 20, 13);
		world.setBlock(i + 5, j + 11, k + 22, 35);
		world.setBlockMetadata(i + 5, j + 11, k + 22, 13);
		world.setBlock(i + 5, j + 11, k + 31, 17);
		world.setBlockMetadata(i + 5, j + 11, k + 31, 3);
		world.setBlock(i + 5, j + 11, k + 36, 35);
		world.setBlockMetadata(i + 5, j + 11, k + 36, 13);
		world.setBlock(i + 5, j + 11, k + 37, 17);
		world.setBlockMetadata(i + 5, j + 11, k + 37, 3);
		world.setBlock(i + 5, j + 11, k + 49, 17);
		world.setBlockMetadata(i + 5, j + 11, k + 49, 3);
		world.setBlock(i + 5, j + 11, k + 53, 85);
		world.setBlock(i + 5, j + 11, k + 54, 85);
		world.setBlock(i + 5, j + 11, k + 58, 101);
		world.setBlock(i + 5, j + 12, k + 20, 35);
		world.setBlockMetadata(i + 5, j + 12, k + 20, 13);
		world.setBlock(i + 5, j + 12, k + 23, 35);
		world.setBlockMetadata(i + 5, j + 12, k + 23, 13);
		world.setBlock(i + 5, j + 12, k + 24, 35);
		world.setBlockMetadata(i + 5, j + 12, k + 24, 13);
		world.setBlock(i + 5, j + 12, k + 31, 17);
		world.setBlockMetadata(i + 5, j + 12, k + 31, 3);
		world.setBlock(i + 5, j + 12, k + 35, 35);
		world.setBlockMetadata(i + 5, j + 12, k + 35, 13);
		world.setBlock(i + 5, j + 12, k + 37, 17);
		world.setBlockMetadata(i + 5, j + 12, k + 37, 3);
		world.setBlock(i + 5, j + 12, k + 49, 17);
		world.setBlockMetadata(i + 5, j + 12, k + 49, 3);
		world.setBlock(i + 5, j + 12, k + 54, 85);
		world.setBlock(i + 5, j + 12, k + 55, 85);
		world.setBlock(i + 5, j + 12, k + 57, 85);
		world.setBlock(i + 5, j + 12, k + 58, 85);
		world.setBlock(i + 5, j + 13, k + 21, 35);
		world.setBlockMetadata(i + 5, j + 13, k + 21, 13);
		world.setBlock(i + 5, j + 13, k + 24, 35);
		world.setBlockMetadata(i + 5, j + 13, k + 24, 13);
		world.setBlock(i + 5, j + 13, k + 25, 35);
		world.setBlockMetadata(i + 5, j + 13, k + 25, 13);
		world.setBlock(i + 5, j + 13, k + 30, 35);
		world.setBlockMetadata(i + 5, j + 13, k + 30, 13);
		world.setBlock(i + 5, j + 13, k + 31, 17);
		world.setBlockMetadata(i + 5, j + 13, k + 31, 3);
		world.setBlock(i + 5, j + 13, k + 36, 35);
		world.setBlockMetadata(i + 5, j + 13, k + 36, 13);
		world.setBlock(i + 5, j + 13, k + 37, 17);
		world.setBlockMetadata(i + 5, j + 13, k + 37, 3);
		world.setBlock(i + 5, j + 13, k + 49, 17);
		world.setBlockMetadata(i + 5, j + 13, k + 49, 3);
		world.setBlock(i + 5, j + 13, k + 55, 85);
		world.setBlock(i + 5, j + 13, k + 56, 85);
		world.setBlock(i + 5, j + 13, k + 57, 85);
		world.setBlock(i + 5, j + 14, k + 22, 35);
		world.setBlockMetadata(i + 5, j + 14, k + 22, 13);
		world.setBlock(i + 5, j + 14, k + 25, 35);
		world.setBlockMetadata(i + 5, j + 14, k + 25, 13);
		world.setBlock(i + 5, j + 14, k + 30, 35);
		world.setBlockMetadata(i + 5, j + 14, k + 30, 13);
		world.setBlock(i + 5, j + 14, k + 31, 17);
		world.setBlockMetadata(i + 5, j + 14, k + 31, 3);
		world.setBlock(i + 5, j + 14, k + 36, 35);
		world.setBlockMetadata(i + 5, j + 14, k + 36, 13);
		world.setBlock(i + 5, j + 14, k + 37, 17);
		world.setBlockMetadata(i + 5, j + 14, k + 37, 3);
		world.setBlock(i + 5, j + 14, k + 49, 17);
		world.setBlockMetadata(i + 5, j + 14, k + 49, 3);
		world.setBlock(i + 5, j + 15, k + 23, 35);
		world.setBlockMetadata(i + 5, j + 15, k + 23, 13);
		world.setBlock(i + 5, j + 15, k + 29, 35);
		world.setBlockMetadata(i + 5, j + 15, k + 29, 13);
		world.setBlock(i + 5, j + 15, k + 31, 17);
		world.setBlockMetadata(i + 5, j + 15, k + 31, 3);
		world.setBlock(i + 5, j + 15, k + 37, 17);
		world.setBlockMetadata(i + 5, j + 15, k + 37, 3);
		world.setBlock(i + 5, j + 15, k + 49, 17);
		world.setBlockMetadata(i + 5, j + 15, k + 49, 3);
		world.setBlock(i + 5, j + 15, k + 50, 85);
		world.setBlock(i + 5, j + 15, k + 51, 85);
		world.setBlock(i + 5, j + 15, k + 52, 85);
		world.setBlock(i + 5, j + 16, k + 24, 35);
		world.setBlockMetadata(i + 5, j + 16, k + 24, 13);
		world.setBlock(i + 5, j + 16, k + 30, 35);
		world.setBlockMetadata(i + 5, j + 16, k + 30, 13);
		world.setBlock(i + 5, j + 16, k + 31, 17);
		world.setBlockMetadata(i + 5, j + 16, k + 31, 3);
		world.setBlock(i + 5, j + 16, k + 37, 17);
		world.setBlockMetadata(i + 5, j + 16, k + 37, 3);
		world.setBlock(i + 5, j + 16, k + 49, 17);
		world.setBlockMetadata(i + 5, j + 16, k + 49, 3);
		world.setBlock(i + 5, j + 16, k + 51, 35);
		world.setBlockMetadata(i + 5, j + 16, k + 51, 13);
		world.setBlock(i + 5, j + 16, k + 52, 85);
		world.setBlock(i + 5, j + 17, k + 25, 35);
		world.setBlockMetadata(i + 5, j + 17, k + 25, 13);
		world.setBlock(i + 5, j + 17, k + 30, 35);
		world.setBlockMetadata(i + 5, j + 17, k + 30, 13);
		world.setBlock(i + 5, j + 17, k + 31, 17);
		world.setBlockMetadata(i + 5, j + 17, k + 31, 3);
		world.setBlock(i + 5, j + 17, k + 36, 35);
		world.setBlockMetadata(i + 5, j + 17, k + 36, 13);
		world.setBlock(i + 5, j + 17, k + 37, 17);
		world.setBlockMetadata(i + 5, j + 17, k + 37, 3);
		world.setBlock(i + 5, j + 17, k + 49, 17);
		world.setBlockMetadata(i + 5, j + 17, k + 49, 3);
		world.setBlock(i + 5, j + 17, k + 51, 35);
		world.setBlockMetadata(i + 5, j + 17, k + 51, 13);
		world.setBlock(i + 5, j + 17, k + 52, 35);
		world.setBlockMetadata(i + 5, j + 17, k + 52, 13);
		world.setBlock(i + 5, j + 18, k + 26, 35);
		world.setBlockMetadata(i + 5, j + 18, k + 26, 7);
		world.setBlock(i + 5, j + 18, k + 31, 17);
		world.setBlockMetadata(i + 5, j + 18, k + 31, 3);
		world.setBlock(i + 5, j + 18, k + 36, 35);
		world.setBlockMetadata(i + 5, j + 18, k + 36, 13);
		world.setBlock(i + 5, j + 18, k + 37, 17);
		world.setBlockMetadata(i + 5, j + 18, k + 37, 3);
		world.setBlock(i + 5, j + 18, k + 49, 17);
		world.setBlockMetadata(i + 5, j + 18, k + 49, 3);
		world.setBlock(i + 5, j + 18, k + 51, 35);
		world.setBlockMetadata(i + 5, j + 18, k + 51, 13);
		world.setBlock(i + 5, j + 18, k + 52, 35);
		world.setBlockMetadata(i + 5, j + 18, k + 52, 13);
		world.setBlock(i + 5, j + 19, k + 27, 35);
		world.setBlockMetadata(i + 5, j + 19, k + 27, 7);
		world.setBlock(i + 5, j + 19, k + 31, 17);
		world.setBlockMetadata(i + 5, j + 19, k + 31, 3);
		world.setBlock(i + 5, j + 19, k + 35, 35);
		world.setBlockMetadata(i + 5, j + 19, k + 35, 13);
		world.setBlock(i + 5, j + 19, k + 37, 17);
		world.setBlockMetadata(i + 5, j + 19, k + 37, 3);
		world.setBlock(i + 5, j + 19, k + 49, 17);
		world.setBlockMetadata(i + 5, j + 19, k + 49, 3);
		world.setBlock(i + 5, j + 19, k + 51, 35);
		world.setBlockMetadata(i + 5, j + 19, k + 51, 13);
		world.setBlock(i + 5, j + 19, k + 52, 35);
		world.setBlockMetadata(i + 5, j + 19, k + 52, 13);
		world.setBlock(i + 5, j + 20, k + 28, 35);
		world.setBlockMetadata(i + 5, j + 20, k + 28, 7);
		world.setBlock(i + 5, j + 20, k + 31, 17);
		world.setBlockMetadata(i + 5, j + 20, k + 31, 3);
		world.setBlock(i + 5, j + 20, k + 35, 35);
		world.setBlockMetadata(i + 5, j + 20, k + 35, 13);
		world.setBlock(i + 5, j + 20, k + 37, 17);
		world.setBlockMetadata(i + 5, j + 20, k + 37, 3);
		world.setBlock(i + 5, j + 20, k + 49, 17);
		world.setBlockMetadata(i + 5, j + 20, k + 49, 3);
		world.setBlock(i + 5, j + 20, k + 51, 35);
		world.setBlockMetadata(i + 5, j + 20, k + 51, 13);
		world.setBlock(i + 5, j + 20, k + 52, 35);
		world.setBlockMetadata(i + 5, j + 20, k + 52, 13);
		world.setBlock(i + 5, j + 21, k + 29, 35);
		world.setBlockMetadata(i + 5, j + 21, k + 29, 7);
		world.setBlock(i + 5, j + 21, k + 31, 17);
		world.setBlockMetadata(i + 5, j + 21, k + 31, 3);
		world.setBlock(i + 5, j + 21, k + 36, 35);
		world.setBlockMetadata(i + 5, j + 21, k + 36, 13);
		world.setBlock(i + 5, j + 21, k + 37, 17);
		world.setBlockMetadata(i + 5, j + 21, k + 37, 3);
		world.setBlock(i + 5, j + 21, k + 49, 17);
		world.setBlockMetadata(i + 5, j + 21, k + 49, 3);
		world.setBlock(i + 5, j + 21, k + 51, 35);
		world.setBlockMetadata(i + 5, j + 21, k + 51, 13);
		world.setBlock(i + 5, j + 21, k + 52, 35);
		world.setBlockMetadata(i + 5, j + 21, k + 52, 13);
		world.setBlock(i + 5, j + 22, k + 30, 35);
		world.setBlockMetadata(i + 5, j + 22, k + 30, 7);
		world.setBlock(i + 5, j + 22, k + 31, 17);
		world.setBlockMetadata(i + 5, j + 22, k + 31, 3);
		world.setBlock(i + 5, j + 22, k + 36, 35);
		world.setBlockMetadata(i + 5, j + 22, k + 36, 13);
		world.setBlock(i + 5, j + 22, k + 37, 17);
		world.setBlockMetadata(i + 5, j + 22, k + 37, 3);
		world.setBlock(i + 5, j + 22, k + 49, 17);
		world.setBlockMetadata(i + 5, j + 22, k + 49, 3);
		world.setBlock(i + 5, j + 22, k + 51, 35);
		world.setBlockMetadata(i + 5, j + 22, k + 51, 13);
		world.setBlock(i + 5, j + 22, k + 52, 35);
		world.setBlockMetadata(i + 5, j + 22, k + 52, 13);
		world.setBlock(i + 5, j + 23, k + 31, 44);
		world.setBlockMetadata(i + 5, j + 23, k + 31, 2);
		world.setBlock(i + 5, j + 23, k + 37, 17);
		world.setBlockMetadata(i + 5, j + 23, k + 37, 3);
		world.setBlock(i + 5, j + 23, k + 49, 17);
		world.setBlockMetadata(i + 5, j + 23, k + 49, 3);
		world.setBlock(i + 5, j + 23, k + 51, 35);
		world.setBlockMetadata(i + 5, j + 23, k + 51, 13);
		world.setBlock(i + 5, j + 23, k + 52, 35);
		world.setBlockMetadata(i + 5, j + 23, k + 52, 13);
		world.setBlock(i + 5, j + 24, k + 37, 17);
		world.setBlockMetadata(i + 5, j + 24, k + 37, 3);
		world.setBlock(i + 5, j + 24, k + 49, 17);
		world.setBlockMetadata(i + 5, j + 24, k + 49, 3);
		world.setBlock(i + 5, j + 24, k + 51, 35);
		world.setBlockMetadata(i + 5, j + 24, k + 51, 13);
		world.setBlock(i + 5, j + 24, k + 52, 35);
		world.setBlockMetadata(i + 5, j + 24, k + 52, 13);
		world.setBlock(i + 5, j + 25, k + 37, 17);
		world.setBlockMetadata(i + 5, j + 25, k + 37, 3);
		world.setBlock(i + 5, j + 25, k + 49, 17);
		world.setBlockMetadata(i + 5, j + 25, k + 49, 3);
		world.setBlock(i + 5, j + 25, k + 51, 35);
		world.setBlockMetadata(i + 5, j + 25, k + 51, 13);
		world.setBlock(i + 5, j + 25, k + 52, 35);
		world.setBlockMetadata(i + 5, j + 25, k + 52, 13);
		world.setBlock(i + 5, j + 26, k + 37, 17);
		world.setBlockMetadata(i + 5, j + 26, k + 37, 3);
		world.setBlock(i + 5, j + 26, k + 49, 17);
		world.setBlockMetadata(i + 5, j + 26, k + 49, 3);
		world.setBlock(i + 5, j + 26, k + 50, 85);
		world.setBlock(i + 5, j + 26, k + 51, 85);
		world.setBlock(i + 5, j + 26, k + 52, 85);
		world.setBlock(i + 5, j + 27, k + 36, 53);
		world.setBlockMetadata(i + 5, j + 27, k + 36, 6);
		world.setBlock(i + 5, j + 27, k + 37, 17);
		world.setBlockMetadata(i + 5, j + 27, k + 37, 3);
		world.setBlock(i + 5, j + 27, k + 38, 53);
		world.setBlockMetadata(i + 5, j + 27, k + 38, 7);
		world.setBlock(i + 5, j + 27, k + 49, 44);
		world.setBlockMetadata(i + 5, j + 27, k + 49, 2);
		world.setBlock(i + 5, j + 28, k + 36, 44);
		world.setBlockMetadata(i + 5, j + 28, k + 36, 2);
		world.setBlock(i + 5, j + 28, k + 37, 85);
		world.setBlock(i + 5, j + 28, k + 38, 44);
		world.setBlockMetadata(i + 5, j + 28, k + 38, 2);
		world.setBlock(i + 5, j + 29, k + 37, 85);
		world.setBlock(i + 5, j + 30, k + 37, 85);
		world.setBlock(i + 5, j + 31, k + 37, 85);
		world.setBlock(i + 5, j + 32, k + 31, 35);
		world.setBlockMetadata(i + 5, j + 32, k + 31, 15);
		world.setBlock(i + 5, j + 32, k + 33, 35);
		world.setBlockMetadata(i + 5, j + 32, k + 33, 15);
		world.setBlock(i + 5, j + 32, k + 36, 35);
		world.setBlockMetadata(i + 5, j + 32, k + 36, 15);
		world.setBlock(i + 5, j + 32, k + 37, 85);
		world.setBlock(i + 5, j + 33, k + 31, 35);
		world.setBlockMetadata(i + 5, j + 33, k + 31, 15);
		world.setBlock(i + 5, j + 33, k + 33, 35);
		world.setBlockMetadata(i + 5, j + 33, k + 33, 15);
		world.setBlock(i + 5, j + 33, k + 36, 35);
		world.setBlockMetadata(i + 5, j + 33, k + 36, 15);
		world.setBlock(i + 5, j + 33, k + 37, 85);
		world.setBlock(i + 5, j + 34, k + 31, 35);
		world.setBlockMetadata(i + 5, j + 34, k + 31, 15);
		world.setBlock(i + 5, j + 34, k + 33, 35);
		world.setBlockMetadata(i + 5, j + 34, k + 33, 8);
		world.setBlock(i + 5, j + 34, k + 36, 35);
		world.setBlockMetadata(i + 5, j + 34, k + 36, 15);
		world.setBlock(i + 5, j + 34, k + 37, 85);
		world.setBlock(i + 5, j + 35, k + 31, 35);
		world.setBlockMetadata(i + 5, j + 35, k + 31, 15);
		world.setBlock(i + 5, j + 35, k + 33, 35);
		world.setBlockMetadata(i + 5, j + 35, k + 33, 15);
		world.setBlock(i + 5, j + 35, k + 36, 35);
		world.setBlockMetadata(i + 5, j + 35, k + 36, 15);
		world.setBlock(i + 5, j + 35, k + 37, 85);
		world.setBlock(i + 5, j + 36, k + 31, 35);
		world.setBlockMetadata(i + 5, j + 36, k + 31, 15);
		world.setBlock(i + 5, j + 36, k + 33, 35);
		world.setBlockMetadata(i + 5, j + 36, k + 33, 15);
		world.setBlock(i + 5, j + 36, k + 36, 35);
		world.setBlockMetadata(i + 5, j + 36, k + 36, 15);
		world.setBlock(i + 5, j + 36, k + 37, 85);
		world.setBlock(i + 6, j + 1, k + 31, 5);
		world.setBlock(i + 6, j + 1, k + 32, 5);
		world.setBlock(i + 6, j + 1, k + 33, 5);
		world.setBlock(i + 6, j + 1, k + 34, 5);
		world.setBlock(i + 6, j + 1, k + 35, 5);
		world.setBlock(i + 6, j + 1, k + 36, 5);
		world.setBlock(i + 6, j + 1, k + 37, 5);
		world.setBlock(i + 6, j + 1, k + 38, 5);
		world.setBlock(i + 6, j + 1, k + 39, 5);
		world.setBlock(i + 6, j + 1, k + 40, 5);
		world.setBlock(i + 6, j + 1, k + 41, 5);
		world.setBlock(i + 6, j + 1, k + 42, 5);
		world.setBlock(i + 6, j + 1, k + 43, 5);
		world.setBlock(i + 6, j + 1, k + 44, 5);
		world.setBlock(i + 6, j + 1, k + 45, 5);
		world.setBlock(i + 6, j + 1, k + 46, 5);
		world.setBlock(i + 6, j + 1, k + 47, 5);
		world.setBlock(i + 6, j + 2, k + 28, 5);
		world.setBlock(i + 6, j + 2, k + 29, 5);
		world.setBlock(i + 6, j + 2, k + 30, 5);
		world.setBlock(i + 6, j + 2, k + 31, 44);
		world.setBlockMetadata(i + 6, j + 2, k + 31, 2);
		world.setBlock(i + 6, j + 2, k + 32, 44);
		world.setBlockMetadata(i + 6, j + 2, k + 32, 2);
		world.setBlock(i + 6, j + 2, k + 33, 44);
		world.setBlockMetadata(i + 6, j + 2, k + 33, 2);
		world.setBlock(i + 6, j + 2, k + 34, 44);
		world.setBlockMetadata(i + 6, j + 2, k + 34, 2);
		world.setBlock(i + 6, j + 2, k + 35, 44);
		world.setBlockMetadata(i + 6, j + 2, k + 35, 2);
		world.setBlock(i + 6, j + 2, k + 36, 44);
		world.setBlockMetadata(i + 6, j + 2, k + 36, 2);
		world.setBlock(i + 6, j + 2, k + 37, 44);
		world.setBlockMetadata(i + 6, j + 2, k + 37, 2);
		world.setBlock(i + 6, j + 2, k + 38, 44);
		world.setBlockMetadata(i + 6, j + 2, k + 38, 2);
		world.setBlock(i + 6, j + 2, k + 39, 44);
		world.setBlockMetadata(i + 6, j + 2, k + 39, 2);
		world.setBlock(i + 6, j + 2, k + 40, 44);
		world.setBlockMetadata(i + 6, j + 2, k + 40, 2);
		world.setBlock(i + 6, j + 2, k + 41, 44);
		world.setBlockMetadata(i + 6, j + 2, k + 41, 2);
		world.setBlock(i + 6, j + 2, k + 42, 44);
		world.setBlockMetadata(i + 6, j + 2, k + 42, 2);
		world.setBlock(i + 6, j + 2, k + 43, 44);
		world.setBlockMetadata(i + 6, j + 2, k + 43, 2);
		world.setBlock(i + 6, j + 2, k + 44, 44);
		world.setBlockMetadata(i + 6, j + 2, k + 44, 2);
		world.setBlock(i + 6, j + 2, k + 45, 44);
		world.setBlockMetadata(i + 6, j + 2, k + 45, 2);
		world.setBlock(i + 6, j + 2, k + 46, 44);
		world.setBlockMetadata(i + 6, j + 2, k + 46, 2);
		world.setBlock(i + 6, j + 2, k + 47, 44);
		world.setBlockMetadata(i + 6, j + 2, k + 47, 2);
		world.setBlock(i + 6, j + 2, k + 48, 5);
		world.setBlock(i + 6, j + 3, k + 27, 5);
		world.setBlock(i + 6, j + 3, k + 28, 5);
		world.setBlock(i + 6, j + 3, k + 49, 5);
		world.setBlock(i + 6, j + 4, k + 26, 17);
		world.setBlockMetadata(i + 6, j + 4, k + 26, 3);
		world.setBlock(i + 6, j + 4, k + 27, 17);
		world.setBlockMetadata(i + 6, j + 4, k + 27, 3);
		world.setBlock(i + 6, j + 4, k + 50, 17);
		world.setBlockMetadata(i + 6, j + 4, k + 50, 3);
		world.setBlock(i + 6, j + 5, k + 25, 5);
		world.setBlock(i + 6, j + 5, k + 26, 5);
		world.setBlock(i + 6, j + 5, k + 27, 5);
		world.setBlock(i + 6, j + 5, k + 28, 44);
		world.setBlockMetadata(i + 6, j + 5, k + 28, 10);
		world.setBlock(i + 6, j + 5, k + 29, 44);
		world.setBlockMetadata(i + 6, j + 5, k + 29, 10);
		world.setBlock(i + 6, j + 5, k + 30, 44);
		world.setBlockMetadata(i + 6, j + 5, k + 30, 10);
		world.setBlock(i + 6, j + 5, k + 31, 44);
		world.setBlockMetadata(i + 6, j + 5, k + 31, 10);
		world.setBlock(i + 6, j + 5, k + 32, 5);
		world.setBlock(i + 6, j + 5, k + 35, 5);
		world.setBlock(i + 6, j + 5, k + 36, 44);
		world.setBlockMetadata(i + 6, j + 5, k + 36, 10);
		world.setBlock(i + 6, j + 5, k + 37, 44);
		world.setBlockMetadata(i + 6, j + 5, k + 37, 10);
		world.setBlock(i + 6, j + 5, k + 38, 44);
		world.setBlockMetadata(i + 6, j + 5, k + 38, 10);
		world.setBlock(i + 6, j + 5, k + 39, 44);
		world.setBlockMetadata(i + 6, j + 5, k + 39, 10);
		world.setBlock(i + 6, j + 5, k + 40, 44);
		world.setBlockMetadata(i + 6, j + 5, k + 40, 10);
		world.setBlock(i + 6, j + 5, k + 41, 44);
		world.setBlockMetadata(i + 6, j + 5, k + 41, 10);
		world.setBlock(i + 6, j + 5, k + 42, 44);
		world.setBlockMetadata(i + 6, j + 5, k + 42, 10);
		world.setBlock(i + 6, j + 5, k + 43, 44);
		world.setBlockMetadata(i + 6, j + 5, k + 43, 10);
		world.setBlock(i + 6, j + 5, k + 44, 44);
		world.setBlockMetadata(i + 6, j + 5, k + 44, 10);
		world.setBlock(i + 6, j + 5, k + 45, 44);
		world.setBlockMetadata(i + 6, j + 5, k + 45, 10);
		world.setBlock(i + 6, j + 5, k + 46, 44);
		world.setBlockMetadata(i + 6, j + 5, k + 46, 10);
		world.setBlock(i + 6, j + 5, k + 47, 44);
		world.setBlockMetadata(i + 6, j + 5, k + 47, 10);
		world.setBlock(i + 6, j + 5, k + 48, 44);
		world.setBlockMetadata(i + 6, j + 5, k + 48, 10);
		world.setBlock(i + 6, j + 5, k + 49, 44);
		world.setBlockMetadata(i + 6, j + 5, k + 49, 10);
		world.setBlock(i + 6, j + 5, k + 50, 5);
		world.setBlock(i + 6, j + 5, k + 51, 53);
		world.setBlockMetadata(i + 6, j + 5, k + 51, 7);
		world.setBlock(i + 6, j + 6, k + 24, 44);
		world.setBlockMetadata(i + 6, j + 6, k + 24, 10);
		world.setBlock(i + 6, j + 6, k + 25, 44);
		world.setBlockMetadata(i + 6, j + 6, k + 25, 2);
		world.setBlock(i + 6, j + 6, k + 30, 44);
		world.setBlockMetadata(i + 6, j + 6, k + 30, 2);
		world.setBlock(i + 6, j + 6, k + 31, 44);
		world.setBlockMetadata(i + 6, j + 6, k + 31, 2);
		world.setBlock(i + 6, j + 6, k + 32, 44);
		world.setBlockMetadata(i + 6, j + 6, k + 32, 2);
		world.setBlock(i + 6, j + 6, k + 35, 44);
		world.setBlockMetadata(i + 6, j + 6, k + 35, 2);
		world.setBlock(i + 6, j + 6, k + 36, 44);
		world.setBlockMetadata(i + 6, j + 6, k + 36, 2);
		world.setBlock(i + 6, j + 6, k + 37, 44);
		world.setBlockMetadata(i + 6, j + 6, k + 37, 2);
		world.setBlock(i + 6, j + 6, k + 38, 44);
		world.setBlockMetadata(i + 6, j + 6, k + 38, 2);
		world.setBlock(i + 6, j + 6, k + 41, 17);
		world.setBlockMetadata(i + 6, j + 6, k + 41, 3);
		world.setBlock(i + 6, j + 6, k + 42, 5);
		world.setBlockMetadata(i + 6, j + 6, k + 42, 3);
		world.setBlock(i + 6, j + 6, k + 43, 5);
		world.setBlockMetadata(i + 6, j + 6, k + 43, 3);
		world.setBlock(i + 6, j + 6, k + 44, 5);
		world.setBlock(i + 6, j + 6, k + 48, 44);
		world.setBlockMetadata(i + 6, j + 6, k + 48, 10);
		world.setBlock(i + 6, j + 6, k + 51, 17);
		world.setBlockMetadata(i + 6, j + 6, k + 51, 3);
		world.setBlock(i + 6, j + 7, k + 24, 85);
		world.setBlock(i + 6, j + 7, k + 41, 85);
		world.setBlock(i + 6, j + 7, k + 42, 17);
		world.setBlockMetadata(i + 6, j + 7, k + 42, 3);
		world.setBlock(i + 6, j + 7, k + 43, 5);
		world.setBlockMetadata(i + 6, j + 7, k + 43, 3);
		world.setBlock(i + 6, j + 7, k + 44, 5);
		world.setBlock(i + 6, j + 7, k + 51, 102);
		world.setBlock(i + 6, j + 7, k + 57, 44);
		world.setBlockMetadata(i + 6, j + 7, k + 57, 13);
		world.setBlock(i + 6, j + 7, k + 58, 109);
		world.setBlockMetadata(i + 6, j + 7, k + 58, 5);
		world.setBlock(i + 6, j + 7, k + 59, 44);
		world.setBlockMetadata(i + 6, j + 7, k + 59, 13);
		world.setBlock(i + 6, j + 8, k + 42, 85);
		world.setBlock(i + 6, j + 8, k + 43, 17);
		world.setBlockMetadata(i + 6, j + 8, k + 43, 3);
		world.setBlock(i + 6, j + 8, k + 44, 5);
		world.setBlock(i + 6, j + 8, k + 51, 102);
		world.setBlock(i + 6, j + 8, k + 57, 101);
		world.setBlock(i + 6, j + 8, k + 58, 101);
		world.setBlock(i + 6, j + 8, k + 59, 101);
		world.setBlock(i + 6, j + 9, k + 43, 85);
		world.setBlock(i + 6, j + 9, k + 44, 17);
		world.setBlockMetadata(i + 6, j + 9, k + 44, 3);
		world.setBlock(i + 6, j + 9, k + 45, 17);
		world.setBlockMetadata(i + 6, j + 9, k + 45, 3);
		world.setBlock(i + 6, j + 9, k + 46, 44);
		world.setBlockMetadata(i + 6, j + 9, k + 46, 10);
		world.setBlock(i + 6, j + 9, k + 47, 44);
		world.setBlockMetadata(i + 6, j + 9, k + 47, 10);
		world.setBlock(i + 6, j + 9, k + 48, 17);
		world.setBlockMetadata(i + 6, j + 9, k + 48, 3);
		world.setBlock(i + 6, j + 9, k + 49, 44);
		world.setBlockMetadata(i + 6, j + 9, k + 49, 10);
		world.setBlock(i + 6, j + 9, k + 50, 44);
		world.setBlockMetadata(i + 6, j + 9, k + 50, 10);
		world.setBlock(i + 6, j + 9, k + 51, 17);
		world.setBlockMetadata(i + 6, j + 9, k + 51, 3);
		world.setBlock(i + 6, j + 9, k + 57, 44);
		world.setBlockMetadata(i + 6, j + 9, k + 57, 5);
		world.setBlock(i + 6, j + 9, k + 58, 109);
		world.setBlockMetadata(i + 6, j + 9, k + 58, 1);
		world.setBlock(i + 6, j + 9, k + 59, 44);
		world.setBlockMetadata(i + 6, j + 9, k + 59, 5);
		world.setBlock(i + 6, j + 10, k + 35, 35);
		world.setBlockMetadata(i + 6, j + 10, k + 35, 13);
		world.setBlock(i + 6, j + 10, k + 44, 85);
		world.setBlock(i + 6, j + 10, k + 48, 44);
		world.setBlockMetadata(i + 6, j + 10, k + 48, 2);
		world.setBlock(i + 6, j + 10, k + 49, 44);
		world.setBlockMetadata(i + 6, j + 10, k + 49, 2);
		world.setBlock(i + 6, j + 10, k + 50, 44);
		world.setBlockMetadata(i + 6, j + 10, k + 50, 2);
		world.setBlock(i + 6, j + 10, k + 52, 44);
		world.setBlockMetadata(i + 6, j + 10, k + 52, 2);
		world.setBlock(i + 6, j + 10, k + 53, 44);
		world.setBlockMetadata(i + 6, j + 10, k + 53, 10);
		world.setBlock(i + 6, j + 11, k + 35, 35);
		world.setBlockMetadata(i + 6, j + 11, k + 35, 13);
		world.setBlock(i + 6, j + 11, k + 53, 85);
		world.setBlock(i + 6, j + 12, k + 34, 35);
		world.setBlockMetadata(i + 6, j + 12, k + 34, 13);
		world.setBlock(i + 6, j + 13, k + 29, 35);
		world.setBlockMetadata(i + 6, j + 13, k + 29, 13);
		world.setBlock(i + 6, j + 13, k + 35, 35);
		world.setBlockMetadata(i + 6, j + 13, k + 35, 13);
		world.setBlock(i + 6, j + 14, k + 29, 35);
		world.setBlockMetadata(i + 6, j + 14, k + 29, 13);
		world.setBlock(i + 6, j + 14, k + 35, 35);
		world.setBlockMetadata(i + 6, j + 14, k + 35, 13);
		world.setBlock(i + 6, j + 15, k + 28, 35);
		world.setBlockMetadata(i + 6, j + 15, k + 28, 13);
		world.setBlock(i + 6, j + 15, k + 36, 17);
		world.setBlockMetadata(i + 6, j + 15, k + 36, 3);
		world.setBlock(i + 6, j + 16, k + 29, 35);
		world.setBlockMetadata(i + 6, j + 16, k + 29, 13);
		world.setBlock(i + 6, j + 16, k + 52, 85);
		world.setBlock(i + 6, j + 16, k + 53, 85);
		world.setBlock(i + 6, j + 16, k + 54, 85);
		world.setBlock(i + 6, j + 17, k + 29, 35);
		world.setBlockMetadata(i + 6, j + 17, k + 29, 13);
		world.setBlock(i + 6, j + 17, k + 36, 35);
		world.setBlockMetadata(i + 6, j + 17, k + 36, 13);
		world.setBlock(i + 6, j + 17, k + 53, 35);
		world.setBlockMetadata(i + 6, j + 17, k + 53, 13);
		world.setBlock(i + 6, j + 17, k + 54, 85);
		world.setBlock(i + 6, j + 18, k + 30, 17);
		world.setBlockMetadata(i + 6, j + 18, k + 30, 3);
		world.setBlock(i + 6, j + 18, k + 35, 35);
		world.setBlockMetadata(i + 6, j + 18, k + 35, 13);
		world.setBlock(i + 6, j + 18, k + 53, 35);
		world.setBlockMetadata(i + 6, j + 18, k + 53, 13);
		world.setBlock(i + 6, j + 18, k + 54, 35);
		world.setBlockMetadata(i + 6, j + 18, k + 54, 13);
		world.setBlock(i + 6, j + 19, k + 34, 35);
		world.setBlockMetadata(i + 6, j + 19, k + 34, 13);
		world.setBlock(i + 6, j + 19, k + 53, 35);
		world.setBlockMetadata(i + 6, j + 19, k + 53, 13);
		world.setBlock(i + 6, j + 19, k + 54, 35);
		world.setBlockMetadata(i + 6, j + 19, k + 54, 13);
		world.setBlock(i + 6, j + 20, k + 34, 35);
		world.setBlockMetadata(i + 6, j + 20, k + 34, 13);
		world.setBlock(i + 6, j + 20, k + 53, 35);
		world.setBlockMetadata(i + 6, j + 20, k + 53, 13);
		world.setBlock(i + 6, j + 20, k + 54, 35);
		world.setBlockMetadata(i + 6, j + 20, k + 54, 13);
		world.setBlock(i + 6, j + 21, k + 35, 35);
		world.setBlockMetadata(i + 6, j + 21, k + 35, 13);
		world.setBlock(i + 6, j + 21, k + 53, 35);
		world.setBlockMetadata(i + 6, j + 21, k + 53, 13);
		world.setBlock(i + 6, j + 21, k + 54, 35);
		world.setBlockMetadata(i + 6, j + 21, k + 54, 13);
		world.setBlock(i + 6, j + 22, k + 35, 35);
		world.setBlockMetadata(i + 6, j + 22, k + 35, 13);
		world.setBlock(i + 6, j + 22, k + 53, 35);
		world.setBlockMetadata(i + 6, j + 22, k + 53, 13);
		world.setBlock(i + 6, j + 22, k + 54, 35);
		world.setBlockMetadata(i + 6, j + 22, k + 54, 13);
		world.setBlock(i + 6, j + 23, k + 36, 17);
		world.setBlockMetadata(i + 6, j + 23, k + 36, 3);
		world.setBlock(i + 6, j + 23, k + 53, 35);
		world.setBlockMetadata(i + 6, j + 23, k + 53, 13);
		world.setBlock(i + 6, j + 23, k + 54, 35);
		world.setBlockMetadata(i + 6, j + 23, k + 54, 13);
		world.setBlock(i + 6, j + 24, k + 53, 35);
		world.setBlockMetadata(i + 6, j + 24, k + 53, 13);
		world.setBlock(i + 6, j + 24, k + 54, 35);
		world.setBlockMetadata(i + 6, j + 24, k + 54, 13);
		world.setBlock(i + 6, j + 25, k + 53, 35);
		world.setBlockMetadata(i + 6, j + 25, k + 53, 13);
		world.setBlock(i + 6, j + 25, k + 54, 35);
		world.setBlockMetadata(i + 6, j + 25, k + 54, 13);
		world.setBlock(i + 6, j + 26, k + 52, 85);
		world.setBlock(i + 6, j + 26, k + 53, 85);
		world.setBlock(i + 6, j + 26, k + 54, 85);
		world.setBlock(i + 6, j + 27, k + 37, 53);
		world.setBlockMetadata(i + 6, j + 27, k + 37, 5);
		world.setBlock(i + 6, j + 28, k + 37, 44);
		world.setBlockMetadata(i + 6, j + 28, k + 37, 2);
		world.setBlock(i + 6, j + 32, k + 34, 35);
		world.setBlockMetadata(i + 6, j + 32, k + 34, 15);
		world.setBlock(i + 6, j + 32, k + 35, 35);
		world.setBlockMetadata(i + 6, j + 32, k + 35, 15);
		world.setBlock(i + 6, j + 33, k + 34, 35);
		world.setBlockMetadata(i + 6, j + 33, k + 34, 15);
		world.setBlock(i + 6, j + 33, k + 35, 35);
		world.setBlockMetadata(i + 6, j + 33, k + 35, 8);
		world.setBlock(i + 6, j + 34, k + 34, 35);
		world.setBlockMetadata(i + 6, j + 34, k + 34, 8);
		world.setBlock(i + 6, j + 34, k + 35, 35);
		world.setBlockMetadata(i + 6, j + 34, k + 35, 15);
		world.setBlock(i + 6, j + 35, k + 34, 35);
		world.setBlockMetadata(i + 6, j + 35, k + 34, 15);
		world.setBlock(i + 6, j + 35, k + 35, 35);
		world.setBlockMetadata(i + 6, j + 35, k + 35, 8);
		world.setBlock(i + 6, j + 36, k + 34, 35);
		world.setBlockMetadata(i + 6, j + 36, k + 34, 15);
		world.setBlock(i + 6, j + 36, k + 35, 35);
		world.setBlockMetadata(i + 6, j + 36, k + 35, 15);
		world.setBlock(i + 7, j + 2, k + 31, 5);
		world.setBlock(i + 7, j + 2, k + 32, 53);
		world.setBlock(i + 7, j + 2, k + 33, 5);
		world.setBlock(i + 7, j + 2, k + 34, 53);
		world.setBlock(i + 7, j + 2, k + 35, 5);
		world.setBlock(i + 7, j + 2, k + 36, 53);
		world.setBlock(i + 7, j + 2, k + 37, 5);
		world.setBlock(i + 7, j + 2, k + 38, 53);
		world.setBlock(i + 7, j + 2, k + 39, 5);
		world.setBlock(i + 7, j + 2, k + 40, 53);
		world.setBlock(i + 7, j + 2, k + 41, 5);
		world.setBlock(i + 7, j + 2, k + 42, 53);
		world.setBlock(i + 7, j + 2, k + 43, 5);
		world.setBlock(i + 7, j + 2, k + 44, 53);
		world.setBlock(i + 7, j + 2, k + 45, 5);
		world.setBlock(i + 7, j + 2, k + 46, 53);
		world.setBlock(i + 7, j + 2, k + 47, 5);
		world.setBlock(i + 7, j + 3, k + 29, 5);
		world.setBlock(i + 7, j + 3, k + 30, 5);
		world.setBlock(i + 7, j + 3, k + 35, 5);
		world.setBlock(i + 7, j + 3, k + 39, 5);
		world.setBlock(i + 7, j + 3, k + 43, 5);
		world.setBlock(i + 7, j + 3, k + 48, 5);
		world.setBlock(i + 7, j + 4, k + 28, 17);
		world.setBlockMetadata(i + 7, j + 4, k + 28, 3);
		world.setBlock(i + 7, j + 4, k + 29, 17);
		world.setBlockMetadata(i + 7, j + 4, k + 29, 3);
		world.setBlock(i + 7, j + 4, k + 30, 17);
		world.setBlockMetadata(i + 7, j + 4, k + 30, 3);
		world.setBlock(i + 7, j + 4, k + 35, 23);
		world.setBlockMetadata(i + 7, j + 4, k + 35, 5);
		world.setBlock(i + 7, j + 4, k + 39, 23);
		world.setBlockMetadata(i + 7, j + 4, k + 39, 5);
		world.setBlock(i + 7, j + 4, k + 43, 23);
		world.setBlockMetadata(i + 7, j + 4, k + 43, 5);
		world.setBlock(i + 7, j + 4, k + 48, 17);
		world.setBlockMetadata(i + 7, j + 4, k + 48, 3);
		world.setBlock(i + 7, j + 4, k + 49, 17);
		world.setBlockMetadata(i + 7, j + 4, k + 49, 3);
		world.setBlock(i + 7, j + 5, k + 26, 5);
		world.setBlock(i + 7, j + 5, k + 27, 5);
		world.setBlock(i + 7, j + 5, k + 28, 5);
		world.setBlock(i + 7, j + 5, k + 29, 5);
		world.setBlock(i + 7, j + 5, k + 30, 5);
		world.setBlock(i + 7, j + 5, k + 31, 44);
		world.setBlockMetadata(i + 7, j + 5, k + 31, 10);
		world.setBlock(i + 7, j + 5, k + 32, 44);
		world.setBlockMetadata(i + 7, j + 5, k + 32, 10);
		world.setBlock(i + 7, j + 5, k + 33, 5);
		world.setBlock(i + 7, j + 5, k + 34, 5);
		world.setBlock(i + 7, j + 5, k + 35, 44);
		world.setBlockMetadata(i + 7, j + 5, k + 35, 10);
		world.setBlock(i + 7, j + 5, k + 36, 44);
		world.setBlockMetadata(i + 7, j + 5, k + 36, 10);
		world.setBlock(i + 7, j + 5, k + 37, 44);
		world.setBlockMetadata(i + 7, j + 5, k + 37, 10);
		world.setBlock(i + 7, j + 5, k + 38, 44);
		world.setBlockMetadata(i + 7, j + 5, k + 38, 10);
		world.setBlock(i + 7, j + 5, k + 39, 44);
		world.setBlockMetadata(i + 7, j + 5, k + 39, 10);
		world.setBlock(i + 7, j + 5, k + 40, 44);
		world.setBlockMetadata(i + 7, j + 5, k + 40, 10);
		world.setBlock(i + 7, j + 5, k + 41, 44);
		world.setBlockMetadata(i + 7, j + 5, k + 41, 10);
		world.setBlock(i + 7, j + 5, k + 42, 44);
		world.setBlockMetadata(i + 7, j + 5, k + 42, 10);
		world.setBlock(i + 7, j + 5, k + 43, 44);
		world.setBlockMetadata(i + 7, j + 5, k + 43, 10);
		world.setBlock(i + 7, j + 5, k + 44, 44);
		world.setBlockMetadata(i + 7, j + 5, k + 44, 10);
		world.setBlock(i + 7, j + 5, k + 45, 44);
		world.setBlockMetadata(i + 7, j + 5, k + 45, 10);
		world.setBlock(i + 7, j + 5, k + 46, 44);
		world.setBlockMetadata(i + 7, j + 5, k + 46, 10);
		world.setBlock(i + 7, j + 5, k + 47, 44);
		world.setBlockMetadata(i + 7, j + 5, k + 47, 10);
		world.setBlock(i + 7, j + 5, k + 48, 5);
		world.setBlock(i + 7, j + 5, k + 49, 5);
		world.setBlock(i + 7, j + 5, k + 50, 44);
		world.setBlockMetadata(i + 7, j + 5, k + 50, 10);
		world.setBlock(i + 7, j + 5, k + 51, 44);
		world.setBlockMetadata(i + 7, j + 5, k + 51, 10);
		world.setBlock(i + 7, j + 6, k + 25, 44);
		world.setBlockMetadata(i + 7, j + 6, k + 25, 10);
		world.setBlock(i + 7, j + 6, k + 26, 44);
		world.setBlockMetadata(i + 7, j + 6, k + 26, 2);
		world.setBlock(i + 7, j + 6, k + 27, 44);
		world.setBlockMetadata(i + 7, j + 6, k + 27, 2);
		world.setBlock(i + 7, j + 6, k + 28, 44);
		world.setBlockMetadata(i + 7, j + 6, k + 28, 2);
		world.setBlock(i + 7, j + 6, k + 41, 53);
		world.setBlockMetadata(i + 7, j + 6, k + 41, 2);
		world.setBlock(i + 7, j + 6, k + 42, 5);
		world.setBlockMetadata(i + 7, j + 6, k + 42, 3);
		world.setBlock(i + 7, j + 6, k + 43, 5);
		world.setBlockMetadata(i + 7, j + 6, k + 43, 3);
		world.setBlock(i + 7, j + 6, k + 44, 5);
		world.setBlock(i + 7, j + 6, k + 51, 17);
		world.setBlockMetadata(i + 7, j + 6, k + 51, 3);
		world.setBlock(i + 7, j + 7, k + 24, 85);
		world.setBlock(i + 7, j + 7, k + 25, 85);
		world.setBlock(i + 7, j + 7, k + 42, 53);
		world.setBlockMetadata(i + 7, j + 7, k + 42, 2);
		world.setBlock(i + 7, j + 7, k + 43, 5);
		world.setBlockMetadata(i + 7, j + 7, k + 43, 3);
		world.setBlock(i + 7, j + 7, k + 44, 5);
		world.setBlock(i + 7, j + 7, k + 51, 17);
		world.setBlockMetadata(i + 7, j + 7, k + 51, 3);
		world.setBlock(i + 7, j + 8, k + 43, 53);
		world.setBlockMetadata(i + 7, j + 8, k + 43, 2);
		world.setBlock(i + 7, j + 8, k + 44, 5);
		world.setBlock(i + 7, j + 8, k + 51, 17);
		world.setBlockMetadata(i + 7, j + 8, k + 51, 3);
		world.setBlock(i + 7, j + 9, k + 44, 53);
		world.setBlockMetadata(i + 7, j + 9, k + 44, 2);
		world.setBlock(i + 7, j + 9, k + 45, 17);
		world.setBlockMetadata(i + 7, j + 9, k + 45, 3);
		world.setBlock(i + 7, j + 9, k + 46, 53);
		world.setBlockMetadata(i + 7, j + 9, k + 46, 4);
		world.setBlock(i + 7, j + 9, k + 47, 53);
		world.setBlockMetadata(i + 7, j + 9, k + 47, 4);
		world.setBlock(i + 7, j + 9, k + 48, 17);
		world.setBlockMetadata(i + 7, j + 9, k + 48, 3);
		world.setBlock(i + 7, j + 9, k + 49, 53);
		world.setBlockMetadata(i + 7, j + 9, k + 49, 4);
		world.setBlock(i + 7, j + 9, k + 50, 53);
		world.setBlockMetadata(i + 7, j + 9, k + 50, 4);
		world.setBlock(i + 7, j + 9, k + 51, 17);
		world.setBlockMetadata(i + 7, j + 9, k + 51, 3);
		world.setBlock(i + 7, j + 10, k + 35, 35);
		world.setBlockMetadata(i + 7, j + 10, k + 35, 13);
		world.setBlock(i + 7, j + 10, k + 52, 44);
		world.setBlockMetadata(i + 7, j + 10, k + 52, 2);
		world.setBlock(i + 7, j + 10, k + 53, 44);
		world.setBlockMetadata(i + 7, j + 10, k + 53, 10);
		world.setBlock(i + 7, j + 11, k + 35, 35);
		world.setBlockMetadata(i + 7, j + 11, k + 35, 13);
		world.setBlock(i + 7, j + 11, k + 53, 85);
		world.setBlock(i + 7, j + 12, k + 34, 35);
		world.setBlockMetadata(i + 7, j + 12, k + 34, 13);
		world.setBlock(i + 7, j + 13, k + 29, 35);
		world.setBlockMetadata(i + 7, j + 13, k + 29, 13);
		world.setBlock(i + 7, j + 13, k + 35, 35);
		world.setBlockMetadata(i + 7, j + 13, k + 35, 13);
		world.setBlock(i + 7, j + 14, k + 29, 35);
		world.setBlockMetadata(i + 7, j + 14, k + 29, 13);
		world.setBlock(i + 7, j + 14, k + 35, 35);
		world.setBlockMetadata(i + 7, j + 14, k + 35, 13);
		world.setBlock(i + 7, j + 15, k + 28, 35);
		world.setBlockMetadata(i + 7, j + 15, k + 28, 13);
		world.setBlock(i + 7, j + 15, k + 36, 17);
		world.setBlockMetadata(i + 7, j + 15, k + 36, 3);
		world.setBlock(i + 7, j + 16, k + 29, 35);
		world.setBlockMetadata(i + 7, j + 16, k + 29, 13);
		world.setBlock(i + 7, j + 17, k + 29, 35);
		world.setBlockMetadata(i + 7, j + 17, k + 29, 13);
		world.setBlock(i + 7, j + 17, k + 36, 35);
		world.setBlockMetadata(i + 7, j + 17, k + 36, 13);
		world.setBlock(i + 7, j + 17, k + 54, 85);
		world.setBlock(i + 7, j + 17, k + 55, 85);
		world.setBlock(i + 7, j + 17, k + 56, 85);
		world.setBlock(i + 7, j + 18, k + 30, 17);
		world.setBlockMetadata(i + 7, j + 18, k + 30, 3);
		world.setBlock(i + 7, j + 18, k + 35, 35);
		world.setBlockMetadata(i + 7, j + 18, k + 35, 13);
		world.setBlock(i + 7, j + 18, k + 55, 35);
		world.setBlockMetadata(i + 7, j + 18, k + 55, 13);
		world.setBlock(i + 7, j + 18, k + 56, 35);
		world.setBlockMetadata(i + 7, j + 18, k + 56, 13);
		world.setBlock(i + 7, j + 19, k + 34, 35);
		world.setBlockMetadata(i + 7, j + 19, k + 34, 13);
		world.setBlock(i + 7, j + 19, k + 55, 35);
		world.setBlockMetadata(i + 7, j + 19, k + 55, 13);
		world.setBlock(i + 7, j + 19, k + 56, 35);
		world.setBlockMetadata(i + 7, j + 19, k + 56, 13);
		world.setBlock(i + 7, j + 20, k + 34, 35);
		world.setBlockMetadata(i + 7, j + 20, k + 34, 13);
		world.setBlock(i + 7, j + 20, k + 55, 35);
		world.setBlockMetadata(i + 7, j + 20, k + 55, 13);
		world.setBlock(i + 7, j + 20, k + 56, 35);
		world.setBlockMetadata(i + 7, j + 20, k + 56, 13);
		world.setBlock(i + 7, j + 21, k + 35, 35);
		world.setBlockMetadata(i + 7, j + 21, k + 35, 13);
		world.setBlock(i + 7, j + 21, k + 55, 35);
		world.setBlockMetadata(i + 7, j + 21, k + 55, 13);
		world.setBlock(i + 7, j + 21, k + 56, 35);
		world.setBlockMetadata(i + 7, j + 21, k + 56, 13);
		world.setBlock(i + 7, j + 22, k + 35, 35);
		world.setBlockMetadata(i + 7, j + 22, k + 35, 13);
		world.setBlock(i + 7, j + 22, k + 55, 35);
		world.setBlockMetadata(i + 7, j + 22, k + 55, 13);
		world.setBlock(i + 7, j + 22, k + 56, 35);
		world.setBlockMetadata(i + 7, j + 22, k + 56, 13);
		world.setBlock(i + 7, j + 23, k + 36, 17);
		world.setBlockMetadata(i + 7, j + 23, k + 36, 3);
		world.setBlock(i + 7, j + 23, k + 55, 35);
		world.setBlockMetadata(i + 7, j + 23, k + 55, 13);
		world.setBlock(i + 7, j + 23, k + 56, 35);
		world.setBlockMetadata(i + 7, j + 23, k + 56, 13);
		world.setBlock(i + 7, j + 24, k + 55, 35);
		world.setBlockMetadata(i + 7, j + 24, k + 55, 13);
		world.setBlock(i + 7, j + 25, k + 55, 35);
		world.setBlockMetadata(i + 7, j + 25, k + 55, 13);
		world.setBlock(i + 7, j + 26, k + 54, 85);
		world.setBlock(i + 7, j + 26, k + 55, 85);
		world.setBlock(i + 8, j + 0, k + 49, 35);
		world.setBlockMetadata(i + 8, j + 0, k + 49, 11);
		world.setBlock(i + 8, j + 1, k + 49, 35);
		world.setBlockMetadata(i + 8, j + 1, k + 49, 11);
		world.setBlock(i + 8, j + 2, k + 49, 35);
		world.setBlockMetadata(i + 8, j + 2, k + 49, 11);
		world.setBlock(i + 8, j + 3, k + 31, 5);
		world.setBlock(i + 8, j + 3, k + 32, 5);
		world.setBlock(i + 8, j + 3, k + 33, 5);
		world.setBlock(i + 8, j + 3, k + 34, 5);
		world.setBlock(i + 8, j + 3, k + 35, 5);
		world.setBlock(i + 8, j + 3, k + 36, 5);
		world.setBlock(i + 8, j + 3, k + 37, 5);
		world.setBlock(i + 8, j + 3, k + 38, 5);
		world.setBlock(i + 8, j + 3, k + 39, 5);
		world.setBlock(i + 8, j + 3, k + 40, 5);
		world.setBlock(i + 8, j + 3, k + 41, 5);
		world.setBlock(i + 8, j + 3, k + 42, 5);
		world.setBlock(i + 8, j + 3, k + 43, 5);
		world.setBlock(i + 8, j + 3, k + 44, 5);
		world.setBlock(i + 8, j + 3, k + 45, 5);
		world.setBlock(i + 8, j + 3, k + 46, 5);
		world.setBlock(i + 8, j + 3, k + 47, 5);
		world.setBlock(i + 8, j + 3, k + 49, 35);
		world.setBlockMetadata(i + 8, j + 3, k + 49, 11);
		world.setBlock(i + 8, j + 4, k + 31, 17);
		world.setBlockMetadata(i + 8, j + 4, k + 31, 3);
		world.setBlock(i + 8, j + 4, k + 32, 17);
		world.setBlockMetadata(i + 8, j + 4, k + 32, 3);
		world.setBlock(i + 8, j + 4, k + 33, 17);
		world.setBlock(i + 8, j + 4, k + 34, 17);
		world.setBlockMetadata(i + 8, j + 4, k + 34, 3);
		world.setBlock(i + 8, j + 4, k + 36, 17);
		world.setBlockMetadata(i + 8, j + 4, k + 36, 3);
		world.setBlock(i + 8, j + 4, k + 37, 17);
		world.setBlock(i + 8, j + 4, k + 38, 17);
		world.setBlockMetadata(i + 8, j + 4, k + 38, 3);
		world.setBlock(i + 8, j + 4, k + 40, 17);
		world.setBlockMetadata(i + 8, j + 4, k + 40, 3);
		world.setBlock(i + 8, j + 4, k + 41, 17);
		world.setBlock(i + 8, j + 4, k + 42, 17);
		world.setBlockMetadata(i + 8, j + 4, k + 42, 3);
		world.setBlock(i + 8, j + 4, k + 44, 17);
		world.setBlockMetadata(i + 8, j + 4, k + 44, 3);
		world.setBlock(i + 8, j + 4, k + 45, 17);
		world.setBlock(i + 8, j + 4, k + 46, 17);
		world.setBlockMetadata(i + 8, j + 4, k + 46, 3);
		world.setBlock(i + 8, j + 4, k + 47, 17);
		world.setBlockMetadata(i + 8, j + 4, k + 47, 3);
		world.setBlock(i + 8, j + 4, k + 48, 17);
		world.setBlockMetadata(i + 8, j + 4, k + 48, 3);
		world.setBlock(i + 8, j + 5, k + 29, 5);
		world.setBlock(i + 8, j + 5, k + 30, 5);
		world.setBlock(i + 8, j + 5, k + 31, 5);
		world.setBlock(i + 8, j + 5, k + 32, 5);
		world.setBlock(i + 8, j + 5, k + 33, 5);
		world.setBlock(i + 8, j + 5, k + 34, 5);
		world.setBlock(i + 8, j + 5, k + 35, 5);
		world.setBlock(i + 8, j + 5, k + 36, 5);
		world.setBlock(i + 8, j + 5, k + 37, 5);
		world.setBlock(i + 8, j + 5, k + 38, 5);
		world.setBlock(i + 8, j + 5, k + 39, 5);
		world.setBlock(i + 8, j + 5, k + 40, 5);
		world.setBlock(i + 8, j + 5, k + 41, 5);
		world.setBlock(i + 8, j + 5, k + 42, 5);
		world.setBlock(i + 8, j + 5, k + 43, 5);
		world.setBlock(i + 8, j + 5, k + 44, 5);
		world.setBlock(i + 8, j + 5, k + 45, 5);
		world.setBlock(i + 8, j + 5, k + 46, 5);
		world.setBlock(i + 8, j + 5, k + 47, 5);
		world.setBlock(i + 8, j + 5, k + 48, 5);
		world.setBlock(i + 8, j + 5, k + 49, 53);
		world.setBlockMetadata(i + 8, j + 5, k + 49, 7);
		world.setBlock(i + 8, j + 6, k + 26, 44);
		world.setBlockMetadata(i + 8, j + 6, k + 26, 10);
		world.setBlock(i + 8, j + 6, k + 27, 44);
		world.setBlockMetadata(i + 8, j + 6, k + 27, 10);
		world.setBlock(i + 8, j + 6, k + 28, 44);
		world.setBlockMetadata(i + 8, j + 6, k + 28, 10);
		world.setBlock(i + 8, j + 6, k + 29, 44);
		world.setBlockMetadata(i + 8, j + 6, k + 29, 2);
		world.setBlock(i + 8, j + 6, k + 30, 44);
		world.setBlockMetadata(i + 8, j + 6, k + 30, 2);
		world.setBlock(i + 8, j + 6, k + 31, 44);
		world.setBlockMetadata(i + 8, j + 6, k + 31, 2);
		world.setBlock(i + 8, j + 6, k + 32, 44);
		world.setBlockMetadata(i + 8, j + 6, k + 32, 2);
		world.setBlock(i + 8, j + 6, k + 33, 44);
		world.setBlockMetadata(i + 8, j + 6, k + 33, 2);
		world.setBlock(i + 8, j + 6, k + 34, 44);
		world.setBlockMetadata(i + 8, j + 6, k + 34, 2);
		world.setBlock(i + 8, j + 6, k + 35, 44);
		world.setBlockMetadata(i + 8, j + 6, k + 35, 2);
		world.setBlock(i + 8, j + 6, k + 36, 44);
		world.setBlockMetadata(i + 8, j + 6, k + 36, 2);
		world.setBlock(i + 8, j + 6, k + 37, 44);
		world.setBlockMetadata(i + 8, j + 6, k + 37, 2);
		world.setBlock(i + 8, j + 6, k + 38, 44);
		world.setBlockMetadata(i + 8, j + 6, k + 38, 2);
		world.setBlock(i + 8, j + 6, k + 39, 44);
		world.setBlockMetadata(i + 8, j + 6, k + 39, 2);
		world.setBlock(i + 8, j + 6, k + 40, 5);
		world.setBlock(i + 8, j + 6, k + 41, 17);
		world.setBlockMetadata(i + 8, j + 6, k + 41, 3);
		world.setBlock(i + 8, j + 6, k + 42, 17);
		world.setBlockMetadata(i + 8, j + 6, k + 42, 3);
		world.setBlock(i + 8, j + 6, k + 43, 17);
		world.setBlockMetadata(i + 8, j + 6, k + 43, 3);
		world.setBlock(i + 8, j + 6, k + 44, 17);
		world.setBlockMetadata(i + 8, j + 6, k + 44, 3);
		world.setBlock(i + 8, j + 6, k + 45, 17);
		world.setBlockMetadata(i + 8, j + 6, k + 45, 3);
		world.setBlock(i + 8, j + 6, k + 46, 17);
		world.setBlockMetadata(i + 8, j + 6, k + 46, 3);
		world.setBlock(i + 8, j + 6, k + 47, 17);
		world.setBlockMetadata(i + 8, j + 6, k + 47, 3);
		world.setBlock(i + 8, j + 6, k + 48, 17);
		world.setBlockMetadata(i + 8, j + 6, k + 48, 3);
		world.setBlock(i + 8, j + 6, k + 49, 17);
		world.setBlockMetadata(i + 8, j + 6, k + 49, 3);
		world.setBlock(i + 8, j + 6, k + 50, 17);
		world.setBlockMetadata(i + 8, j + 6, k + 50, 3);
		world.setBlock(i + 8, j + 7, k + 25, 85);
		world.setBlock(i + 8, j + 7, k + 26, 85);
		world.setBlock(i + 8, j + 7, k + 27, 85);
		world.setBlock(i + 8, j + 7, k + 28, 85);
		world.setBlock(i + 8, j + 7, k + 40, 85);
		world.setBlock(i + 8, j + 7, k + 41, 85);
		world.setBlock(i + 8, j + 7, k + 42, 17);
		world.setBlockMetadata(i + 8, j + 7, k + 42, 3);
		world.setBlock(i + 8, j + 7, k + 43, 17);
		world.setBlockMetadata(i + 8, j + 7, k + 43, 3);
		world.setBlock(i + 8, j + 7, k + 44, 17);
		world.setBlockMetadata(i + 8, j + 7, k + 44, 3);
		world.setBlock(i + 8, j + 7, k + 45, 17);
		world.setBlockMetadata(i + 8, j + 7, k + 45, 3);
		world.setBlock(i + 8, j + 7, k + 46, 43);
		world.setBlockMetadata(i + 8, j + 7, k + 46, 2);
		world.setBlock(i + 8, j + 7, k + 47, 5);
		world.setBlock(i + 8, j + 7, k + 48, 17);
		world.setBlockMetadata(i + 8, j + 7, k + 48, 3);
		world.setBlock(i + 8, j + 7, k + 49, 102);
		world.setBlock(i + 8, j + 7, k + 50, 5);
		world.setBlock(i + 8, j + 8, k + 41, 85);
		world.setBlock(i + 8, j + 8, k + 42, 85);
		world.setBlock(i + 8, j + 8, k + 43, 17);
		world.setBlockMetadata(i + 8, j + 8, k + 43, 3);
		world.setBlock(i + 8, j + 8, k + 44, 17);
		world.setBlockMetadata(i + 8, j + 8, k + 44, 3);
		world.setBlock(i + 8, j + 8, k + 45, 17);
		world.setBlockMetadata(i + 8, j + 8, k + 45, 3);
		world.setBlock(i + 8, j + 8, k + 46, 5);
		world.setBlock(i + 8, j + 8, k + 47, 5);
		world.setBlock(i + 8, j + 8, k + 48, 17);
		world.setBlockMetadata(i + 8, j + 8, k + 48, 3);
		world.setBlock(i + 8, j + 8, k + 49, 102);
		world.setBlock(i + 8, j + 8, k + 50, 5);
		world.setBlock(i + 8, j + 9, k + 42, 85);
		world.setBlock(i + 8, j + 9, k + 43, 85);
		world.setBlock(i + 8, j + 9, k + 44, 17);
		world.setBlockMetadata(i + 8, j + 9, k + 44, 3);
		world.setBlock(i + 8, j + 9, k + 45, 17);
		world.setBlockMetadata(i + 8, j + 9, k + 45, 3);
		world.setBlock(i + 8, j + 9, k + 46, 5);
		world.setBlock(i + 8, j + 9, k + 47, 5);
		world.setBlock(i + 8, j + 9, k + 48, 17);
		world.setBlockMetadata(i + 8, j + 9, k + 48, 3);
		world.setBlock(i + 8, j + 9, k + 49, 17);
		world.setBlockMetadata(i + 8, j + 9, k + 49, 3);
		world.setBlock(i + 8, j + 9, k + 50, 17);
		world.setBlockMetadata(i + 8, j + 9, k + 50, 3);
		world.setBlock(i + 8, j + 10, k + 34, 35);
		world.setBlockMetadata(i + 8, j + 10, k + 34, 13);
		world.setBlock(i + 8, j + 10, k + 43, 85);
		world.setBlock(i + 8, j + 10, k + 44, 85);
		world.setBlock(i + 8, j + 10, k + 51, 44);
		world.setBlockMetadata(i + 8, j + 10, k + 51, 2);
		world.setBlock(i + 8, j + 10, k + 52, 44);
		world.setBlockMetadata(i + 8, j + 10, k + 52, 10);
		world.setBlock(i + 8, j + 11, k + 34, 35);
		world.setBlockMetadata(i + 8, j + 11, k + 34, 13);
		world.setBlock(i + 8, j + 11, k + 44, 85);
		world.setBlock(i + 8, j + 11, k + 52, 85);
		world.setBlock(i + 8, j + 11, k + 53, 85);
		world.setBlock(i + 8, j + 12, k + 33, 35);
		world.setBlockMetadata(i + 8, j + 12, k + 33, 13);
		world.setBlock(i + 8, j + 13, k + 28, 35);
		world.setBlockMetadata(i + 8, j + 13, k + 28, 13);
		world.setBlock(i + 8, j + 13, k + 34, 35);
		world.setBlockMetadata(i + 8, j + 13, k + 34, 13);
		world.setBlock(i + 8, j + 14, k + 28, 35);
		world.setBlockMetadata(i + 8, j + 14, k + 28, 13);
		world.setBlock(i + 8, j + 14, k + 34, 35);
		world.setBlockMetadata(i + 8, j + 14, k + 34, 13);
		world.setBlock(i + 8, j + 15, k + 27, 35);
		world.setBlockMetadata(i + 8, j + 15, k + 27, 13);
		world.setBlock(i + 8, j + 15, k + 35, 17);
		world.setBlockMetadata(i + 8, j + 15, k + 35, 3);
		world.setBlock(i + 8, j + 16, k + 28, 35);
		world.setBlockMetadata(i + 8, j + 16, k + 28, 13);
		world.setBlock(i + 8, j + 17, k + 28, 35);
		world.setBlockMetadata(i + 8, j + 17, k + 28, 13);
		world.setBlock(i + 8, j + 17, k + 35, 35);
		world.setBlockMetadata(i + 8, j + 17, k + 35, 13);
		world.setBlock(i + 8, j + 18, k + 29, 17);
		world.setBlockMetadata(i + 8, j + 18, k + 29, 3);
		world.setBlock(i + 8, j + 18, k + 34, 35);
		world.setBlockMetadata(i + 8, j + 18, k + 34, 13);
		world.setBlock(i + 8, j + 19, k + 33, 35);
		world.setBlockMetadata(i + 8, j + 19, k + 33, 13);
		world.setBlock(i + 8, j + 20, k + 33, 35);
		world.setBlockMetadata(i + 8, j + 20, k + 33, 13);
		world.setBlock(i + 8, j + 21, k + 34, 35);
		world.setBlockMetadata(i + 8, j + 21, k + 34, 13);
		world.setBlock(i + 8, j + 22, k + 34, 35);
		world.setBlockMetadata(i + 8, j + 22, k + 34, 13);
		world.setBlock(i + 8, j + 23, k + 35, 17);
		world.setBlockMetadata(i + 8, j + 23, k + 35, 3);
		world.setBlock(i + 9, j + 6, k + 29, 44);
		world.setBlockMetadata(i + 9, j + 6, k + 29, 10);
		world.setBlock(i + 9, j + 6, k + 30, 44);
		world.setBlockMetadata(i + 9, j + 6, k + 30, 10);
