/*
*** MADE BY MITHION'S .SCHEMATIC TO JAVA CONVERTING TOOL v1.6 ***
*/

package techguy.mods.undead.common;
import java.util.Random;


import net.minecraft.block.Block;
import net.minecraft.world.World;
import net.minecraft.world.gen.feature.WorldGenerator;

public class ModUndeadWorldGenCastle extends WorldGenerator
{
	protected int[] GetValidSpawnBlocks() 
	{
		return new int[] {
			ModUndeadMainRegistry.dimGrass.blockID,
			ModUndeadMainRegistry.dimDirt.blockID
		};
	}

	public boolean LocationIsValidSpawn(World world, int i, int j, int k){
		int distanceToAir = 0;
		int checkID = world.getBlockId(i, j, k);

		while (checkID != 0){
			distanceToAir++;
			checkID = world.getBlockId(i, j + distanceToAir, k);
		}

		if (distanceToAir > 20){
			return false;
		}
		j += distanceToAir - 1;

		int blockID = world.getBlockId(i, j, k);
		int blockIDAbove = world.getBlockId(i, j+1, k);
		int blockIDBelow = world.getBlockId(i, j-1, k);
		for (int x : GetValidSpawnBlocks()){
			if (blockIDAbove != 0){
				return false;
			}
			if (blockID == x){
				return true;
			}else if (blockID == Block.snow.blockID && blockIDBelow == x){
				return true;
			}
		}
		return false;
	}

	public ModUndeadWorldGenCastle() { }

	public boolean generate(World world, Random rand, int i, int j, int k) 
	{
		//check that each corner is one of the valid spawn blocks
		if(!LocationIsValidSpawn(world, i, j, k) || !LocationIsValidSpawn(world, i + 49, j, k) || !LocationIsValidSpawn(world, i + 49, j, k + 50) || !LocationIsValidSpawn(world, i, j, k + 50))
		{
			return false;
		}

		world.setBlock(i + 0, j + 0, k + 0, ModUndeadMainRegistry.dimGrass.blockID);
		world.setBlock(i + 0, j + 0, k + 1, ModUndeadMainRegistry.dimGrass.blockID);
		world.setBlock(i + 0, j + 0, k + 2, ModUndeadMainRegistry.dimGrass.blockID);
		world.setBlock(i + 0, j + 0, k + 3, ModUndeadMainRegistry.dimGrass.blockID);
		world.setBlock(i + 0, j + 0, k + 4, Block.stoneBrick.blockID);
		world.setBlock(i + 0, j + 0, k + 5, Block.stoneBrick.blockID);
		world.setBlock(i + 0, j + 0, k + 13, Block.stoneBrick.blockID);
		world.setBlock(i + 0, j + 0, k + 14, Block.stoneBrick.blockID);
		world.setBlock(i + 0, j + 0, k + 15, ModUndeadMainRegistry.dimGrass.blockID);
		world.setBlock(i + 0, j + 0, k + 16, ModUndeadMainRegistry.dimGrass.blockID);
		world.setBlock(i + 0, j + 0, k + 17, ModUndeadMainRegistry.dimGrass.blockID);
		world.setBlock(i + 0, j + 0, k + 18, ModUndeadMainRegistry.dimGrass.blockID);
		world.setBlock(i + 0, j + 0, k + 19, ModUndeadMainRegistry.dimGrass.blockID);
		world.setBlock(i + 0, j + 0, k + 20, ModUndeadMainRegistry.dimGrass.blockID);
		world.setBlock(i + 0, j + 0, k + 21, ModUndeadMainRegistry.dimGrass.blockID);
		world.setBlock(i + 0, j + 0, k + 22, ModUndeadMainRegistry.dimGrass.blockID);
		world.setBlock(i + 0, j + 0, k + 23, ModUndeadMainRegistry.dimGrass.blockID);
		world.setBlock(i + 0, j + 0, k + 24, ModUndeadMainRegistry.dimGrass.blockID);
		world.setBlock(i + 0, j + 0, k + 25, ModUndeadMainRegistry.dimGrass.blockID);
		world.setBlock(i + 0, j + 0, k + 26, ModUndeadMainRegistry.dimGrass.blockID);
		world.setBlock(i + 0, j + 0, k + 27, ModUndeadMainRegistry.dimGrass.blockID);
		world.setBlock(i + 0, j + 0, k + 28, ModUndeadMainRegistry.dimGrass.blockID);
		world.setBlock(i + 0, j + 0, k + 29, ModUndeadMainRegistry.dimGrass.blockID);
		world.setBlock(i + 0, j + 0, k + 30, ModUndeadMainRegistry.dimGrass.blockID);
		world.setBlock(i + 0, j + 0, k + 31, ModUndeadMainRegistry.dimGrass.blockID);
		world.setBlock(i + 0, j + 0, k + 32, ModUndeadMainRegistry.dimGrass.blockID);
		world.setBlock(i + 0, j + 0, k + 33, ModUndeadMainRegistry.dimGrass.blockID);
		world.setBlock(i + 0, j + 0, k + 34, ModUndeadMainRegistry.dimGrass.blockID);
		world.setBlock(i + 0, j + 0, k + 35, ModUndeadMainRegistry.dimGrass.blockID);
		world.setBlock(i + 0, j + 0, k + 36, Block.stoneBrick.blockID);
		world.setBlock(i + 0, j + 0, k + 37, Block.stoneBrick.blockID);
		world.setBlock(i + 0, j + 0, k + 45, Block.stoneBrick.blockID);
		world.setBlock(i + 0, j + 0, k + 46, Block.stoneBrick.blockID);
		world.setBlock(i + 0, j + 0, k + 47, ModUndeadMainRegistry.dimGrass.blockID);
		world.setBlock(i + 0, j + 0, k + 48, ModUndeadMainRegistry.dimGrass.blockID);
		world.setBlock(i + 0, j + 0, k + 49, ModUndeadMainRegistry.dimGrass.blockID);
		world.setBlock(i + 0, j + 0, k + 50, ModUndeadMainRegistry.dimGrass.blockID);
		world.setBlock(i + 1, j + 0, k + 0, ModUndeadMainRegistry.dimGrass.blockID);
		world.setBlock(i + 1, j + 0, k + 1, ModUndeadMainRegistry.dimGrass.blockID);
		world.setBlock(i + 1, j + 0, k + 2, ModUndeadMainRegistry.dimGrass.blockID);
		world.setBlock(i + 1, j + 0, k + 3, Block.stoneBrick.blockID);
		world.setBlock(i + 1, j + 0, k + 4, Block.stoneBrick.blockID);
		world.setBlock(i + 1, j + 0, k + 14, Block.stoneBrick.blockID);
		world.setBlock(i + 1, j + 0, k + 15, Block.stoneBrick.blockID);
		world.setBlock(i + 1, j + 0, k + 16, ModUndeadMainRegistry.dimGrass.blockID);
		world.setBlock(i + 1, j + 0, k + 17, ModUndeadMainRegistry.dimGrass.blockID);
		world.setBlock(i + 1, j + 0, k + 18, ModUndeadMainRegistry.dimGrass.blockID);
		world.setBlock(i + 1, j + 0, k + 19, ModUndeadMainRegistry.dimGrass.blockID);
		world.setBlock(i + 1, j + 0, k + 20, ModUndeadMainRegistry.dimGrass.blockID);
		world.setBlock(i + 1, j + 0, k + 21, ModUndeadMainRegistry.dimGrass.blockID);
		world.setBlock(i + 1, j + 0, k + 22, ModUndeadMainRegistry.dimGrass.blockID);
		world.setBlock(i + 1, j + 0, k + 23, ModUndeadMainRegistry.dimGrass.blockID);
		world.setBlock(i + 1, j + 0, k + 24, ModUndeadMainRegistry.dimGrass.blockID);
		world.setBlock(i + 1, j + 0, k + 25, ModUndeadMainRegistry.dimGrass.blockID);
		world.setBlock(i + 1, j + 0, k + 26, ModUndeadMainRegistry.dimGrass.blockID);
		world.setBlock(i + 1, j + 0, k + 27, ModUndeadMainRegistry.dimGrass.blockID);
		world.setBlock(i + 1, j + 0, k + 28, ModUndeadMainRegistry.dimGrass.blockID);
		world.setBlock(i + 1, j + 0, k + 29, ModUndeadMainRegistry.dimGrass.blockID);
		world.setBlock(i + 1, j + 0, k + 30, ModUndeadMainRegistry.dimGrass.blockID);
		world.setBlock(i + 1, j + 0, k + 31, ModUndeadMainRegistry.dimGrass.blockID);
		world.setBlock(i + 1, j + 0, k + 32, ModUndeadMainRegistry.dimGrass.blockID);
		world.setBlock(i + 1, j + 0, k + 33, ModUndeadMainRegistry.dimGrass.blockID);
		world.setBlock(i + 1, j + 0, k + 34, ModUndeadMainRegistry.dimGrass.blockID);
		world.setBlock(i + 1, j + 0, k + 35, Block.stoneBrick.blockID);
		world.setBlock(i + 1, j + 0, k + 36, Block.stoneBrick.blockID);
		world.setBlock(i + 1, j + 0, k + 46, Block.stoneBrick.blockID);
		world.setBlock(i + 1, j + 0, k + 47, Block.stoneBrick.blockID);
		world.setBlock(i + 1, j + 0, k + 48, ModUndeadMainRegistry.dimGrass.blockID);
		world.setBlock(i + 1, j + 0, k + 49, ModUndeadMainRegistry.dimGrass.blockID);
		world.setBlock(i + 1, j + 0, k + 50, ModUndeadMainRegistry.dimGrass.blockID);
		world.setBlock(i + 2, j + 0, k + 0, ModUndeadMainRegistry.dimGrass.blockID);
		world.setBlock(i + 2, j + 0, k + 1, ModUndeadMainRegistry.dimGrass.blockID);
		world.setBlock(i + 2, j + 0, k + 2, Block.stoneBrick.blockID);
		world.setBlock(i + 2, j + 0, k + 3, Block.stoneBrick.blockID);
		world.setBlock(i + 2, j + 0, k + 7, Block.stoneBrick.blockID);
		world.setBlock(i + 2, j + 0, k + 8, Block.stoneBrick.blockID);
		world.setBlock(i + 2, j + 0, k + 9, Block.stoneBrick.blockID);
		world.setBlock(i + 2, j + 0, k + 10, Block.stoneBrick.blockID);
		world.setBlock(i + 2, j + 0, k + 11, Block.stoneBrick.blockID);
		world.setBlock(i + 2, j + 0, k + 15, Block.stoneBrick.blockID);
		world.setBlock(i + 2, j + 0, k + 16, Block.stoneBrick.blockID);
		world.setBlock(i + 2, j + 0, k + 17, ModUndeadMainRegistry.dimGrass.blockID);
		world.setBlock(i + 2, j + 0, k + 18, ModUndeadMainRegistry.dimGrass.blockID);
		world.setBlock(i + 2, j + 0, k + 19, ModUndeadMainRegistry.dimGrass.blockID);
		world.setBlock(i + 2, j + 0, k + 20, ModUndeadMainRegistry.dimGrass.blockID);
		world.setBlock(i + 2, j + 0, k + 21, ModUndeadMainRegistry.dimGrass.blockID);
		world.setBlock(i + 2, j + 0, k + 22, ModUndeadMainRegistry.dimGrass.blockID);
		world.setBlock(i + 2, j + 0, k + 23, ModUndeadMainRegistry.dimGrass.blockID);
		world.setBlock(i + 2, j + 0, k + 24, ModUndeadMainRegistry.dimGrass.blockID);
		world.setBlock(i + 2, j + 0, k + 25, ModUndeadMainRegistry.dimGrass.blockID);
		world.setBlock(i + 2, j + 0, k + 26, ModUndeadMainRegistry.dimGrass.blockID);
		world.setBlock(i + 2, j + 0, k + 27, ModUndeadMainRegistry.dimGrass.blockID);
		world.setBlock(i + 2, j + 0, k + 28, ModUndeadMainRegistry.dimGrass.blockID);
		world.setBlock(i + 2, j + 0, k + 29, ModUndeadMainRegistry.dimGrass.blockID);
		world.setBlock(i + 2, j + 0, k + 30, ModUndeadMainRegistry.dimGrass.blockID);
		world.setBlock(i + 2, j + 0, k + 31, ModUndeadMainRegistry.dimGrass.blockID);
		world.setBlock(i + 2, j + 0, k + 32, ModUndeadMainRegistry.dimGrass.blockID);
		world.setBlock(i + 2, j + 0, k + 33, ModUndeadMainRegistry.dimGrass.blockID);
		world.setBlock(i + 2, j + 0, k + 34, Block.stoneBrick.blockID);
		world.setBlock(i + 2, j + 0, k + 35, Block.stoneBrick.blockID);
		world.setBlock(i + 2, j + 0, k + 39, Block.stoneBrick.blockID);
		world.setBlock(i + 2, j + 0, k + 40, Block.stoneBrick.blockID);
		world.setBlock(i + 2, j + 0, k + 41, Block.stoneBrick.blockID);
		world.setBlock(i + 2, j + 0, k + 42, Block.stoneBrick.blockID);
		world.setBlock(i + 2, j + 0, k + 43, Block.stoneBrick.blockID);
		world.setBlock(i + 2, j + 0, k + 47, Block.stoneBrick.blockID);
		world.setBlock(i + 2, j + 0, k + 48, Block.stoneBrick.blockID);
		world.setBlock(i + 2, j + 0, k + 49, ModUndeadMainRegistry.dimGrass.blockID);
		world.setBlock(i + 2, j + 0, k + 50, ModUndeadMainRegistry.dimGrass.blockID);
		world.setBlockAndMetadata(i + 2, j + 1, k + 7, Block.stoneBrick.blockID, 1);
		world.setBlockAndMetadata(i + 2, j + 1, k + 8, Block.stoneBrick.blockID, 1);
		world.setBlock(i + 2, j + 1, k + 9, Block.stoneBrick.blockID);
		world.setBlock(i + 2, j + 1, k + 10, Block.stoneBrick.blockID);
		world.setBlock(i + 2, j + 1, k + 11, Block.stoneBrick.blockID);
		world.setBlock(i + 2, j + 1, k + 39, Block.stoneBrick.blockID);
		world.setBlock(i + 2, j + 1, k + 40, Block.stoneBrick.blockID);
		world.setBlock(i + 2, j + 1, k + 41, Block.stoneBrick.blockID);
		world.setBlock(i + 2, j + 1, k + 42, Block.stoneBrick.blockID);
		world.setBlock(i + 2, j + 1, k + 43, Block.stoneBrick.blockID);
		world.setBlockAndMetadata(i + 2, j + 2, k + 7, Block.stoneBrick.blockID, 1);
		world.setBlock(i + 2, j + 2, k + 8, Block.stoneBrick.blockID);
		world.setBlock(i + 2, j + 2, k + 9, Block.stoneBrick.blockID);
		world.setBlock(i + 2, j + 2, k + 10, Block.stoneBrick.blockID);
		world.setBlock(i + 2, j + 2, k + 11, Block.stoneBrick.blockID);
		world.setBlock(i + 2, j + 2, k + 39, Block.stoneBrick.blockID);
		world.setBlockAndMetadata(i + 2, j + 2, k + 40, Block.stoneBrick.blockID, 1);
		world.setBlockAndMetadata(i + 2, j + 2, k + 41, Block.stoneBrick.blockID, 1);
		world.setBlock(i + 2, j + 2, k + 42, Block.stoneBrick.blockID);
		world.setBlock(i + 2, j + 2, k + 43, Block.stoneBrick.blockID);
		world.setBlock(i + 2, j + 3, k + 7, Block.stoneBrick.blockID);
		world.setBlock(i + 2, j + 3, k + 8, Block.stoneBrick.blockID);
		world.setBlock(i + 2, j + 3, k + 9, Block.stoneBrick.blockID);
		world.setBlock(i + 2, j + 3, k + 10, Block.stoneBrick.blockID);
		world.setBlock(i + 2, j + 3, k + 11, Block.stoneBrick.blockID);
		world.setBlock(i + 2, j + 3, k + 39, Block.stoneBrick.blockID);
		world.setBlock(i + 2, j + 3, k + 40, Block.stoneBrick.blockID);
		world.setBlockAndMetadata(i + 2, j + 3, k + 41, Block.stoneBrick.blockID, 1);
		world.setBlockAndMetadata(i + 2, j + 3, k + 42, Block.stoneBrick.blockID, 1);
		world.setBlock(i + 2, j + 3, k + 43, Block.stoneBrick.blockID);
		world.setBlock(i + 2, j + 4, k + 7, Block.stoneBrick.blockID);
		world.setBlock(i + 2, j + 4, k + 8, Block.stoneBrick.blockID);
		world.setBlock(i + 2, j + 4, k + 9, Block.stoneBrick.blockID);
		world.setBlock(i + 2, j + 4, k + 10, Block.stoneBrick.blockID);
		world.setBlock(i + 2, j + 4, k + 11, Block.stoneBrick.blockID);
		world.setBlock(i + 2, j + 4, k + 39, Block.stoneBrick.blockID);
		world.setBlock(i + 2, j + 4, k + 40, Block.stoneBrick.blockID);
		world.setBlock(i + 2, j + 4, k + 41, Block.stoneBrick.blockID);
		world.setBlockAndMetadata(i + 2, j + 4, k + 42, Block.stoneBrick.blockID, 1);
		world.setBlock(i + 2, j + 4, k + 43, Block.stoneBrick.blockID);
		world.setBlock(i + 2, j + 5, k + 7, Block.stoneBrick.blockID);
		world.setBlock(i + 2, j + 5, k + 8, Block.stoneBrick.blockID);
		world.setBlock(i + 2, j + 5, k + 9, Block.stoneBrick.blockID);
		world.setBlock(i + 2, j + 5, k + 10, Block.stoneBrick.blockID);
		world.setBlockAndMetadata(i + 2, j + 5, k + 11, Block.stoneBrick.blockID, 2);
		world.setBlock(i + 2, j + 5, k + 39, Block.stoneBrick.blockID);
		world.setBlock(i + 2, j + 5, k + 40, Block.stoneBrick.blockID);
		world.setBlock(i + 2, j + 5, k + 41, Block.stoneBrick.blockID);
		world.setBlock(i + 2, j + 5, k + 42, Block.stoneBrick.blockID);
		world.setBlock(i + 2, j + 5, k + 43, Block.stoneBrick.blockID);
		world.setBlock(i + 2, j + 6, k + 7, Block.stoneBrick.blockID);
		world.setBlock(i + 2, j + 6, k + 8, Block.stoneBrick.blockID);
		world.setBlock(i + 2, j + 6, k + 9, Block.stoneBrick.blockID);
		world.setBlockAndMetadata(i + 2, j + 6, k + 10, Block.stoneBrick.blockID, 2);
		world.setBlockAndMetadata(i + 2, j + 6, k + 11, Block.stoneBrick.blockID, 2);
		world.setBlock(i + 2, j + 6, k + 39, Block.stoneBrick.blockID);
		world.setBlock(i + 2, j + 6, k + 40, Block.stoneBrick.blockID);
		world.setBlock(i + 2, j + 6, k + 41, Block.stoneBrick.blockID);
		world.setBlock(i + 2, j + 6, k + 42, Block.stoneBrick.blockID);
		world.setBlock(i + 2, j + 6, k + 43, Block.stoneBrick.blockID);
		world.setBlock(i + 2, j + 7, k + 7, Block.stoneBrick.blockID);
		world.setBlock(i + 2, j + 7, k + 8, Block.stoneBrick.blockID);
		world.setBlockAndMetadata(i + 2, j + 7, k + 9, Block.stoneBrick.blockID, 2);
		world.setBlockAndMetadata(i + 2, j + 7, k + 10, Block.stoneBrick.blockID, 2);
		world.setBlock(i + 2, j + 7, k + 11, Block.stoneBrick.blockID);
		world.setBlock(i + 2, j + 7, k + 39, Block.stoneBrick.blockID);
		world.setBlock(i + 2, j + 7, k + 40, Block.stoneBrick.blockID);
		world.setBlock(i + 2, j + 7, k + 41, Block.stoneBrick.blockID);
		world.setBlock(i + 2, j + 7, k + 42, Block.stoneBrick.blockID);
		world.setBlock(i + 2, j + 7, k + 43, Block.stoneBrick.blockID);
		world.setBlock(i + 2, j + 8, k + 7, Block.stoneBrick.blockID);
		world.setBlock(i + 2, j + 8, k + 8, Block.fence.blockID);
		world.setBlock(i + 2, j + 8, k + 9, Block.fence.blockID);
		world.setBlock(i + 2, j + 8, k + 10, Block.fence.blockID);
		world.setBlock(i + 2, j + 8, k + 11, Block.stoneBrick.blockID);
		world.setBlock(i + 2, j + 8, k + 39, Block.stoneBrick.blockID);
		world.setBlock(i + 2, j + 8, k + 40, Block.fence.blockID);
		world.setBlock(i + 2, j + 8, k + 41, Block.fence.blockID);
		world.setBlock(i + 2, j + 8, k + 42, Block.fence.blockID);
		world.setBlock(i + 2, j + 8, k + 43, Block.stoneBrick.blockID);
		world.setBlock(i + 2, j + 9, k + 7, Block.stoneBrick.blockID);
		world.setBlock(i + 2, j + 9, k + 11, Block.stoneBrick.blockID);
		world.setBlock(i + 2, j + 9, k + 39, Block.stoneBrick.blockID);
		world.setBlock(i + 2, j + 9, k + 43, Block.stoneBrick.blockID);
		world.setBlock(i + 2, j + 10, k + 7, Block.stoneBrick.blockID);
		world.setBlockAndMetadata(i + 2, j + 10, k + 11, Block.stoneBrick.blockID, 2);
		world.setBlock(i + 2, j + 10, k + 39, Block.stoneBrick.blockID);
		world.setBlock(i + 2, j + 10, k + 43, Block.stoneBrick.blockID);
		world.setBlock(i + 2, j + 11, k + 7, Block.stoneBrick.blockID);
		world.setBlock(i + 2, j + 11, k + 8, Block.fence.blockID);
		world.setBlock(i + 2, j + 11, k + 9, Block.fence.blockID);
		world.setBlock(i + 2, j + 11, k + 10, Block.fence.blockID);
		world.setBlockAndMetadata(i + 2, j + 11, k + 11, Block.stoneBrick.blockID, 2);
		world.setBlockAndMetadata(i + 2, j + 11, k + 39, Block.stoneBrick.blockID, 2);
		world.setBlock(i + 2, j + 11, k + 40, Block.fence.blockID);
		world.setBlock(i + 2, j + 11, k + 41, Block.fence.blockID);
		world.setBlock(i + 2, j + 11, k + 42, Block.fence.blockID);
		world.setBlock(i + 2, j + 11, k + 43, Block.stoneBrick.blockID);
		world.setBlock(i + 2, j + 12, k + 7, Block.stoneBrick.blockID);
		world.setBlock(i + 2, j + 12, k + 8, Block.stoneBrick.blockID);
		world.setBlock(i + 2, j + 12, k + 9, Block.stoneBrick.blockID);
		world.setBlock(i + 2, j + 12, k + 10, Block.stoneBrick.blockID);
		world.setBlock(i + 2, j + 12, k + 11, Block.stoneBrick.blockID);
		world.setBlockAndMetadata(i + 2, j + 12, k + 39, Block.stoneBrick.blockID, 2);
		world.setBlockAndMetadata(i + 2, j + 12, k + 40, Block.stoneBrick.blockID, 2);
		world.setBlockAndMetadata(i + 2, j + 12, k + 41, Block.stoneBrick.blockID, 2);
		world.setBlock(i + 2, j + 12, k + 42, Block.stoneBrick.blockID);
		world.setBlock(i + 2, j + 12, k + 43, Block.stoneBrick.blockID);
		world.setBlock(i + 2, j + 13, k + 7, Block.stoneBrick.blockID);
		world.setBlock(i + 2, j + 13, k + 8, Block.stoneBrick.blockID);
		world.setBlock(i + 2, j + 13, k + 9, Block.stoneBrick.blockID);
		world.setBlock(i + 2, j + 13, k + 10, Block.stoneBrick.blockID);
		world.setBlock(i + 2, j + 13, k + 11, Block.stoneBrick.blockID);
		world.setBlock(i + 2, j + 13, k + 39, Block.stoneBrick.blockID);
		world.setBlock(i + 2, j + 13, k + 40, Block.stoneBrick.blockID);
		world.setBlockAndMetadata(i + 2, j + 13, k + 41, Block.stoneBrick.blockID, 2);
		world.setBlock(i + 2, j + 13, k + 42, Block.stoneBrick.blockID);
		world.setBlock(i + 2, j + 13, k + 43, Block.stoneBrick.blockID);
		world.setBlockAndMetadata(i + 2, j + 14, k + 7, Block.stoneSingleSlab.blockID, 5);
		world.setBlockAndMetadata(i + 2, j + 14, k + 9, Block.stoneSingleSlab.blockID, 5);
		world.setBlockAndMetadata(i + 2, j + 14, k + 11, Block.stoneSingleSlab.blockID, 5);
		world.setBlockAndMetadata(i + 2, j + 14, k + 39, Block.stoneSingleSlab.blockID, 5);
		world.setBlockAndMetadata(i + 2, j + 14, k + 41, Block.stoneSingleSlab.blockID, 5);
		world.setBlockAndMetadata(i + 2, j + 14, k + 43, Block.stoneSingleSlab.blockID, 5);
		world.setBlock(i + 3, j + 0, k + 0, ModUndeadMainRegistry.dimGrass.blockID);
		world.setBlock(i + 3, j + 0, k + 1, Block.stoneBrick.blockID);
		world.setBlock(i + 3, j + 0, k + 2, Block.stoneBrick.blockID);
		world.setBlock(i + 3, j + 0, k + 6, Block.stoneBrick.blockID);
		world.setBlock(i + 3, j + 0, k + 7, Block.stoneDoubleSlab.blockID);
		world.setBlock(i + 3, j + 0, k + 8, Block.stoneDoubleSlab.blockID);
		world.setBlock(i + 3, j + 0, k + 9, Block.stoneDoubleSlab.blockID);
		world.setBlock(i + 3, j + 0, k + 10, Block.stoneDoubleSlab.blockID);
		world.setBlock(i + 3, j + 0, k + 11, Block.stoneDoubleSlab.blockID);
		world.setBlock(i + 3, j + 0, k + 12, Block.stoneBrick.blockID);
		world.setBlock(i + 3, j + 0, k + 16, Block.stoneBrick.blockID);
		world.setBlock(i + 3, j + 0, k + 17, Block.stoneBrick.blockID);
		world.setBlock(i + 3, j + 0, k + 18, Block.stoneBrick.blockID);
		world.setBlock(i + 3, j + 0, k + 19, Block.stoneBrick.blockID);
		world.setBlock(i + 3, j + 0, k + 20, Block.stoneBrick.blockID);
		world.setBlock(i + 3, j + 0, k + 21, Block.stoneBrick.blockID);
		world.setBlock(i + 3, j + 0, k + 22, Block.stoneBrick.blockID);
		world.setBlock(i + 3, j + 0, k + 23, Block.stoneBrick.blockID);
		world.setBlock(i + 3, j + 0, k + 24, Block.stoneBrick.blockID);
		world.setBlock(i + 3, j + 0, k + 25, Block.stoneBrick.blockID);
		world.setBlock(i + 3, j + 0, k + 26, Block.stoneBrick.blockID);
		world.setBlock(i + 3, j + 0, k + 27, Block.stoneBrick.blockID);
		world.setBlock(i + 3, j + 0, k + 28, Block.stoneBrick.blockID);
		world.setBlock(i + 3, j + 0, k + 29, Block.stoneBrick.blockID);
		world.setBlock(i + 3, j + 0, k + 30, Block.stoneBrick.blockID);
		world.setBlock(i + 3, j + 0, k + 31, Block.stoneBrick.blockID);
		world.setBlock(i + 3, j + 0, k + 32, Block.stoneBrick.blockID);
		world.setBlock(i + 3, j + 0, k + 33, Block.stoneBrick.blockID);
		world.setBlock(i + 3, j + 0, k + 34, Block.stoneBrick.blockID);
		world.setBlock(i + 3, j + 0, k + 38, Block.stoneBrick.blockID);
		world.setBlock(i + 3, j + 0, k + 39, Block.stoneDoubleSlab.blockID);
		world.setBlock(i + 3, j + 0, k + 40, Block.stoneDoubleSlab.blockID);
		world.setBlock(i + 3, j + 0, k + 41, Block.stoneDoubleSlab.blockID);
		world.setBlock(i + 3, j + 0, k + 42, Block.stoneDoubleSlab.blockID);
		world.setBlock(i + 3, j + 0, k + 43, Block.stoneDoubleSlab.blockID);
		world.setBlock(i + 3, j + 0, k + 44, Block.stoneBrick.blockID);
		world.setBlock(i + 3, j + 0, k + 48, Block.stoneBrick.blockID);
		world.setBlock(i + 3, j + 0, k + 49, Block.stoneBrick.blockID);
		world.setBlock(i + 3, j + 0, k + 50, ModUndeadMainRegistry.dimGrass.blockID);
		world.setBlockAndMetadata(i + 3, j + 1, k + 6, Block.stoneBrick.blockID, 1);
		world.setBlock(i + 3, j + 1, k + 12, Block.stoneBrick.blockID);
		world.setBlockAndMetadata(i + 3, j + 1, k + 38, Block.stoneBrick.blockID, 1);
		world.setBlock(i + 3, j + 1, k + 44, Block.stoneBrick.blockID);
		world.setBlockAndMetadata(i + 3, j + 2, k + 6, Block.stoneBrick.blockID, 1);
		world.setBlock(i + 3, j + 2, k + 12, Block.stoneBrick.blockID);
		world.setBlockAndMetadata(i + 3, j + 2, k + 38, Block.stoneBrick.blockID, 1);
		world.setBlock(i + 3, j + 2, k + 44, Block.stoneBrick.blockID);
		world.setBlock(i + 3, j + 3, k + 6, Block.stoneBrick.blockID);
		world.setBlock(i + 3, j + 3, k + 12, Block.stoneBrick.blockID);
		world.setBlockAndMetadata(i + 3, j + 3, k + 38, Block.stoneBrick.blockID, 1);
		world.setBlock(i + 3, j + 3, k + 44, Block.stoneBrick.blockID);
		world.setBlock(i + 3, j + 4, k + 6, Block.stoneBrick.blockID);
		world.setBlock(i + 3, j + 4, k + 12, Block.stoneBrick.blockID);
		world.setBlock(i + 3, j + 4, k + 38, Block.stoneBrick.blockID);
		world.setBlockAndMetadata(i + 3, j + 4, k + 44, Block.stoneBrick.blockID, 1);
		world.setBlock(i + 3, j + 5, k + 6, Block.stoneBrick.blockID);
		world.setBlock(i + 3, j + 5, k + 12, Block.stoneBrick.blockID);
		world.setBlock(i + 3, j + 5, k + 38, Block.stoneBrick.blockID);
		world.setBlock(i + 3, j + 5, k + 44, Block.stoneBrick.blockID);
		world.setBlock(i + 3, j + 6, k + 6, Block.stoneBrick.blockID);
		world.setBlock(i + 3, j + 6, k + 12, Block.stoneBrick.blockID);
		world.setBlock(i + 3, j + 6, k + 38, Block.stoneBrick.blockID);
		world.setBlock(i + 3, j + 6, k + 44, Block.stoneBrick.blockID);
		world.setBlockAndMetadata(i + 3, j + 7, k + 6, Block.stoneBrick.blockID, 2);
		world.setBlock(i + 3, j + 7, k + 7, Block.stoneBrick.blockID);
		world.setBlockAndMetadata(i + 3, j + 7, k + 8, Block.stoneSingleSlab.blockID, 13);
		world.setBlockAndMetadata(i + 3, j + 7, k + 9, Block.stoneSingleSlab.blockID, 13);
		world.setBlockAndMetadata(i + 3, j + 7, k + 10, Block.stoneSingleSlab.blockID, 13);
		world.setBlock(i + 3, j + 7, k + 11, Block.stoneBrick.blockID);
		world.setBlock(i + 3, j + 7, k + 12, Block.stoneBrick.blockID);
		world.setBlock(i + 3, j + 7, k + 38, Block.stoneBrick.blockID);
		world.setBlock(i + 3, j + 7, k + 39, Block.stoneBrick.blockID);
		world.setBlockAndMetadata(i + 3, j + 7, k + 40, Block.stoneSingleSlab.blockID, 13);
		world.setBlockAndMetadata(i + 3, j + 7, k + 41, Block.stoneSingleSlab.blockID, 13);
		world.setBlockAndMetadata(i + 3, j + 7, k + 42, Block.stoneSingleSlab.blockID, 13);
		world.setBlock(i + 3, j + 7, k + 43, Block.stoneBrick.blockID);
		world.setBlock(i + 3, j + 7, k + 44, Block.stoneBrick.blockID);
		world.setBlockAndMetadata(i + 3, j + 8, k + 6, Block.stoneBrick.blockID, 2);
		world.setBlock(i + 3, j + 8, k + 7, Block.wood.blockID);
		world.setBlock(i + 3, j + 8, k + 8, Block.wood.blockID);
		world.setBlock(i + 3, j + 8, k + 9, Block.wood.blockID);
		world.setBlock(i + 3, j + 8, k + 10, Block.wood.blockID);
		world.setBlock(i + 3, j + 8, k + 11, Block.wood.blockID);
		world.setBlock(i + 3, j + 8, k + 12, Block.stoneBrick.blockID);
		world.setBlock(i + 3, j + 8, k + 38, Block.stoneBrick.blockID);
		world.setBlock(i + 3, j + 8, k + 39, Block.wood.blockID);
		world.setBlock(i + 3, j + 8, k + 40, Block.wood.blockID);
		world.setBlock(i + 3, j + 8, k + 41, Block.wood.blockID);
		world.setBlock(i + 3, j + 8, k + 42, Block.wood.blockID);
		world.setBlock(i + 3, j + 8, k + 43, Block.wood.blockID);
		world.setBlock(i + 3, j + 8, k + 44, Block.stoneBrick.blockID);
		world.setBlock(i + 3, j + 9, k + 6, Block.stoneBrick.blockID);
		world.setBlock(i + 3, j + 9, k + 7, Block.fence.blockID);
		world.setBlock(i + 3, j + 9, k + 11, Block.fence.blockID);
		world.setBlock(i + 3, j + 9, k + 12, Block.stoneBrick.blockID);
		world.setBlock(i + 3, j + 9, k + 38, Block.stoneBrick.blockID);
		world.setBlock(i + 3, j + 9, k + 39, Block.fence.blockID);
		world.setBlock(i + 3, j + 9, k + 43, Block.fence.blockID);
		world.setBlock(i + 3, j + 9, k + 44, Block.stoneBrick.blockID);
		world.setBlock(i + 3, j + 10, k + 6, Block.stoneBrick.blockID);
		world.setBlock(i + 3, j + 10, k + 12, Block.stoneBrick.blockID);
		world.setBlockAndMetadata(i + 3, j + 10, k + 38, Block.stoneBrick.blockID, 2);
		world.setBlock(i + 3, j + 10, k + 44, Block.stoneBrick.blockID);
		world.setBlock(i + 3, j + 11, k + 6, Block.stoneBrick.blockID);
		world.setBlockAndMetadata(i + 3, j + 11, k + 12, Block.stoneBrick.blockID, 2);
		world.setBlockAndMetadata(i + 3, j + 11, k + 38, Block.stoneBrick.blockID, 2);
		world.setBlock(i + 3, j + 11, k + 44, Block.stoneBrick.blockID);
		world.setBlock(i + 3, j + 12, k + 6, Block.stoneBrick.blockID);
		world.setBlockAndMetadata(i + 3, j + 12, k + 12, Block.stoneBrick.blockID, 2);
		world.setBlock(i + 3, j + 12, k + 38, Block.stoneBrick.blockID);
		world.setBlock(i + 3, j + 12, k + 44, Block.stoneBrick.blockID);
		world.setBlock(i + 3, j + 13, k + 6, Block.stoneBrick.blockID);
		world.setBlockAndMetadata(i + 3, j + 13, k + 7, Block.stoneSingleSlab.blockID, 2);
		world.setBlockAndMetadata(i + 3, j + 13, k + 8, Block.stoneSingleSlab.blockID, 2);
		world.setBlockAndMetadata(i + 3, j + 13, k + 9, Block.stoneSingleSlab.blockID, 2);
		world.setBlockAndMetadata(i + 3, j + 13, k + 10, Block.stoneSingleSlab.blockID, 2);
		world.setBlockAndMetadata(i + 3, j + 13, k + 11, Block.stoneSingleSlab.blockID, 2);
		world.setBlock(i + 3, j + 13, k + 12, Block.stoneBrick.blockID);
		world.setBlock(i + 3, j + 13, k + 38, Block.stoneBrick.blockID);
		world.setBlockAndMetadata(i + 3, j + 13, k + 39, Block.stoneSingleSlab.blockID, 2);
		world.setBlockAndMetadata(i + 3, j + 13, k + 40, Block.stoneSingleSlab.blockID, 2);
		world.setBlockAndMetadata(i + 3, j + 13, k + 41, Block.stoneSingleSlab.blockID, 2);
		world.setBlockAndMetadata(i + 3, j + 13, k + 42, Block.stoneSingleSlab.blockID, 2);
		world.setBlockAndMetadata(i + 3, j + 13, k + 43, Block.stoneSingleSlab.blockID, 2);
		world.setBlock(i + 3, j + 13, k + 44, Block.stoneBrick.blockID);
		world.setBlockAndMetadata(i + 3, j + 20, k + 11, Block.cloth.blockID, 15);
		world.setBlockAndMetadata(i + 3, j + 20, k + 43, Block.cloth.blockID, 15);
		world.setBlock(i + 4, j + 0, k + 0, Block.stoneBrick.blockID);
		world.setBlock(i + 4, j + 0, k + 1, Block.stoneBrick.blockID);
		world.setBlock(i + 4, j + 0, k + 5, Block.stoneBrick.blockID);
		world.setBlock(i + 4, j + 0, k + 6, Block.stoneDoubleSlab.blockID);
		world.setBlock(i + 4, j + 0, k + 7, Block.stoneDoubleSlab.blockID);
		world.setBlock(i + 4, j + 0, k + 8, Block.stoneDoubleSlab.blockID);
		world.setBlock(i + 4, j + 0, k + 9, Block.stoneDoubleSlab.blockID);
		world.setBlock(i + 4, j + 0, k + 10, Block.stoneDoubleSlab.blockID);
		world.setBlock(i + 4, j + 0, k + 11, Block.stoneDoubleSlab.blockID);
		world.setBlock(i + 4, j + 0, k + 12, Block.stoneDoubleSlab.blockID);
		world.setBlock(i + 4, j + 0, k + 13, Block.stoneBrick.blockID);
		world.setBlock(i + 4, j + 0, k + 37, Block.stoneBrick.blockID);
		world.setBlock(i + 4, j + 0, k + 38, Block.stoneDoubleSlab.blockID);
		world.setBlock(i + 4, j + 0, k + 39, Block.stoneDoubleSlab.blockID);
		world.setBlock(i + 4, j + 0, k + 40, Block.stoneDoubleSlab.blockID);
		world.setBlock(i + 4, j + 0, k + 41, Block.stoneDoubleSlab.blockID);
		world.setBlock(i + 4, j + 0, k + 42, Block.stoneDoubleSlab.blockID);
		world.setBlock(i + 4, j + 0, k + 43, Block.stoneDoubleSlab.blockID);
		world.setBlock(i + 4, j + 0, k + 44, Block.stoneDoubleSlab.blockID);
		world.setBlock(i + 4, j + 0, k + 45, Block.stoneBrick.blockID);
		world.setBlock(i + 4, j + 0, k + 49, Block.stoneBrick.blockID);
		world.setBlock(i + 4, j + 0, k + 50, Block.stoneBrick.blockID);
		world.setBlockAndMetadata(i + 4, j + 1, k + 5, Block.stoneBrick.blockID, 1);
		world.setBlockAndMetadata(i + 4, j + 1, k + 13, Block.stoneBrick.blockID, 1);
		world.setBlock(i + 4, j + 1, k + 37, Block.stoneBrick.blockID);
		world.setBlock(i + 4, j + 1, k + 45, Block.stoneBrick.blockID);
		world.setBlock(i + 4, j + 2, k + 5, Block.stoneBrick.blockID);
		world.setBlock(i + 4, j + 2, k + 13, Block.stoneBrick.blockID);
		world.setBlock(i + 4, j + 2, k + 37, Block.stoneBrick.blockID);
		world.setBlockAndMetadata(i + 4, j + 2, k + 45, Block.stoneBrick.blockID, 1);
		world.setBlock(i + 4, j + 3, k + 5, Block.stoneBrick.blockID);
		world.setBlock(i + 4, j + 3, k + 13, Block.stoneBrick.blockID);
		world.setBlock(i + 4, j + 3, k + 37, Block.stoneBrick.blockID);
		world.setBlockAndMetadata(i + 4, j + 3, k + 45, Block.stoneBrick.blockID, 1);
		world.setBlock(i + 4, j + 4, k + 5, Block.stoneBrick.blockID);
		world.setBlock(i + 4, j + 4, k + 13, Block.stoneBrick.blockID);
		world.setBlock(i + 4, j + 4, k + 37, Block.stoneBrick.blockID);
		world.setBlock(i + 4, j + 4, k + 45, Block.stoneBrick.blockID);
		world.setBlock(i + 4, j + 5, k + 5, Block.stoneBrick.blockID);
		world.setBlock(i + 4, j + 5, k + 13, Block.stoneBrick.blockID);
		world.setBlock(i + 4, j + 5, k + 37, Block.stoneBrick.blockID);
		world.setBlock(i + 4, j + 5, k + 45, Block.stoneBrick.blockID);
		world.setBlockAndMetadata(i + 4, j + 6, k + 5, Block.stoneBrick.blockID, 2);
		world.setBlock(i + 4, j + 6, k + 8, Block.netherFence.blockID);
		world.setBlock(i + 4, j + 6, k + 10, Block.netherFence.blockID);
		world.setBlock(i + 4, j + 6, k + 13, Block.stoneBrick.blockID);
		world.setBlock(i + 4, j + 6, k + 37, Block.stoneBrick.blockID);
		world.setBlock(i + 4, j + 6, k + 40, Block.netherFence.blockID);
		world.setBlock(i + 4, j + 6, k + 42, Block.netherFence.blockID);
		world.setBlock(i + 4, j + 6, k + 45, Block.stoneBrick.blockID);
		world.setBlockAndMetadata(i + 4, j + 7, k + 5, Block.stoneBrick.blockID, 2);
		world.setBlock(i + 4, j + 7, k + 6, Block.stoneBrick.blockID);
		world.setBlockAndMetadata(i + 4, j + 7, k + 7, Block.stoneSingleSlab.blockID, 13);
		world.setBlock(i + 4, j + 7, k + 8, Block.fence.blockID);
		world.setBlock(i + 4, j + 7, k + 10, Block.fence.blockID);
		world.setBlockAndMetadata(i + 4, j + 7, k + 11, Block.stoneSingleSlab.blockID, 13);
		world.setBlock(i + 4, j + 7, k + 12, Block.stoneBrick.blockID);
		world.setBlock(i + 4, j + 7, k + 13, Block.stoneBrick.blockID);
		world.setBlock(i + 4, j + 7, k + 37, Block.stoneBrick.blockID);
		world.setBlock(i + 4, j + 7, k + 38, Block.stoneBrick.blockID);
		world.setBlockAndMetadata(i + 4, j + 7, k + 39, Block.stoneSingleSlab.blockID, 13);
		world.setBlock(i + 4, j + 7, k + 40, Block.fence.blockID);
		world.setBlock(i + 4, j + 7, k + 42, Block.fence.blockID);
		world.setBlockAndMetadata(i + 4, j + 7, k + 43, Block.stoneSingleSlab.blockID, 13);
		world.setBlock(i + 4, j + 7, k + 44, Block.stoneBrick.blockID);
		world.setBlock(i + 4, j + 7, k + 45, Block.stoneBrick.blockID);
		world.setBlock(i + 4, j + 8, k + 5, Block.stoneBrick.blockID);
		world.setBlock(i + 4, j + 8, k + 6, Block.wood.blockID);
		world.setBlock(i + 4, j + 8, k + 7, Block.wood.blockID);
		world.setBlockAndMetadata(i + 4, j + 8, k + 8, Block.stoneBrick.blockID, 3);
		world.setBlockAndMetadata(i + 4, j + 8, k + 9, Block.stoneBrick.blockID, 3);
		world.setBlockAndMetadata(i + 4, j + 8, k + 10, Block.stoneBrick.blockID, 3);
		world.setBlock(i + 4, j + 8, k + 11, Block.wood.blockID);
		world.setBlock(i + 4, j + 8, k + 12, Block.wood.blockID);
		world.setBlock(i + 4, j + 8, k + 13, Block.stoneBrick.blockID);
		world.setBlock(i + 4, j + 8, k + 37, Block.stoneBrick.blockID);
		world.setBlock(i + 4, j + 8, k + 38, Block.wood.blockID);
		world.setBlock(i + 4, j + 8, k + 39, Block.wood.blockID);
		world.setBlockAndMetadata(i + 4, j + 8, k + 40, Block.stoneBrick.blockID, 3);
		world.setBlockAndMetadata(i + 4, j + 8, k + 41, Block.stoneBrick.blockID, 3);
		world.setBlockAndMetadata(i + 4, j + 8, k + 42, Block.stoneBrick.blockID, 3);
		world.setBlock(i + 4, j + 8, k + 43, Block.wood.blockID);
		world.setBlock(i + 4, j + 8, k + 44, Block.wood.blockID);
		world.setBlock(i + 4, j + 8, k + 45, Block.stoneBrick.blockID);
		world.setBlock(i + 4, j + 9, k + 5, Block.stoneBrick.blockID);
		world.setBlock(i + 4, j + 9, k + 13, Block.stoneBrick.blockID);
		world.setBlockAndMetadata(i + 4, j + 9, k + 37, Block.stoneBrick.blockID, 2);
		world.setBlock(i + 4, j + 9, k + 45, Block.stoneBrick.blockID);
		world.setBlock(i + 4, j + 10, k + 5, Block.stoneBrick.blockID);
		world.setBlock(i + 4, j + 10, k + 13, Block.stoneBrick.blockID);
		world.setBlockAndMetadata(i + 4, j + 10, k + 37, Block.stoneBrick.blockID, 2);
		world.setBlock(i + 4, j + 10, k + 45, Block.stoneBrick.blockID);
		world.setBlock(i + 4, j + 11, k + 5, Block.stoneBrick.blockID);
		world.setBlock(i + 4, j + 11, k + 13, Block.stoneBrick.blockID);
		world.setBlock(i + 4, j + 11, k + 37, Block.stoneBrick.blockID);
		world.setBlockAndMetadata(i + 4, j + 11, k + 45, Block.stoneBrick.blockID, 2);
		world.setBlock(i + 4, j + 12, k + 5, Block.stoneBrick.blockID);
		world.setBlock(i + 4, j + 12, k + 13, Block.stoneBrick.blockID);
		world.setBlock(i + 4, j + 12, k + 37, Block.stoneBrick.blockID);
		world.setBlockAndMetadata(i + 4, j + 12, k + 45, Block.stoneBrick.blockID, 2);
		world.setBlock(i + 4, j + 13, k + 5, Block.stoneBrick.blockID);
		world.setBlockAndMetadata(i + 4, j + 13, k + 6, Block.stoneSingleSlab.blockID, 2);
		world.setBlockAndMetadata(i + 4, j + 13, k + 7, Block.stoneSingleSlab.blockID, 2);
		world.setBlockAndMetadata(i + 4, j + 13, k + 8, Block.stoneSingleSlab.blockID, 2);
		world.setBlockAndMetadata(i + 4, j + 13, k + 9, Block.stoneSingleSlab.blockID, 2);
		world.setBlockAndMetadata(i + 4, j + 13, k + 10, Block.stoneSingleSlab.blockID, 2);
		world.setBlockAndMetadata(i + 4, j + 13, k + 11, Block.stoneSingleSlab.blockID, 2);
		world.setBlockAndMetadata(i + 4, j + 13, k + 12, Block.stoneSingleSlab.blockID, 2);
		world.setBlock(i + 4, j + 13, k + 13, Block.stoneBrick.blockID);
		world.setBlock(i + 4, j + 13, k + 37, Block.stoneBrick.blockID);
		world.setBlockAndMetadata(i + 4, j + 13, k + 38, Block.stoneSingleSlab.blockID, 2);
		world.setBlockAndMetadata(i + 4, j + 13, k + 39, Block.stoneSingleSlab.blockID, 2);
		world.setBlockAndMetadata(i + 4, j + 13, k + 40, Block.stoneSingleSlab.blockID, 2);
		world.setBlockAndMetadata(i + 4, j + 13, k + 41, Block.stoneSingleSlab.blockID, 2);
		world.setBlockAndMetadata(i + 4, j + 13, k + 42, Block.stoneSingleSlab.blockID, 2);
		world.setBlockAndMetadata(i + 4, j + 13, k + 43, Block.stoneSingleSlab.blockID, 2);
		world.setBlockAndMetadata(i + 4, j + 13, k + 44, Block.stoneSingleSlab.blockID, 2);
		world.setBlock(i + 4, j + 13, k + 45, Block.stoneBrick.blockID);
		world.setBlockAndMetadata(i + 4, j + 14, k + 5, Block.stoneSingleSlab.blockID, 5);
		world.setBlockAndMetadata(i + 4, j + 14, k + 13, Block.stoneSingleSlab.blockID, 5);
		world.setBlockAndMetadata(i + 4, j + 14, k + 37, Block.stoneSingleSlab.blockID, 5);
		world.setBlockAndMetadata(i + 4, j + 14, k + 45, Block.stoneSingleSlab.blockID, 5);
		world.setBlockAndMetadata(i + 4, j + 19, k + 11, Block.cloth.blockID, 15);
		world.setBlockAndMetadata(i + 4, j + 19, k + 43, Block.cloth.blockID, 15);
		world.setBlockAndMetadata(i + 4, j + 20, k + 11, Block.cloth.blockID, 11);
		world.setBlockAndMetadata(i + 4, j + 20, k + 43, Block.cloth.blockID, 11);
		world.setBlockAndMetadata(i + 4, j + 21, k + 11, Block.cloth.blockID, 15);
		world.setBlockAndMetadata(i + 4, j + 21, k + 43, Block.cloth.blockID, 15);
		world.setBlock(i + 5, j + 0, k + 0, Block.stoneBrick.blockID);
		world.setBlock(i + 5, j + 0, k + 4, Block.stoneBrick.blockID);
		world.setBlock(i + 5, j + 0, k + 5, Block.stoneDoubleSlab.blockID);
		world.setBlock(i + 5, j + 0, k + 6, Block.stoneDoubleSlab.blockID);
		world.setBlock(i + 5, j + 0, k + 7, Block.stoneDoubleSlab.blockID);
		world.setBlock(i + 5, j + 0, k + 8, Block.glowStone.blockID);
		world.setBlock(i + 5, j + 0, k + 9, Block.glowStone.blockID);
		world.setBlock(i + 5, j + 0, k + 10, Block.glowStone.blockID);
		world.setBlock(i + 5, j + 0, k + 11, Block.stoneDoubleSlab.blockID);
		world.setBlock(i + 5, j + 0, k + 12, Block.stoneDoubleSlab.blockID);
		world.setBlock(i + 5, j + 0, k + 13, Block.stoneDoubleSlab.blockID);
		world.setBlockAndMetadata(i + 5, j + 0, k + 14, Block.stoneBrick.blockID, 1);
		world.setBlock(i + 5, j + 0, k + 36, Block.stoneBrick.blockID);
		world.setBlock(i + 5, j + 0, k + 37, Block.stoneDoubleSlab.blockID);
		world.setBlock(i + 5, j + 0, k + 38, Block.stoneDoubleSlab.blockID);
		world.setBlock(i + 5, j + 0, k + 39, Block.stoneDoubleSlab.blockID);
		world.setBlock(i + 5, j + 0, k + 40, Block.glowStone.blockID);
		world.setBlock(i + 5, j + 0, k + 41, Block.glowStone.blockID);
		world.setBlock(i + 5, j + 0, k + 42, Block.glowStone.blockID);
		world.setBlock(i + 5, j + 0, k + 43, Block.stoneDoubleSlab.blockID);
		world.setBlock(i + 5, j + 0, k + 44, Block.stoneDoubleSlab.blockID);
		world.setBlock(i + 5, j + 0, k + 45, Block.stoneDoubleSlab.blockID);
		world.setBlock(i + 5, j + 0, k + 46, Block.stoneBrick.blockID);
		world.setBlock(i + 5, j + 0, k + 50, Block.stoneBrick.blockID);
		world.setBlock(i + 5, j + 1, k + 4, Block.stoneBrick.blockID);
		world.setBlockAndMetadata(i + 5, j + 1, k + 14, Block.stoneBrick.blockID, 1);
		world.setBlock(i + 5, j + 1, k + 36, Block.stoneBrick.blockID);
		world.setBlock(i + 5, j + 1, k + 46, Block.stoneBrick.blockID);
		world.setBlock(i + 5, j + 2, k + 4, Block.stoneBrick.blockID);
		world.setBlockAndMetadata(i + 5, j + 2, k + 14, Block.stoneBrick.blockID, 1);
		world.setBlock(i + 5, j + 2, k + 36, Block.stoneBrick.blockID);
		world.setBlockAndMetadata(i + 5, j + 2, k + 46, Block.stoneBrick.blockID, 1);
		world.setBlock(i + 5, j + 3, k + 4, Block.stoneBrick.blockID);
		world.setBlock(i + 5, j + 3, k + 14, Block.stoneBrick.blockID);
		world.setBlock(i + 5, j + 3, k + 36, Block.stoneBrick.blockID);
		world.setBlockAndMetadata(i + 5, j + 3, k + 46, Block.stoneBrick.blockID, 1);
		world.setBlock(i + 5, j + 4, k + 4, Block.stoneBrick.blockID);
		world.setBlock(i + 5, j + 4, k + 14, Block.stoneBrick.blockID);
		world.setBlock(i + 5, j + 4, k + 36, Block.stoneBrick.blockID);
		world.setBlockAndMetadata(i + 5, j + 4, k + 46, Block.stoneBrick.blockID, 1);
		world.setBlock(i + 5, j + 5, k + 4, Block.stoneBrick.blockID);
		world.setBlock(i + 5, j + 5, k + 14, Block.stoneBrick.blockID);
		world.setBlock(i + 5, j + 5, k + 36, Block.stoneBrick.blockID);
		world.setBlock(i + 5, j + 5, k + 46, Block.stoneBrick.blockID);
		world.setBlock(i + 5, j + 6, k + 4, Block.stoneBrick.blockID);
		world.setBlock(i + 5, j + 6, k + 7, Block.netherFence.blockID);
		world.setBlock(i + 5, j + 6, k + 9, Block.netherFence.blockID);
		world.setBlock(i + 5, j + 6, k + 11, Block.netherFence.blockID);
		world.setBlock(i + 5, j + 6, k + 14, Block.stoneBrick.blockID);
		world.setBlock(i + 5, j + 6, k + 36, Block.stoneBrick.blockID);
		world.setBlock(i + 5, j + 6, k + 39, Block.netherFence.blockID);
		world.setBlock(i + 5, j + 6, k + 41, Block.netherFence.blockID);
		world.setBlock(i + 5, j + 6, k + 43, Block.netherFence.blockID);
		world.setBlockAndMetadata(i + 5, j + 6, k + 46, Block.stoneBrick.blockID, 2);
		world.setBlock(i + 5, j + 7, k + 4, Block.stoneBrick.blockID);
		world.setBlock(i + 5, j + 7, k + 5, Block.stoneBrick.blockID);
		world.setBlockAndMetadata(i + 5, j + 7, k + 6, Block.stoneSingleSlab.blockID, 13);
		world.setBlock(i + 5, j + 7, k + 7, Block.fence.blockID);
		world.setBlock(i + 5, j + 7, k + 9, Block.fence.blockID);
		world.setBlock(i + 5, j + 7, k + 11, Block.fence.blockID);
		world.setBlockAndMetadata(i + 5, j + 7, k + 12, Block.stoneSingleSlab.blockID, 13);
		world.setBlock(i + 5, j + 7, k + 13, Block.stoneBrick.blockID);
		world.setBlock(i + 5, j + 7, k + 14, Block.stoneBrick.blockID);
		world.setBlock(i + 5, j + 7, k + 36, Block.stoneBrick.blockID);
		world.setBlock(i + 5, j + 7, k + 37, Block.stoneBrick.blockID);
		world.setBlockAndMetadata(i + 5, j + 7, k + 38, Block.stoneSingleSlab.blockID, 13);
		world.setBlock(i + 5, j + 7, k + 39, Block.fence.blockID);
		world.setBlock(i + 5, j + 7, k + 41, Block.fence.blockID);
		world.setBlock(i + 5, j + 7, k + 43, Block.fence.blockID);
		world.setBlockAndMetadata(i + 5, j + 7, k + 44, Block.stoneSingleSlab.blockID, 13);
		world.setBlock(i + 5, j + 7, k + 45, Block.stoneBrick.blockID);
		world.setBlockAndMetadata(i + 5, j + 7, k + 46, Block.stoneBrick.blockID, 2);
		world.setBlock(i + 5, j + 8, k + 4, Block.stoneBrick.blockID);
		world.setBlock(i + 5, j + 8, k + 5, Block.wood.blockID);
		world.setBlock(i + 5, j + 8, k + 6, Block.wood.blockID);
		world.setBlockAndMetadata(i + 5, j + 8, k + 7, Block.stoneBrick.blockID, 3);
		world.setBlockAndMetadata(i + 5, j + 8, k + 8, Block.stoneBrick.blockID, 3);
		world.setBlockAndMetadata(i + 5, j + 8, k + 9, Block.stoneBrick.blockID, 3);
		world.setBlockAndMetadata(i + 5, j + 8, k + 10, Block.stoneBrick.blockID, 3);
		world.setBlockAndMetadata(i + 5, j + 8, k + 11, Block.stoneBrick.blockID, 3);
		world.setBlock(i + 5, j + 8, k + 12, Block.wood.blockID);
		world.setBlock(i + 5, j + 8, k + 13, Block.wood.blockID);
		world.setBlock(i + 5, j + 8, k + 14, Block.stoneBrick.blockID);
		world.setBlock(i + 5, j + 8, k + 36, Block.stoneBrick.blockID);
		world.setBlock(i + 5, j + 8, k + 37, Block.wood.blockID);
		world.setBlock(i + 5, j + 8, k + 38, Block.wood.blockID);
		world.setBlockAndMetadata(i + 5, j + 8, k + 39, Block.stoneBrick.blockID, 3);
		world.setBlockAndMetadata(i + 5, j + 8, k + 40, Block.stoneBrick.blockID, 3);
		world.setBlockAndMetadata(i + 5, j + 8, k + 41, Block.stoneBrick.blockID, 3);
		world.setBlockAndMetadata(i + 5, j + 8, k + 42, Block.stoneBrick.blockID, 3);
		world.setBlockAndMetadata(i + 5, j + 8, k + 43, Block.stoneBrick.blockID, 3);
		world.setBlock(i + 5, j + 8, k + 44, Block.wood.blockID);
		world.setBlock(i + 5, j + 8, k + 45, Block.wood.blockID);
		world.setBlock(i + 5, j + 8, k + 46, Block.stoneBrick.blockID);
		world.setBlock(i + 5, j + 9, k + 4, Block.stoneBrick.blockID);
		world.setBlock(i + 5, j + 9, k + 8, Block.stoneSingleSlab.blockID);
		world.setBlock(i + 5, j + 9, k + 9, Block.stoneSingleSlab.blockID);
		world.setBlock(i + 5, j + 9, k + 10, Block.stoneSingleSlab.blockID);
		world.setBlock(i + 5, j + 9, k + 14, Block.stoneBrick.blockID);
		world.setBlock(i + 5, j + 9, k + 36, Block.stoneBrick.blockID);
		world.setBlock(i + 5, j + 9, k + 40, Block.stoneSingleSlab.blockID);
		world.setBlock(i + 5, j + 9, k + 41, Block.stoneSingleSlab.blockID);
		world.setBlock(i + 5, j + 9, k + 42, Block.stoneSingleSlab.blockID);
		world.setBlock(i + 5, j + 9, k + 46, Block.stoneBrick.blockID);
		world.setBlockAndMetadata(i + 5, j + 10, k + 4, Block.stoneBrick.blockID, 2);
		world.setBlock(i + 5, j + 10, k + 14, Block.stoneBrick.blockID);
		world.setBlock(i + 5, j + 10, k + 36, Block.stoneBrick.blockID);
		world.setBlockAndMetadata(i + 5, j + 10, k + 46, Block.stoneBrick.blockID, 2);
		world.setBlockAndMetadata(i + 5, j + 11, k + 4, Block.stoneBrick.blockID, 2);
		world.setBlock(i + 5, j + 11, k + 14, Block.stoneBrick.blockID);
		world.setBlock(i + 5, j + 11, k + 36, Block.stoneBrick.blockID);
		world.setBlockAndMetadata(i + 5, j + 11, k + 46, Block.stoneBrick.blockID, 2);
		world.setBlock(i + 5, j + 12, k + 4, Block.stoneBrick.blockID);
		world.setBlock(i + 5, j + 12, k + 14, Block.stoneBrick.blockID);
		world.setBlock(i + 5, j + 12, k + 36, Block.stoneBrick.blockID);
		world.setBlock(i + 5, j + 12, k + 46, Block.stoneBrick.blockID);
		world.setBlock(i + 5, j + 13, k + 4, Block.stoneBrick.blockID);
		world.setBlockAndMetadata(i + 5, j + 13, k + 5, Block.stoneSingleSlab.blockID, 2);
		world.setBlockAndMetadata(i + 5, j + 13, k + 6, Block.stoneSingleSlab.blockID, 2);
		world.setBlockAndMetadata(i + 5, j + 13, k + 7, Block.stoneSingleSlab.blockID, 2);
		world.setBlockAndMetadata(i + 5, j + 13, k + 8, Block.stoneSingleSlab.blockID, 2);
		world.setBlockAndMetadata(i + 5, j + 13, k + 9, Block.stoneSingleSlab.blockID, 2);
		world.setBlockAndMetadata(i + 5, j + 13, k + 10, Block.stoneSingleSlab.blockID, 2);
		world.setBlockAndMetadata(i + 5, j + 13, k + 11, Block.stoneSingleSlab.blockID, 2);
		world.setBlockAndMetadata(i + 5, j + 13, k + 12, Block.stoneSingleSlab.blockID, 2);
		world.setBlockAndMetadata(i + 5, j + 13, k + 13, Block.stoneSingleSlab.blockID, 2);
		world.setBlock(i + 5, j + 13, k + 14, Block.stoneBrick.blockID);
		world.setBlock(i + 5, j + 13, k + 36, Block.stoneBrick.blockID);
		world.setBlockAndMetadata(i + 5, j + 13, k + 37, Block.stoneSingleSlab.blockID, 2);
		world.setBlockAndMetadata(i + 5, j + 13, k + 38, Block.stoneSingleSlab.blockID, 2);
		world.setBlockAndMetadata(i + 5, j + 13, k + 39, Block.stoneSingleSlab.blockID, 2);
		world.setBlockAndMetadata(i + 5, j + 13, k + 40, Block.stoneSingleSlab.blockID, 2);
		world.setBlockAndMetadata(i + 5, j + 13, k + 41, Block.stoneSingleSlab.blockID, 2);
		world.setBlockAndMetadata(i + 5, j + 13, k + 42, Block.stoneSingleSlab.blockID, 2);
		world.setBlockAndMetadata(i + 5, j + 13, k + 43, Block.stoneSingleSlab.blockID, 2);
		world.setBlockAndMetadata(i + 5, j + 13, k + 44, Block.stoneSingleSlab.blockID, 2);
		world.setBlockAndMetadata(i + 5, j + 13, k + 45, Block.stoneSingleSlab.blockID, 2);
		world.setBlock(i + 5, j + 13, k + 46, Block.stoneBrick.blockID);
		world.setBlockAndMetadata(i + 5, j + 19, k + 10, Block.cloth.blockID, 15);
		world.setBlockAndMetadata(i + 5, j + 19, k + 42, Block.cloth.blockID, 15);
		world.setBlockAndMetadata(i + 5, j + 20, k + 10, Block.cloth.blockID, 11);
		world.setBlockAndMetadata(i + 5, j + 20, k + 42, Block.cloth.blockID, 11);
		world.setBlockAndMetadata(i + 5, j + 21, k + 10, Block.cloth.blockID, 15);
		world.setBlockAndMetadata(i + 5, j + 21, k + 42, Block.cloth.blockID, 15);
		world.setBlock(i + 6, j + 0, k + 0, Block.stoneBrick.blockID);
		world.setBlock(i + 6, j + 0, k + 3, Block.stoneBrick.blockID);
		world.setBlock(i + 6, j + 0, k + 4, Block.stoneDoubleSlab.blockID);
		world.setBlock(i + 6, j + 0, k + 5, Block.stoneDoubleSlab.blockID);
		world.setBlock(i + 6, j + 0, k + 6, Block.stoneDoubleSlab.blockID);
		world.setBlock(i + 6, j + 0, k + 7, Block.glowStone.blockID);
		world.setBlock(i + 6, j + 0, k + 8, Block.glowStone.blockID);
		world.setBlockAndMetadata(i + 6, j + 0, k + 9, Block.cloth.blockID, 11);
		world.setBlock(i + 6, j + 0, k + 10, Block.glowStone.blockID);
		world.setBlock(i + 6, j + 0, k + 11, Block.glowStone.blockID);
		world.setBlock(i + 6, j + 0, k + 12, Block.stoneDoubleSlab.blockID);
		world.setBlock(i + 6, j + 0, k + 13, Block.stoneDoubleSlab.blockID);
		world.setBlock(i + 6, j + 0, k + 14, Block.stoneDoubleSlab.blockID);
		world.setBlock(i + 6, j + 0, k + 15, Block.stoneBrick.blockID);
		world.setBlockAndMetadata(i + 6, j + 0, k + 16, Block.stoneBrick.blockID, 1);
		world.setBlock(i + 6, j + 0, k + 17, Block.stoneBrick.blockID);
		world.setBlock(i + 6, j + 0, k + 18, Block.stoneBrick.blockID);
		world.setBlock(i + 6, j + 0, k + 19, Block.stoneBrick.blockID);
		world.setBlock(i + 6, j + 0, k + 20, Block.stoneBrick.blockID);
		world.setBlock(i + 6, j + 0, k + 21, Block.stoneBrick.blockID);
		world.setBlock(i + 6, j + 0, k + 22, Block.stoneBrick.blockID);
		world.setBlock(i + 6, j + 0, k + 23, Block.stoneBrick.blockID);
		world.setBlock(i + 6, j + 0, k + 24, Block.stoneBrick.blockID);
		world.setBlock(i + 6, j + 0, k + 25, Block.stoneBrick.blockID);
		world.setBlock(i + 6, j + 0, k + 26, Block.stoneBrick.blockID);
		world.setBlock(i + 6, j + 0, k + 27, Block.stoneBrick.blockID);
		world.setBlock(i + 6, j + 0, k + 28, Block.stoneBrick.blockID);
		world.setBlock(i + 6, j + 0, k + 29, Block.stoneBrick.blockID);
		world.setBlock(i + 6, j + 0, k + 30, Block.stoneBrick.blockID);
		world.setBlock(i + 6, j + 0, k + 31, Block.stoneBrick.blockID);
		world.setBlock(i + 6, j + 0, k + 32, Block.stoneBrick.blockID);
		world.setBlock(i + 6, j + 0, k + 33, Block.stoneBrick.blockID);
		world.setBlock(i + 6, j + 0, k + 34, Block.stoneBrick.blockID);
		world.setBlock(i + 6, j + 0, k + 35, Block.stoneBrick.blockID);
		world.setBlock(i + 6, j + 0, k + 36, Block.stoneDoubleSlab.blockID);
		world.setBlock(i + 6, j + 0, k + 37, Block.stoneDoubleSlab.blockID);
		world.setBlock(i + 6, j + 0, k + 38, Block.stoneDoubleSlab.blockID);
		world.setBlock(i + 6, j + 0, k + 39, Block.glowStone.blockID);
		world.setBlock(i + 6, j + 0, k + 40, Block.glowStone.blockID);
		world.setBlockAndMetadata(i + 6, j + 0, k + 41, Block.cloth.blockID, 11);
		world.setBlock(i + 6, j + 0, k + 42, Block.glowStone.blockID);
		world.setBlock(i + 6, j + 0, k + 43, Block.glowStone.blockID);
		world.setBlock(i + 6, j + 0, k + 44, Block.stoneDoubleSlab.blockID);
		world.setBlock(i + 6, j + 0, k + 45, Block.stoneDoubleSlab.blockID);
		world.setBlock(i + 6, j + 0, k + 46, Block.stoneDoubleSlab.blockID);
		world.setBlock(i + 6, j + 0, k + 47, Block.stoneBrick.blockID);
		world.setBlock(i + 6, j + 0, k + 50, Block.stoneBrick.blockID);
		world.setBlock(i + 6, j + 1, k + 3, Block.stoneBrick.blockID);
		world.setBlockAndMetadata(i + 6, j + 1, k + 15, Block.stoneBrick.blockID, 1);
		world.setBlockAndMetadata(i + 6, j + 1, k + 16, Block.stoneBrick.blockID, 1);
		world.setBlock(i + 6, j + 1, k + 17, Block.stoneBrick.blockID);
		world.setBlock(i + 6, j + 1, k + 18, Block.stoneBrick.blockID);
		world.setBlock(i + 6, j + 1, k + 19, Block.stoneBrick.blockID);
		world.setBlock(i + 6, j + 1, k + 20, Block.stoneBrick.blockID);
		world.setBlock(i + 6, j + 1, k + 21, Block.stoneBrick.blockID);
		world.setBlock(i + 6, j + 1, k + 22, Block.stoneBrick.blockID);
		world.setBlock(i + 6, j + 1, k + 23, Block.stoneBrick.blockID);
		world.setBlock(i + 6, j + 1, k + 24, Block.stoneBrick.blockID);
		world.setBlock(i + 6, j + 1, k + 25, Block.stoneBrick.blockID);
		world.setBlock(i + 6, j + 1, k + 26, Block.stoneBrick.blockID);
		world.setBlock(i + 6, j + 1, k + 27, Block.stoneBrick.blockID);
		world.setBlock(i + 6, j + 1, k + 28, Block.stoneBrick.blockID);
		world.setBlock(i + 6, j + 1, k + 29, Block.stoneBrick.blockID);
		world.setBlock(i + 6, j + 1, k + 30, Block.stoneBrick.blockID);
		world.setBlock(i + 6, j + 1, k + 31, Block.stoneBrick.blockID);
		world.setBlock(i + 6, j + 1, k + 32, Block.stoneBrick.blockID);
		world.setBlock(i + 6, j + 1, k + 33, Block.stoneBrick.blockID);
		world.setBlockAndMetadata(i + 6, j + 1, k + 34, Block.stoneBrick.blockID, 1);
		world.setBlock(i + 6, j + 1, k + 35, Block.stoneBrick.blockID);
		world.setBlockAndMetadata(i + 6, j + 1, k + 47, Block.stoneBrick.blockID, 1);
		world.setBlock(i + 6, j + 2, k + 3, Block.stoneBrick.blockID);
		world.setBlock(i + 6, j + 2, k + 15, Block.stoneBrick.blockID);
		world.setBlock(i + 6, j + 2, k + 16, Block.stoneBrick.blockID);
		world.setBlock(i + 6, j + 2, k + 17, Block.stoneBrick.blockID);
		world.setBlock(i + 6, j + 2, k + 18, Block.stoneBrick.blockID);
		world.setBlock(i + 6, j + 2, k + 19, Block.stoneBrick.blockID);
		world.setBlock(i + 6, j + 2, k + 20, Block.stoneBrick.blockID);
		world.setBlock(i + 6, j + 2, k + 21, Block.stoneBrick.blockID);
		world.setBlock(i + 6, j + 2, k + 22, Block.stoneBrick.blockID);
		world.setBlock(i + 6, j + 2, k + 23, Block.stoneBrick.blockID);
		world.setBlock(i + 6, j + 2, k + 24, Block.stoneBrick.blockID);
		world.setBlock(i + 6, j + 2, k + 25, Block.stoneBrick.blockID);
		world.setBlock(i + 6, j + 2, k + 26, Block.stoneBrick.blockID);
		world.setBlock(i + 6, j + 2, k + 27, Block.stoneBrick.blockID);
		world.setBlock(i + 6, j + 2, k + 28, Block.stoneBrick.blockID);
		world.setBlock(i + 6, j + 2, k + 29, Block.stoneBrick.blockID);
		world.setBlock(i + 6, j + 2, k + 30, Block.stoneBrick.blockID);
		world.setBlock(i + 6, j + 2, k + 31, Block.stoneBrick.blockID);
		world.setBlock(i + 6, j + 2, k + 32, Block.stoneBrick.blockID);
		world.setBlockAndMetadata(i + 6, j + 2, k + 33, Block.stoneBrick.blockID, 1);
		world.setBlockAndMetadata(i + 6, j + 2, k + 34, Block.stoneBrick.blockID, 1);
		world.setBlock(i + 6, j + 2, k + 35, Block.stoneBrick.blockID);
		world.setBlockAndMetadata(i + 6, j + 2, k + 47, Block.stoneBrick.blockID, 1);
		world.setBlock(i + 6, j + 3, k + 3, Block.stoneBrick.blockID);
		world.setBlock(i + 6, j + 3, k + 15, Block.stoneBrick.blockID);
		world.setBlock(i + 6, j + 3, k + 16, Block.stoneBrick.blockID);
		world.setBlock(i + 6, j + 3, k + 17, Block.stoneBrick.blockID);
		world.setBlock(i + 6, j + 3, k + 18, Block.stoneBrick.blockID);
		world.setBlock(i + 6, j + 3, k + 19, Block.stoneBrick.blockID);
		world.setBlock(i + 6, j + 3, k + 20, Block.stoneBrick.blockID);
		world.setBlock(i + 6, j + 3, k + 21, Block.stoneBrick.blockID);
		world.setBlockAndMetadata(i + 6, j + 3, k + 22, Block.stoneBrick.blockID, 1);
		world.setBlockAndMetadata(i + 6, j + 3, k + 23, Block.stoneBrick.blockID, 1);
		world.setBlock(i + 6, j + 3, k + 24, Block.stoneBrick.blockID);
		world.setBlock(i + 6, j + 3, k + 25, Block.stoneBrick.blockID);
		world.setBlockAndMetadata(i + 6, j + 3, k + 26, Block.stoneBrick.blockID, 1);
		world.setBlockAndMetadata(i + 6, j + 3, k + 27, Block.stoneBrick.blockID, 1);
		world.setBlock(i + 6, j + 3, k + 28, Block.stoneBrick.blockID);
		world.setBlock(i + 6, j + 3, k + 29, Block.stoneBrick.blockID);
		world.setBlock(i + 6, j + 3, k + 30, Block.stoneBrick.blockID);
		world.setBlock(i + 6, j + 3, k + 31, Block.stoneBrick.blockID);
		world.setBlock(i + 6, j + 3, k + 32, Block.stoneBrick.blockID);
		world.setBlockAndMetadata(i + 6, j + 3, k + 33, Block.stoneBrick.blockID, 1);
		world.setBlock(i + 6, j + 3, k + 34, Block.stoneBrick.blockID);
		world.setBlock(i + 6, j + 3, k + 35, Block.stoneBrick.blockID);
		world.setBlock(i + 6, j + 3, k + 47, Block.stoneBrick.blockID);
		world.setBlock(i + 6, j + 4, k + 3, Block.stoneBrick.blockID);
		world.setBlock(i + 6, j + 4, k + 15, Block.stoneBrick.blockID);
		world.setBlock(i + 6, j + 4, k + 16, Block.stoneBrick.blockID);
		world.setBlock(i + 6, j + 4, k + 17, Block.stoneBrick.blockID);
		world.setBlock(i + 6, j + 4, k + 18, Block.stoneBrick.blockID);
		world.setBlock(i + 6, j + 4, k + 19, Block.stoneBrick.blockID);
		world.setBlock(i + 6, j + 4, k + 20, Block.stoneBrick.blockID);
		world.setBlock(i + 6, j + 4, k + 21, Block.stoneBrick.blockID);
		world.setBlock(i + 6, j + 4, k + 22, Block.stoneBrick.blockID);
		world.setBlockAndMetadata(i + 6, j + 4, k + 23, Block.stoneBrick.blockID, 1);
		world.setBlockAndMetadata(i + 6, j + 4, k + 24, Block.stoneBrick.blockID, 1);
		world.setBlockAndMetadata(i + 6, j + 4, k + 25, Block.stoneBrick.blockID, 1);
		world.setBlockAndMetadata(i + 6, j + 4, k + 26, Block.stoneBrick.blockID, 1);
		world.setBlock(i + 6, j + 4, k + 27, Block.stoneBrick.blockID);
		world.setBlock(i + 6, j + 4, k + 28, Block.stoneBrick.blockID);
		world.setBlock(i + 6, j + 4, k + 29, Block.stoneBrick.blockID);
		world.setBlock(i + 6, j + 4, k + 30, Block.stoneBrick.blockID);
		world.setBlock(i + 6, j + 4, k + 31, Block.stoneBrick.blockID);
		world.setBlock(i + 6, j + 4, k + 32, Block.stoneBrick.blockID);
		world.setBlock(i + 6, j + 4, k + 33, Block.stoneBrick.blockID);
		world.setBlock(i + 6, j + 4, k + 34, Block.stoneBrick.blockID);
		world.setBlock(i + 6, j + 4, k + 35, Block.stoneBrick.blockID);
		world.setBlock(i + 6, j + 4, k + 47, Block.stoneBrick.blockID);
		world.setBlock(i + 6, j + 5, k + 3, Block.stoneBrick.blockID);
		world.setBlock(i + 6, j + 5, k + 15, Block.stoneBrick.blockID);
		world.setBlock(i + 6, j + 5, k + 16, Block.stoneBrick.blockID);
		world.setBlock(i + 6, j + 5, k + 17, Block.stoneBrick.blockID);
		world.setBlock(i + 6, j + 5, k + 18, Block.stoneBrick.blockID);
		world.setBlock(i + 6, j + 5, k + 19, Block.stoneBrick.blockID);
		world.setBlock(i + 6, j + 5, k + 20, Block.stoneBrick.blockID);
		world.setBlock(i + 6, j + 5, k + 21, Block.stoneBrick.blockID);
		world.setBlock(i + 6, j + 5, k + 22, Block.stoneBrick.blockID);
		world.setBlock(i + 6, j + 5, k + 23, Block.stoneBrick.blockID);
		world.setBlockAndMetadata(i + 6, j + 5, k + 24, Block.stoneBrick.blockID, 1);
		world.setBlockAndMetadata(i + 6, j + 5, k + 25, Block.stoneBrick.blockID, 1);
		world.setBlock(i + 6, j + 5, k + 26, Block.stoneBrick.blockID);
		world.setBlock(i + 6, j + 5, k + 27, Block.stoneBrick.blockID);
		world.setBlock(i + 6, j + 5, k + 28, Block.stoneBrick.blockID);
		world.setBlock(i + 6, j + 5, k + 29, Block.stoneBrick.blockID);
		world.setBlock(i + 6, j + 5, k + 30, Block.stoneBrick.blockID);
		world.setBlock(i + 6, j + 5, k + 31, Block.stoneBrick.blockID);
		world.setBlock(i + 6, j + 5, k + 32, Block.stoneBrick.blockID);
		world.setBlock(i + 6, j + 5, k + 33, Block.stoneBrick.blockID);
		world.setBlock(i + 6, j + 5, k + 34, Block.stoneBrick.blockID);
		world.setBlock(i + 6, j + 5, k + 35, Block.stoneBrick.blockID);
		world.setBlock(i + 6, j + 5, k + 47, Block.stoneBrick.blockID);
		world.setBlock(i + 6, j + 6, k + 3, Block.stoneBrick.blockID);
		world.setBlock(i + 6, j + 6, k + 6, Block.netherFence.blockID);
		world.setBlock(i + 6, j + 6, k + 8, Block.netherFence.blockID);
		world.setBlock(i + 6, j + 6, k + 10, Block.netherFence.blockID);
		world.setBlock(i + 6, j + 6, k + 12, Block.netherFence.blockID);
		world.setBlock(i + 6, j + 6, k + 15, Block.stoneBrick.blockID);
		world.setBlock(i + 6, j + 6, k + 16, Block.stoneBrick.blockID);
		world.setBlock(i + 6, j + 6, k + 17, Block.stoneBrick.blockID);
		world.setBlock(i + 6, j + 6, k + 18, Block.stoneBrick.blockID);
		world.setBlock(i + 6, j + 6, k + 19, Block.stoneBrick.blockID);
		world.setBlock(i + 6, j + 6, k + 20, Block.stoneBrick.blockID);
		world.setBlock(i + 6, j + 6, k + 21, Block.stoneBrick.blockID);
		world.setBlock(i + 6, j + 6, k + 22, Block.stoneBrick.blockID);
		world.setBlockAndMetadata(i + 6, j + 6, k + 23, Block.stoneBrick.blockID, 1);
		world.setBlockAndMetadata(i + 6, j + 6, k + 24, Block.stoneBrick.blockID, 1);
		world.setBlockAndMetadata(i + 6, j + 6, k + 25, Block.stoneBrick.blockID, 1);
		world.setBlockAndMetadata(i + 6, j + 6, k + 26, Block.stoneBrick.blockID, 1);
		world.setBlock(i + 6, j + 6, k + 27, Block.stoneBrick.blockID);
		world.setBlock(i + 6, j + 6, k + 28, Block.stoneBrick.blockID);
		world.setBlock(i + 6, j + 6, k + 29, Block.stoneBrick.blockID);
		world.setBlock(i + 6, j + 6, k + 30, Block.stoneBrick.blockID);
		world.setBlock(i + 6, j + 6, k + 31, Block.stoneBrick.blockID);
		world.setBlockAndMetadata(i + 6, j + 6, k + 32, Block.stoneBrick.blockID, 2);
		world.setBlock(i + 6, j + 6, k + 33, Block.stoneBrick.blockID);
		world.setBlock(i + 6, j + 6, k + 34, Block.stoneBrick.blockID);
		world.setBlock(i + 6, j + 6, k + 35, Block.stoneBrick.blockID);
		world.setBlock(i + 6, j + 6, k + 38, Block.netherFence.blockID);
		world.setBlock(i + 6, j + 6, k + 40, Block.netherFence.blockID);
		world.setBlock(i + 6, j + 6, k + 42, Block.netherFence.blockID);
		world.setBlock(i + 6, j + 6, k + 44, Block.netherFence.blockID);
		world.setBlock(i + 6, j + 6, k + 47, Block.stoneBrick.blockID);
		world.setBlock(i + 6, j + 7, k + 3, Block.stoneBrick.blockID);
		world.setBlock(i + 6, j + 7, k + 4, Block.stoneBrick.blockID);
		world.setBlockAndMetadata(i + 6, j + 7, k + 5, Block.stoneSingleSlab.blockID, 13);
		world.setBlock(i + 6, j + 7, k + 6, Block.fence.blockID);
		world.setBlock(i + 6, j + 7, k + 8, Block.fence.blockID);
		world.setBlock(i + 6, j + 7, k + 10, Block.fence.blockID);
		world.setBlock(i + 6, j + 7, k + 12, Block.fence.blockID);
		world.setBlockAndMetadata(i + 6, j + 7, k + 13, Block.stoneSingleSlab.blockID, 13);
		world.setBlock(i + 6, j + 7, k + 14, Block.stoneBrick.blockID);
		world.setBlock(i + 6, j + 7, k + 15, Block.stoneBrick.blockID);
		world.setBlock(i + 6, j + 7, k + 16, Block.stoneBrick.blockID);
		world.setBlockAndMetadata(i + 6, j + 7, k + 17, Block.stoneBrick.blockID, 2);
		world.setBlockAndMetadata(i + 6, j + 7, k + 18, Block.stoneBrick.blockID, 2);
		world.setBlock(i + 6, j + 7, k + 19, Block.stoneBrick.blockID);
		world.setBlock(i + 6, j + 7, k + 20, Block.stoneBrick.blockID);
		world.setBlock(i + 6, j + 7, k + 21, Block.stoneBrick.blockID);
		world.setBlock(i + 6, j + 7, k + 22, Block.stoneBrick.blockID);
		world.setBlock(i + 6, j + 7, k + 23, Block.stoneBrick.blockID);
		world.setBlockAndMetadata(i + 6, j + 7, k + 24, Block.stoneBrick.blockID, 1);
		world.setBlockAndMetadata(i + 6, j + 7, k + 25, Block.stoneBrick.blockID, 1);
		world.setBlock(i + 6, j + 7, k + 26, Block.stoneBrick.blockID);
		world.setBlock(i + 6, j + 7, k + 27, Block.stoneBrick.blockID);
		world.setBlock(i + 6, j + 7, k + 28, Block.stoneBrick.blockID);
		world.setBlock(i + 6, j + 7, k + 29, Block.stoneBrick.blockID);
		world.setBlock(i + 6, j + 7, k + 30, Block.stoneBrick.blockID);
		world.setBlock(i + 6, j + 7, k + 31, Block.stoneBrick.blockID);
		world.setBlockAndMetadata(i + 6, j + 7, k + 32, Block.stoneBrick.blockID, 2);
		world.setBlockAndMetadata(i + 6, j + 7, k + 33, Block.stoneBrick.blockID, 2);
		world.setBlock(i + 6, j + 7, k + 34, Block.stoneBrick.blockID);
		world.setBlock(i + 6, j + 7, k + 35, Block.stoneBrick.blockID);
		world.setBlock(i + 6, j + 7, k + 36, Block.stoneBrick.blockID);
		world.setBlockAndMetadata(i + 6, j + 7, k + 37, Block.stoneSingleSlab.blockID, 13);
		world.setBlock(i + 6, j + 7, k + 38, Block.fence.blockID);
		world.setBlock(i + 6, j + 7, k + 40, Block.fence.blockID);
		world.setBlock(i + 6, j + 7, k + 42, Block.fence.blockID);
		world.setBlock(i + 6, j + 7, k + 44, Block.fence.blockID);
		world.setBlockAndMetadata(i + 6, j + 7, k + 45, Block.stoneSingleSlab.blockID, 13);
		world.setBlock(i + 6, j + 7, k + 46, Block.stoneBrick.blockID);
		world.setBlockAndMetadata(i + 6, j + 7, k + 47, Block.stoneBrick.blockID, 2);
		world.setBlock(i + 6, j + 8, k + 3, Block.stoneBrick.blockID);
		world.setBlock(i + 6, j + 8, k + 4, Block.wood.blockID);
		world.setBlock(i + 6, j + 8, k + 5, Block.wood.blockID);
		world.setBlockAndMetadata(i + 6, j + 8, k + 6, Block.stoneBrick.blockID, 3);
		world.setBlockAndMetadata(i + 6, j + 8, k + 7, Block.stoneBrick.blockID, 3);
		world.setBlockAndMetadata(i + 6, j + 8, k + 8, Block.stoneBrick.blockID, 3);
		world.setBlockAndMetadata(i + 6, j + 8, k + 9, Block.stoneBrick.blockID, 3);
		world.setBlockAndMetadata(i + 6, j + 8, k + 10, Block.stoneBrick.blockID, 3);
		world.setBlockAndMetadata(i + 6, j + 8, k + 11, Block.stoneBrick.blockID, 3);
		world.setBlockAndMetadata(i + 6, j + 8, k + 12, Block.stoneBrick.blockID, 3);
		world.setBlock(i + 6, j + 8, k + 13, Block.wood.blockID);
		world.setBlock(i + 6, j + 8, k + 14, Block.wood.blockID);
		world.setBlock(i + 6, j + 8, k + 15, Block.stoneBrick.blockID);
		world.setBlockAndMetadata(i + 6, j + 8, k + 16, Block.stoneBrick.blockID, 2);
		world.setBlockAndMetadata(i + 6, j + 8, k + 17, Block.stoneBrick.blockID, 2);
		world.setBlock(i + 6, j + 8, k + 18, Block.stoneBrick.blockID);
		world.setBlock(i + 6, j + 8, k + 19, Block.stoneBrick.blockID);
		world.setBlock(i + 6, j + 8, k + 20, Block.stoneBrick.blockID);
		world.setBlock(i + 6, j + 8, k + 21, Block.stoneBrick.blockID);
		world.setBlock(i + 6, j + 8, k + 22, Block.stoneBrick.blockID);
		world.setBlock(i + 6, j + 8, k + 23, Block.stoneBrick.blockID);
		world.setBlock(i + 6, j + 8, k + 24, Block.stoneBrick.blockID);
		world.setBlock(i + 6, j + 8, k + 25, Block.stoneBrick.blockID);
		world.setBlock(i + 6, j + 8, k + 26, Block.stoneBrick.blockID);
		world.setBlock(i + 6, j + 8, k + 27, Block.stoneBrick.blockID);
		world.setBlock(i + 6, j + 8, k + 28, Block.stoneBrick.blockID);
		world.setBlock(i + 6, j + 8, k + 29, Block.stoneBrick.blockID);
		world.setBlock(i + 6, j + 8, k + 30, Block.stoneBrick.blockID);
		world.setBlock(i + 6, j + 8, k + 31, Block.stoneBrick.blockID);
		world.setBlock(i + 6, j + 8, k + 32, Block.stoneBrick.blockID);
		world.setBlockAndMetadata(i + 6, j + 8, k + 33, Block.stoneBrick.blockID, 2);
		world.setBlockAndMetadata(i + 6, j + 8, k + 34, Block.stoneBrick.blockID, 2);
		world.setBlock(i + 6, j + 8, k + 35, Block.stoneBrick.blockID);
		world.setBlock(i + 6, j + 8, k + 36, Block.wood.blockID);
		world.setBlock(i + 6, j + 8, k + 37, Block.wood.blockID);
		world.setBlockAndMetadata(i + 6, j + 8, k + 38, Block.stoneBrick.blockID, 3);
		world.setBlockAndMetadata(i + 6, j + 8, k + 39, Block.stoneBrick.blockID, 3);
		world.setBlockAndMetadata(i + 6, j + 8, k + 40, Block.stoneBrick.blockID, 3);
		world.setBlockAndMetadata(i + 6, j + 8, k + 41, Block.stoneBrick.blockID, 3);
		world.setBlockAndMetadata(i + 6, j + 8, k + 42, Block.stoneBrick.blockID, 3);
		world.setBlockAndMetadata(i + 6, j + 8, k + 43, Block.stoneBrick.blockID, 3);
		world.setBlockAndMetadata(i + 6, j + 8, k + 44, Block.stoneBrick.blockID, 3);
		world.setBlock(i + 6, j + 8, k + 45, Block.wood.blockID);
		world.setBlock(i + 6, j + 8, k + 46, Block.wood.blockID);
		world.setBlockAndMetadata(i + 6, j + 8, k + 47, Block.stoneBrick.blockID, 2);
		world.setBlock(i + 6, j + 9, k + 3, Block.stoneBrick.blockID);
		world.setBlock(i + 6, j + 9, k + 4, Block.fence.blockID);
		world.setBlock(i + 6, j + 9, k + 7, Block.stoneSingleSlab.blockID);
		world.setBlock(i + 6, j + 9, k + 8, Block.stoneBrick.blockID);
		world.setBlock(i + 6, j + 9, k + 9, Block.stoneBrick.blockID);
		world.setBlock(i + 6, j + 9, k + 10, Block.stoneBrick.blockID);
		world.setBlock(i + 6, j + 9, k + 11, Block.stoneSingleSlab.blockID);
		world.setBlockAndMetadata(i + 6, j + 9, k + 15, Block.stoneBrick.blockID, 2);
		world.setBlockAndMetadata(i + 6, j + 9, k + 16, Block.stoneBrick.blockID, 2);
		world.setBlock(i + 6, j + 9, k + 17, Block.stoneBrick.blockID);
		world.setBlockAndMetadata(i + 6, j + 9, k + 18, Block.stoneSingleSlab.blockID, 5);
		world.setBlockAndMetadata(i + 6, j + 9, k + 20, Block.stoneSingleSlab.blockID, 5);
		world.setBlockAndMetadata(i + 6, j + 9, k + 22, Block.stoneSingleSlab.blockID, 5);
		world.setBlockAndMetadata(i + 6, j + 9, k + 24, Block.stoneSingleSlab.blockID, 5);
		world.setBlock(i + 6, j + 9, k + 25, Block.stoneBrick.blockID);
		world.setBlockAndMetadata(i + 6, j + 9, k + 26, Block.stoneSingleSlab.blockID, 5);
		world.setBlockAndMetadata(i + 6, j + 9, k + 28, Block.stoneSingleSlab.blockID, 5);
		world.setBlockAndMetadata(i + 6, j + 9, k + 30, Block.stoneSingleSlab.blockID, 5);
		world.setBlockAndMetadata(i + 6, j + 9, k + 32, Block.stoneSingleSlab.blockID, 5);
		world.setBlock(i + 6, j + 9, k + 33, Block.stoneBrick.blockID);
		world.setBlockAndMetadata(i + 6, j + 9, k + 34, Block.stoneBrick.blockID, 2);
		world.setBlock(i + 6, j + 9, k + 35, Block.stoneBrick.blockID);
		world.setBlock(i + 6, j + 9, k + 39, Block.stoneSingleSlab.blockID);
		world.setBlock(i + 6, j + 9, k + 40, Block.stoneBrick.blockID);
		world.setBlock(i + 6, j + 9, k + 41, Block.stoneBrick.blockID);
		world.setBlock(i + 6, j + 9, k + 42, Block.stoneBrick.blockID);
		world.setBlock(i + 6, j + 9, k + 43, Block.stoneSingleSlab.blockID);
		world.setBlock(i + 6, j + 9, k + 46, Block.fence.blockID);
		world.setBlockAndMetadata(i + 6, j + 9, k + 47, Block.stoneBrick.blockID, 2);
		world.setBlock(i + 6, j + 10, k + 3, Block.stoneBrick.blockID);
		world.setBlockAndMetadata(i + 6, j + 10, k + 9, Block.stoneSingleSlab.blockID, 5);
		world.setBlock(i + 6, j + 10, k + 15, Block.stoneBrick.blockID);
		world.setBlockAndMetadata(i + 6, j + 10, k + 16, Block.stoneSingleSlab.blockID, 5);
		world.setBlockAndMetadata(i + 6, j + 10, k + 34, Block.stoneSingleSlab.blockID, 5);
		world.setBlock(i + 6, j + 10, k + 35, Block.stoneBrick.blockID);
		world.setBlockAndMetadata(i + 6, j + 10, k + 41, Block.stoneSingleSlab.blockID, 5);
		world.setBlock(i + 6, j + 10, k + 47, Block.stoneBrick.blockID);
		world.setBlockAndMetadata(i + 6, j + 11, k + 3, Block.stoneBrick.blockID, 2);
		world.setBlock(i + 6, j + 11, k + 15, Block.stoneBrick.blockID);
		world.setBlock(i + 6, j + 11, k + 35, Block.stoneBrick.blockID);
		world.setBlock(i + 6, j + 11, k + 47, Block.stoneBrick.blockID);
		world.setBlockAndMetadata(i + 6, j + 12, k + 3, Block.stoneBrick.blockID, 2);
		world.setBlock(i + 6, j + 12, k + 15, Block.stoneBrick.blockID);
		world.setBlock(i + 6, j + 12, k + 35, Block.stoneBrick.blockID);
		world.setBlock(i + 6, j + 12, k + 47, Block.stoneBrick.blockID);
		world.setBlock(i + 6, j + 13, k + 3, Block.stoneBrick.blockID);
		world.setBlockAndMetadata(i + 6, j + 13, k + 4, Block.stoneSingleSlab.blockID, 2);
		world.setBlockAndMetadata(i + 6, j + 13, k + 5, Block.stoneSingleSlab.blockID, 2);
		world.setBlockAndMetadata(i + 6, j + 13, k + 6, Block.stoneSingleSlab.blockID, 2);
		world.setBlockAndMetadata(i + 6, j + 13, k + 7, Block.stoneSingleSlab.blockID, 2);
		world.setBlock(i + 6, j + 13, k + 8, Block.planks.blockID);
		world.setBlock(i + 6, j + 13, k + 9, Block.planks.blockID);
		world.setBlock(i + 6, j + 13, k + 10, Block.planks.blockID);
		world.setBlockAndMetadata(i + 6, j + 13, k + 11, Block.stoneSingleSlab.blockID, 2);
		world.setBlockAndMetadata(i + 6, j + 13, k + 12, Block.stoneSingleSlab.blockID, 2);
		world.setBlockAndMetadata(i + 6, j + 13, k + 13, Block.stoneSingleSlab.blockID, 2);
		world.setBlockAndMetadata(i + 6, j + 13, k + 14, Block.stoneSingleSlab.blockID, 2);
		world.setBlock(i + 6, j + 13, k + 15, Block.stoneBrick.blockID);
		world.setBlock(i + 6, j + 13, k + 35, Block.stoneBrick.blockID);
		world.setBlockAndMetadata(i + 6, j + 13, k + 36, Block.stoneSingleSlab.blockID, 2);
		world.setBlockAndMetadata(i + 6, j + 13, k + 37, Block.stoneSingleSlab.blockID, 2);
		world.setBlockAndMetadata(i + 6, j + 13, k + 38, Block.stoneSingleSlab.blockID, 2);
		world.setBlockAndMetadata(i + 6, j + 13, k + 39, Block.stoneSingleSlab.blockID, 2);
		world.setBlock(i + 6, j + 13, k + 40, Block.planks.blockID);
		world.setBlock(i + 6, j + 13, k + 41, Block.planks.blockID);
		world.setBlock(i + 6, j + 13, k + 42, Block.planks.blockID);
		world.setBlockAndMetadata(i + 6, j + 13, k + 43, Block.stoneSingleSlab.blockID, 2);
		world.setBlockAndMetadata(i + 6, j + 13, k + 44, Block.stoneSingleSlab.blockID, 2);
		world.setBlockAndMetadata(i + 6, j + 13, k + 45, Block.stoneSingleSlab.blockID, 2);
		world.setBlockAndMetadata(i + 6, j + 13, k + 46, Block.stoneSingleSlab.blockID, 2);
		world.setBlock(i + 6, j + 13, k + 47, Block.stoneBrick.blockID);
		world.setBlockAndMetadata(i + 6, j + 14, k + 3, Block.stoneSingleSlab.blockID, 5);
		world.setBlockAndMetadata(i + 6, j + 14, k + 15, Block.stoneSingleSlab.blockID, 5);
		world.setBlockAndMetadata(i + 6, j + 14, k + 35, Block.stoneSingleSlab.blockID, 5);
		world.setBlockAndMetadata(i + 6, j + 14, k + 47, Block.stoneSingleSlab.blockID, 5);
		world.setBlockAndMetadata(i + 6, j + 19, k + 9, Block.cloth.blockID, 15);
		world.setBlockAndMetadata(i + 6, j + 19, k + 41, Block.cloth.blockID, 15);
		world.setBlockAndMetadata(i + 6, j + 20, k + 9, Block.cloth.blockID, 11);
		world.setBlockAndMetadata(i + 6, j + 20, k + 41, Block.cloth.blockID, 11);
		world.setBlockAndMetadata(i + 6, j + 21, k + 9, Block.cloth.blockID, 15);
		world.setBlockAndMetadata(i + 6, j + 21, k + 41, Block.cloth.blockID, 15);
		world.setBlock(i + 7, j + 0, k + 0, Block.stoneBrick.blockID);
		world.setBlock(i + 7, j + 0, k + 3, Block.stoneBrick.blockID);
		world.setBlock(i + 7, j + 0, k + 4, Block.stoneDoubleSlab.blockID);
		world.setBlock(i + 7, j + 0, k + 5, Block.stoneDoubleSlab.blockID);
		world.setBlock(i + 7, j + 0, k + 6, Block.glowStone.blockID);
		world.setBlock(i + 7, j + 0, k + 7, Block.glowStone.blockID);
		world.setBlockAndMetadata(i + 7, j + 0, k + 8, Block.cloth.blockID, 11);
		world.setBlockAndMetadata(i + 7, j + 0, k + 9, Block.cloth.blockID, 11);
		world.setBlockAndMetadata(i + 7, j + 0, k + 10, Block.cloth.blockID, 11);
		world.setBlock(i + 7, j + 0, k + 11, Block.glowStone.blockID);
		world.setBlock(i + 7, j + 0, k + 12, Block.glowStone.blockID);
		world.setBlock(i + 7, j + 0, k + 13, Block.stoneDoubleSlab.blockID);
		world.setBlock(i + 7, j + 0, k + 14, Block.stoneDoubleSlab.blockID);
		world.setBlock(i + 7, j + 0, k + 15, Block.obsidian.blockID);
		world.setBlock(i + 7, j + 0, k + 16, Block.obsidian.blockID);
		world.setBlock(i + 7, j + 0, k + 17, Block.obsidian.blockID);
		world.setBlock(i + 7, j + 0, k + 18, Block.obsidian.blockID);
		world.setBlock(i + 7, j + 0, k + 19, Block.obsidian.blockID);
		world.setBlock(i + 7, j + 0, k + 20, Block.obsidian.blockID);
		world.setBlock(i + 7, j + 0, k + 21, Block.obsidian.blockID);
		world.setBlock(i + 7, j + 0, k + 22, Block.obsidian.blockID);
		world.setBlock(i + 7, j + 0, k + 23, Block.obsidian.blockID);
		world.setBlock(i + 7, j + 0, k + 24, Block.obsidian.blockID);
		world.setBlock(i + 7, j + 0, k + 25, Block.obsidian.blockID);
		world.setBlock(i + 7, j + 0, k + 26, Block.obsidian.blockID);
		world.setBlock(i + 7, j + 0, k + 27, Block.obsidian.blockID);
		world.setBlock(i + 7, j + 0, k + 28, Block.obsidian.blockID);
		world.setBlock(i + 7, j + 0, k + 29, Block.obsidian.blockID);
		world.setBlock(i + 7, j + 0, k + 30, Block.obsidian.blockID);
		world.setBlock(i + 7, j + 0, k + 31, Block.obsidian.blockID);
		world.setBlock(i + 7, j + 0, k + 32, Block.obsidian.blockID);
		world.setBlock(i + 7, j + 0, k + 33, Block.obsidian.blockID);
		world.setBlock(i + 7, j + 0, k + 34, Block.obsidian.blockID);
		world.setBlock(i + 7, j + 0, k + 35, Block.obsidian.blockID);
		world.setBlock(i + 7, j + 0, k + 36, Block.stoneDoubleSlab.blockID);
		world.setBlock(i + 7, j + 0, k + 37, Block.stoneDoubleSlab.blockID);
		world.setBlock(i + 7, j + 0, k + 38, Block.glowStone.blockID);
		world.setBlock(i + 7, j + 0, k + 39, Block.glowStone.blockID);
		world.setBlockAndMetadata(i + 7, j + 0, k + 40, Block.cloth.blockID, 11);
		world.setBlockAndMetadata(i + 7, j + 0, k + 41, Block.cloth.blockID, 11);
		world.setBlockAndMetadata(i + 7, j + 0, k + 42, Block.cloth.blockID, 11);
		world.setBlock(i + 7, j + 0, k + 43, Block.glowStone.blockID);
		world.setBlock(i + 7, j + 0, k + 44, Block.glowStone.blockID);
		world.setBlock(i + 7, j + 0, k + 45, Block.stoneDoubleSlab.blockID);
		world.setBlock(i + 7, j + 0, k + 46, Block.stoneDoubleSlab.blockID);
		world.setBlock(i + 7, j + 0, k + 47, Block.stoneBrick.blockID);
		world.setBlock(i + 7, j + 0, k + 50, Block.stoneBrick.blockID);
		world.setBlock(i + 7, j + 1, k + 3, Block.stoneBrick.blockID);
		world.setBlock(i + 7, j + 1, k + 47, Block.stoneBrick.blockID);
		world.setBlock(i + 7, j + 2, k + 3, Block.stoneBrick.blockID);
		world.setBlock(i + 7, j + 2, k + 47, Block.stoneBrick.blockID);
		world.setBlock(i + 7, j + 3, k + 3, Block.stoneBrick.blockID);
		world.setBlock(i + 7, j + 3, k + 47, Block.stoneBrick.blockID);
		world.setBlock(i + 7, j + 4, k + 3, Block.stoneBrick.blockID);
		world.setBlock(i + 7, j + 4, k + 47, Block.stoneBrick.blockID);
		world.setBlock(i + 7, j + 5, k + 3, Block.stoneBrick.blockID);
		world.setBlock(i + 7, j + 5, k + 47, Block.stoneBrick.blockID);
		world.setBlock(i + 7, j + 6, k + 3, Block.stoneBrick.blockID);
		world.setBlock(i + 7, j + 6, k + 5, Block.netherFence.blockID);
		world.setBlock(i + 7, j + 6, k + 7, Block.netherFence.blockID);
		world.setBlock(i + 7, j + 6, k + 9, Block.netherFence.blockID);
		world.setBlock(i + 7, j + 6, k + 11, Block.netherFence.blockID);
		world.setBlock(i + 7, j + 6, k + 13, Block.netherFence.blockID);
		world.setBlock(i + 7, j + 6, k + 37, Block.netherFence.blockID);
		world.setBlock(i + 7, j + 6, k + 39, Block.netherFence.blockID);
		world.setBlock(i + 7, j + 6, k + 41, Block.netherFence.blockID);
		world.setBlock(i + 7, j + 6, k + 43, Block.netherFence.blockID);
		world.setBlock(i + 7, j + 6, k + 45, Block.netherFence.blockID);
		world.setBlockAndMetadata(i + 7, j + 6, k + 47, Block.stoneBrick.blockID, 2);
		world.setBlockAndMetadata(i + 7, j + 7, k + 3, Block.stoneBrick.blockID, 1);
		world.setBlockAndMetadata(i + 7, j + 7, k + 4, Block.stoneSingleSlab.blockID, 13);
		world.setBlock(i + 7, j + 7, k + 5, Block.fence.blockID);
		world.setBlock(i + 7, j + 7, k + 7, Block.fence.blockID);
		world.setBlock(i + 7, j + 7, k + 9, Block.fence.blockID);
		world.setBlock(i + 7, j + 7, k + 11, Block.fence.blockID);
		world.setBlock(i + 7, j + 7, k + 13, Block.fence.blockID);
		world.setBlockAndMetadata(i + 7, j + 7, k + 14, Block.stoneSingleSlab.blockID, 13);
		world.setBlockAndMetadata(i + 7, j + 7, k + 36, Block.stoneSingleSlab.blockID, 13);
		world.setBlock(i + 7, j + 7, k + 37, Block.fence.blockID);
		world.setBlock(i + 7, j + 7, k + 39, Block.fence.blockID);
		world.setBlock(i + 7, j + 7, k + 41, Block.fence.blockID);
		world.setBlock(i + 7, j + 7, k + 43, Block.fence.blockID);
		world.setBlock(i + 7, j + 7, k + 45, Block.fence.blockID);
		world.setBlockAndMetadata(i + 7, j + 7, k + 46, Block.stoneSingleSlab.blockID, 13);
		world.setBlockAndMetadata(i + 7, j + 7, k + 47, Block.stoneBrick.blockID, 2);
		world.setBlock(i + 7, j + 8, k + 3, Block.fence.blockID);
		world.setBlock(i + 7, j + 8, k + 4, Block.wood.blockID);
		world.setBlockAndMetadata(i + 7, j + 8, k + 5, Block.stoneBrick.blockID, 3);
		world.setBlockAndMetadata(i + 7, j + 8, k + 6, Block.stoneBrick.blockID, 3);
		world.setBlockAndMetadata(i + 7, j + 8, k + 7, Block.stoneBrick.blockID, 3);
		world.setBlockAndMetadata(i + 7, j + 8, k + 8, Block.stoneBrick.blockID, 3);
		world.setBlockAndMetadata(i + 7, j + 8, k + 9, Block.stoneBrick.blockID, 3);
		world.setBlockAndMetadata(i + 7, j + 8, k + 10, Block.stoneBrick.blockID, 3);
		world.setBlockAndMetadata(i + 7, j + 8, k + 11, Block.stoneBrick.blockID, 3);
		world.setBlockAndMetadata(i + 7, j + 8, k + 12, Block.stoneBrick.blockID, 3);
		world.setBlockAndMetadata(i + 7, j + 8, k + 13, Block.stoneBrick.blockID, 3);
		world.setBlock(i + 7, j + 8, k + 14, Block.wood.blockID);
		world.setBlockAndMetadata(i + 7, j + 8, k + 15, Block.stairCompactPlanks.blockID, 3);
		world.setBlockAndMetadata(i + 7, j + 8, k + 16, Block.stoneSingleSlab.blockID, 2);
		world.setBlockAndMetadata(i + 7, j + 8, k + 17, Block.stoneSingleSlab.blockID, 2);
		world.setBlockAndMetadata(i + 7, j + 8, k + 18, Block.stoneSingleSlab.blockID, 2);
		world.setBlockAndMetadata(i + 7, j + 8, k + 19, Block.stoneSingleSlab.blockID, 2);
		world.setBlockAndMetadata(i + 7, j + 8, k + 20, Block.stoneSingleSlab.blockID, 2);
		world.setBlockAndMetadata(i + 7, j + 8, k + 21, Block.stoneSingleSlab.blockID, 2);
		world.setBlockAndMetadata(i + 7, j + 8, k + 22, Block.stoneSingleSlab.blockID, 2);
		world.setBlockAndMetadata(i + 7, j + 8, k + 23, Block.stoneSingleSlab.blockID, 2);
		world.setBlockAndMetadata(i + 7, j + 8, k + 24, Block.stoneSingleSlab.blockID, 2);
		world.setBlockAndMetadata(i + 7, j + 8, k + 25, Block.stoneSingleSlab.blockID, 2);
		world.setBlockAndMetadata(i + 7, j + 8, k + 26, Block.stoneSingleSlab.blockID, 2);
		world.setBlockAndMetadata(i + 7, j + 8, k + 27, Block.stoneSingleSlab.blockID, 2);
		world.setBlockAndMetadata(i + 7, j + 8, k + 28, Block.stoneSingleSlab.blockID, 2);
		world.setBlockAndMetadata(i + 7, j + 8, k + 29, Block.stoneSingleSlab.blockID, 2);
		world.setBlockAndMetadata(i + 7, j + 8, k + 30, Block.stoneSingleSlab.blockID, 2);
		world.setBlockAndMetadata(i + 7, j + 8, k + 31, Block.stoneSingleSlab.blockID, 2);
		world.setBlockAndMetadata(i + 7, j + 8, k + 32, Block.stoneSingleSlab.blockID, 2);
		world.setBlockAndMetadata(i + 7, j + 8, k + 33, Block.stoneSingleSlab.blockID, 2);
		world.setBlockAndMetadata(i + 7, j + 8, k + 34, Block.stoneSingleSlab.blockID, 2);
		world.setBlockAndMetadata(i + 7, j + 8, k + 35, Block.stairCompactPlanks.blockID, 2);
		world.setBlock(i + 7, j + 8, k + 36, Block.wood.blockID);
		world.setBlockAndMetadata(i + 7, j + 8, k + 37, Block.stoneBrick.blockID, 3);
		world.setBlockAndMetadata(i + 7, j + 8, k + 38, Block.stoneBrick.blockID, 3);
		world.setBlockAndMetadata(i + 7, j + 8, k + 39, Block.stoneBrick.blockID, 3);
		world.setBlockAndMetadata(i + 7, j + 8, k + 40, Block.stoneBrick.blockID, 3);
		world.setBlockAndMetadata(i + 7, j + 8, k + 41, Block.stoneBrick.blockID, 3);
		world.setBlockAndMetadata(i + 7, j + 8, k + 42, Block.stoneBrick.blockID, 3);
		world.setBlockAndMetadata(i + 7, j + 8, k + 43, Block.stoneBrick.blockID, 3);
		world.setBlockAndMetadata(i + 7, j + 8, k + 44, Block.stoneBrick.blockID, 3);
		world.setBlockAndMetadata(i + 7, j + 8, k + 45, Block.stoneBrick.blockID, 3);
		world.setBlock(i + 7, j + 8, k + 46, Block.wood.blockID);
		world.setBlock(i + 7, j + 8, k + 47, Block.fence.blockID);
		world.setBlock(i + 7, j + 9, k + 6, Block.stoneSingleSlab.blockID);
		world.setBlock(i + 7, j + 9, k + 7, Block.stoneBrick.blockID);
		world.setBlock(i + 7, j + 9, k + 8, Block.stoneBrick.blockID);
		world.setBlock(i + 7, j + 9, k + 9, Block.stoneBrick.blockID);
		world.setBlock(i + 7, j + 9, k + 10, Block.stoneBrick.blockID);
		world.setBlock(i + 7, j + 9, k + 11, Block.stoneBrick.blockID);
		world.setBlock(i + 7, j + 9, k + 12, Block.stoneSingleSlab.blockID);
		world.setBlock(i + 7, j + 9, k + 38, Block.stoneSingleSlab.blockID);
		world.setBlock(i + 7, j + 9, k + 39, Block.stoneSingleSlab.blockID);
		world.setBlock(i + 7, j + 9, k + 40, Block.stoneBrick.blockID);
		world.setBlock(i + 7, j + 9, k + 41, Block.stoneBrick.blockID);
		world.setBlock(i + 7, j + 9, k + 42, Block.stoneBrick.blockID);
		world.setBlock(i + 7, j + 9, k + 43, Block.stoneBrick.blockID);
		world.setBlock(i + 7, j + 9, k + 44, Block.stoneSingleSlab.blockID);
		world.setBlock(i + 7, j + 10, k + 8, Block.stoneBrick.blockID);
		world.setBlock(i + 7, j + 10, k + 9, Block.stoneBrick.blockID);
		world.setBlock(i + 7, j + 10, k + 10, Block.stoneBrick.blockID);
		world.setBlock(i + 7, j + 10, k + 40, Block.stoneBrick.blockID);
		world.setBlock(i + 7, j + 10, k + 41, Block.stoneBrick.blockID);
		world.setBlock(i + 7, j + 10, k + 42, Block.stoneBrick.blockID);
		world.setBlock(i + 7, j + 11, k + 3, Block.fence.blockID);
		world.setBlock(i + 7, j + 11, k + 8, Block.stoneBrick.blockID);
		world.setBlock(i + 7, j + 11, k + 9, Block.stoneBrick.blockID);
		world.setBlock(i + 7, j + 11, k + 10, Block.stoneBrick.blockID);
		world.setBlockAndMetadata(i + 7, j + 11, k + 15, Block.stairsStoneBrickSmooth.blockID, 5);
		world.setBlockAndMetadata(i + 7, j + 11, k + 35, Block.stairsStoneBrickSmooth.blockID, 5);
		world.setBlock(i + 7, j + 11, k + 40, Block.stoneBrick.blockID);
		world.setBlock(i + 7, j + 11, k + 41, Block.stoneBrick.blockID);
		world.setBlock(i + 7, j + 11, k + 42, Block.stoneBrick.blockID);
		world.setBlock(i + 7, j + 11, k + 47, Block.fence.blockID);
		world.setBlockAndMetadata(i + 7, j + 12, k + 3, Block.stoneBrick.blockID, 2);
		world.setBlock(i + 7, j + 12, k + 8, Block.stoneBrick.blockID);
		world.setBlock(i + 7, j + 12, k + 9, Block.stoneBrick.blockID);
		world.setBlock(i + 7, j + 12, k + 10, Block.stoneBrick.blockID);
		world.setBlock(i + 7, j + 12, k + 15, Block.stoneBrick.blockID);
		world.setBlock(i + 7, j + 12, k + 35, Block.stoneBrick.blockID);
		world.setBlock(i + 7, j + 12, k + 40, Block.stoneBrick.blockID);
		world.setBlock(i + 7, j + 12, k + 41, Block.stoneBrick.blockID);
		world.setBlock(i + 7, j + 12, k + 42, Block.stoneBrick.blockID);
		world.setBlock(i + 7, j + 12, k + 47, Block.stoneBrick.blockID);
		world.setBlock(i + 7, j + 13, k + 3, Block.stoneBrick.blockID);
		world.setBlockAndMetadata(i + 7, j + 13, k + 4, Block.stoneSingleSlab.blockID, 2);
		world.setBlockAndMetadata(i + 7, j + 13, k + 5, Block.stoneSingleSlab.blockID, 2);
		world.setBlockAndMetadata(i + 7, j + 13, k + 6, Block.stoneSingleSlab.blockID, 2);
		world.setBlock(i + 7, j + 13, k + 7, Block.planks.blockID);
		world.setBlock(i + 7, j + 13, k + 8, Block.planks.blockID);
		world.setBlock(i + 7, j + 13, k + 9, Block.planks.blockID);
		world.setBlock(i + 7, j + 13, k + 10, Block.planks.blockID);
		world.setBlock(i + 7, j + 13, k + 11, Block.planks.blockID);
		world.setBlockAndMetadata(i + 7, j + 13, k + 12, Block.stoneSingleSlab.blockID, 2);
		world.setBlockAndMetadata(i + 7, j + 13, k + 13, Block.stoneSingleSlab.blockID, 2);
		world.setBlockAndMetadata(i + 7, j + 13, k + 14, Block.stoneSingleSlab.blockID, 2);
		world.setBlock(i + 7, j + 13, k + 15, Block.stoneBrick.blockID);
		world.setBlock(i + 7, j + 13, k + 35, Block.stoneBrick.blockID);
		world.setBlockAndMetadata(i + 7, j + 13, k + 36, Block.stoneSingleSlab.blockID, 2);
		world.setBlockAndMetadata(i + 7, j + 13, k + 37, Block.stoneSingleSlab.blockID, 2);
		world.setBlockAndMetadata(i + 7, j + 13, k + 38, Block.stoneSingleSlab.blockID, 2);
		world.setBlock(i + 7, j + 13, k + 39, Block.planks.blockID);
		world.setBlock(i + 7, j + 13, k + 40, Block.planks.blockID);
		world.setBlock(i + 7, j + 13, k + 41, Block.planks.blockID);
		world.setBlock(i + 7, j + 13, k + 42, Block.planks.blockID);
		world.setBlock(i + 7, j + 13, k + 43, Block.planks.blockID);
		world.setBlockAndMetadata(i + 7, j + 13, k + 44, Block.stoneSingleSlab.blockID, 2);
		world.setBlockAndMetadata(i + 7, j + 13, k + 45, Block.stoneSingleSlab.blockID, 2);
		world.setBlockAndMetadata(i + 7, j + 13, k + 46, Block.stoneSingleSlab.blockID, 2);
		world.setBlock(i + 7, j + 13, k + 47, Block.stoneBrick.blockID);
		world.setBlockAndMetadata(i + 7, j + 20, k + 9, Block.cloth.blockID, 15);
		world.setBlockAndMetadata(i + 7, j + 20, k + 41, Block.cloth.blockID, 15);
		world.setBlock(i + 8, j + 0, k + 0, Block.stoneBrick.blockID);
		world.setBlock(i + 8, j + 0, k + 3, Block.stoneBrick.blockID);
		world.setBlock(i + 8, j + 0, k + 4, Block.stoneDoubleSlab.blockID);
		world.setBlock(i + 8, j + 0, k + 5, Block.stoneDoubleSlab.blockID);
		world.setBlock(i + 8, j + 0, k + 6, Block.glowStone.blockID);
		world.setBlockAndMetadata(i + 8, j + 0, k + 7, Block.cloth.blockID, 11);
		world.setBlockAndMetadata(i + 8, j + 0, k + 8, Block.cloth.blockID, 11);
		world.setBlock(i + 8, j + 0, k + 9, Block.glowStone.blockID);
		world.setBlockAndMetadata(i + 8, j + 0, k + 10, Block.cloth.blockID, 11);
		world.setBlockAndMetadata(i + 8, j + 0, k + 11, Block.cloth.blockID, 11);
		world.setBlock(i + 8, j + 0, k + 12, Block.glowStone.blockID);
		world.setBlock(i + 8, j + 0, k + 13, Block.stoneDoubleSlab.blockID);
		world.setBlock(i + 8, j + 0, k + 14, Block.stoneDoubleSlab.blockID);
		world.setBlock(i + 8, j + 0, k + 15, Block.obsidian.blockID);
		world.setBlock(i + 8, j + 0, k + 16, Block.glowStone.blockID);
		world.setBlockAndMetadata(i + 8, j + 0, k + 17, Block.cloth.blockID, 11);
		world.setBlockAndMetadata(i + 8, j + 0, k + 18, Block.cloth.blockID, 11);
		world.setBlockAndMetadata(i + 8, j + 0, k + 19, Block.cloth.blockID, 11);
		world.setBlockAndMetadata(i + 8, j + 0, k + 20, Block.cloth.blockID, 11);
		world.setBlockAndMetadata(i + 8, j + 0, k + 21, Block.cloth.blockID, 11);
		world.setBlock(i + 8, j + 0, k + 22, Block.glowStone.blockID);
		world.setBlockAndMetadata(i + 8, j + 0, k + 23, Block.cloth.blockID, 11);
		world.setBlockAndMetadata(i + 8, j + 0, k + 24, Block.cloth.blockID, 11);
		world.setBlockAndMetadata(i + 8, j + 0, k + 25, Block.cloth.blockID, 11);
		world.setBlockAndMetadata(i + 8, j + 0, k + 26, Block.cloth.blockID, 11);
		world.setBlockAndMetadata(i + 8, j + 0, k + 27, Block.cloth.blockID, 11);
		world.setBlock(i + 8, j + 0, k + 28, Block.glowStone.blockID);
		world.setBlockAndMetadata(i + 8, j + 0, k + 29, Block.cloth.blockID, 11);
		world.setBlockAndMetadata(i + 8, j + 0, k + 30, Block.cloth.blockID, 11);
		world.setBlockAndMetadata(i + 8, j + 0, k + 31, Block.cloth.blockID, 11);
		world.setBlockAndMetadata(i + 8, j + 0, k + 32, Block.cloth.blockID, 11);
		world.setBlockAndMetadata(i + 8, j + 0, k + 33, Block.cloth.blockID, 11);
		world.setBlock(i + 8, j + 0, k + 34, Block.glowStone.blockID);
		world.setBlock(i + 8, j + 0, k + 35, Block.obsidian.blockID);
		world.setBlock(i + 8, j + 0, k + 36, Block.stoneDoubleSlab.blockID);
		world.setBlock(i + 8, j + 0, k + 37, Block.stoneDoubleSlab.blockID);
		world.setBlock(i + 8, j + 0, k + 38, Block.glowStone.blockID);
		world.setBlockAndMetadata(i + 8, j + 0, k + 39, Block.cloth.blockID, 11);
		world.setBlockAndMetadata(i + 8, j + 0, k + 40, Block.cloth.blockID, 11);
		world.setBlock(i + 8, j + 0, k + 41, Block.glowStone.blockID);
		world.setBlockAndMetadata(i + 8, j + 0, k + 42, Block.cloth.blockID, 11);
		world.setBlockAndMetadata(i + 8, j + 0, k + 43, Block.cloth.blockID, 11);
		world.setBlock(i + 8, j + 0, k + 44, Block.glowStone.blockID);
		world.setBlock(i + 8, j + 0, k + 45, Block.stoneDoubleSlab.blockID);
		world.setBlock(i + 8, j + 0, k + 46, Block.stoneDoubleSlab.blockID);
		world.setBlock(i + 8, j + 0, k + 47, Block.stoneBrick.blockID);
		world.setBlock(i + 8, j + 0, k + 50, Block.stoneBrick.blockID);
		world.setBlock(i + 8, j + 1, k + 3, Block.stoneBrick.blockID);
		world.setBlock(i + 8, j + 1, k + 47, Block.stoneBrick.blockID);
		world.setBlock(i + 8, j + 2, k + 3, Block.stoneBrick.blockID);
		world.setBlock(i + 8, j + 2, k + 47, Block.stoneBrick.blockID);
		world.setBlock(i + 8, j + 3, k + 3, Block.stoneBrick.blockID);
		world.setBlock(i + 8, j + 3, k + 47, Block.stoneBrick.blockID);
		world.setBlock(i + 8, j + 4, k + 3, Block.stoneBrick.blockID);
		world.setBlock(i + 8, j + 4, k + 47, Block.stoneBrick.blockID);
		world.setBlock(i + 8, j + 5, k + 3, Block.stoneBrick.blockID);
		world.setBlock(i + 8, j + 5, k + 47, Block.stoneBrick.blockID);
		world.setBlockAndMetadata(i + 8, j + 6, k + 3, Block.stoneBrick.blockID, 1);
		world.setBlock(i + 8, j + 6, k + 6, Block.netherFence.blockID);
		world.setBlock(i + 8, j + 6, k + 8, Block.netherFence.blockID);
		world.setBlock(i + 8, j + 6, k + 10, Block.netherFence.blockID);
		world.setBlock(i + 8, j + 6, k + 12, Block.netherFence.blockID);
		world.setBlock(i + 8, j + 6, k + 38, Block.netherFence.blockID);
		world.setBlock(i + 8, j + 6, k + 40, Block.netherFence.blockID);
		world.setBlock(i + 8, j + 6, k + 42, Block.netherFence.blockID);
		world.setBlock(i + 8, j + 6, k + 44, Block.netherFence.blockID);
		world.setBlock(i + 8, j + 6, k + 47, Block.stoneBrick.blockID);
		world.setBlockAndMetadata(i + 8, j + 7, k + 3, Block.stoneBrick.blockID, 1);
		world.setBlockAndMetadata(i + 8, j + 7, k + 4, Block.stoneSingleSlab.blockID, 13);
		world.setBlock(i + 8, j + 7, k + 6, Block.fence.blockID);
		world.setBlock(i + 8, j + 7, k + 8, Block.fence.blockID);
		world.setBlock(i + 8, j + 7, k + 10, Block.fence.blockID);
		world.setBlock(i + 8, j + 7, k + 12, Block.fence.blockID);
		world.setBlockAndMetadata(i + 8, j + 7, k + 14, Block.stoneSingleSlab.blockID, 13);
		world.setBlockAndMetadata(i + 8, j + 7, k + 36, Block.stoneSingleSlab.blockID, 13);
		world.setBlock(i + 8, j + 7, k + 38, Block.fence.blockID);
		world.setBlock(i + 8, j + 7, k + 40, Block.fence.blockID);
		world.setBlock(i + 8, j + 7, k + 42, Block.fence.blockID);
		world.setBlock(i + 8, j + 7, k + 44, Block.fence.blockID);
		world.setBlockAndMetadata(i + 8, j + 7, k + 46, Block.stoneSingleSlab.blockID, 13);
		world.setBlock(i + 8, j + 7, k + 47, Block.stoneBrick.blockID);
		world.setBlock(i + 8, j + 8, k + 3, Block.fence.blockID);
		world.setBlock(i + 8, j + 8, k + 4, Block.wood.blockID);
		world.setBlockAndMetadata(i + 8, j + 8, k + 5, Block.stoneBrick.blockID, 3);
		world.setBlockAndMetadata(i + 8, j + 8, k + 6, Block.stoneBrick.blockID, 3);
		world.setBlockAndMetadata(i + 8, j + 8, k + 7, Block.stoneBrick.blockID, 3);
		world.setBlockAndMetadata(i + 8, j + 8, k + 8, Block.stoneBrick.blockID, 3);
		world.setBlockAndMetadata(i + 8, j + 8, k + 9, Block.stoneBrick.blockID, 3);
		world.setBlockAndMetadata(i + 8, j + 8, k + 10, Block.stoneBrick.blockID, 3);
		world.setBlockAndMetadata(i + 8, j + 8, k + 11, Block.stoneBrick.blockID, 3);
		world.setBlockAndMetadata(i + 8, j + 8, k + 12, Block.stoneBrick.blockID, 3);
		world.setBlockAndMetadata(i + 8, j + 8, k + 13, Block.stoneBrick.blockID, 3);
		world.setBlock(i + 8, j + 8, k + 14, Block.wood.blockID);
		world.setBlockAndMetadata(i + 8, j + 8, k + 15, Block.stairCompactPlanks.blockID, 3);
		world.setBlockAndMetadata(i + 8, j + 8, k + 16, Block.stoneSingleSlab.blockID, 2);
		world.setBlockAndMetadata(i + 8, j + 8, k + 17, Block.stoneSingleSlab.blockID, 2);
		world.setBlockAndMetadata(i + 8, j + 8, k + 18, Block.stoneSingleSlab.blockID, 2);
		world.setBlockAndMetadata(i + 8, j + 8, k + 19, Block.stoneSingleSlab.blockID, 2);
		world.setBlockAndMetadata(i + 8, j + 8, k + 20, Block.stoneSingleSlab.blockID, 2);
		world.setBlockAndMetadata(i + 8, j + 8, k + 21, Block.stoneSingleSlab.blockID, 2);
		world.setBlockAndMetadata(i + 8, j + 8, k + 22, Block.stoneSingleSlab.blockID, 2);
		world.setBlockAndMetadata(i + 8, j + 8, k + 23, Block.stoneSingleSlab.blockID, 2);
		world.setBlockAndMetadata(i + 8, j + 8, k + 24, Block.stoneSingleSlab.blockID, 2);
		world.setBlockAndMetadata(i + 8, j + 8, k + 25, Block.stoneSingleSlab.blockID, 2);
		world.setBlockAndMetadata(i + 8, j + 8, k + 26, Block.stoneSingleSlab.blockID, 2);
		world.setBlockAndMetadata(i + 8, j + 8, k + 27, Block.stoneSingleSlab.blockID, 2);
		world.setBlockAndMetadata(i + 8, j + 8, k + 28, Block.stoneSingleSlab.blockID, 2);
		world.setBlockAndMetadata(i + 8, j + 8, k + 29, Block.stoneSingleSlab.blockID, 2);
		world.setBlockAndMetadata(i + 8, j + 8, k + 30, Block.stoneSingleSlab.blockID, 2);
		world.setBlockAndMetadata(i + 8, j + 8, k + 31, Block.stoneSingleSlab.blockID, 2);
		world.setBlockAndMetadata(i + 8, j + 8, k + 32, Block.stoneSingleSlab.blockID, 2);
		world.setBlockAndMetadata(i + 8, j + 8, k + 33, Block.stoneSingleSlab.blockID, 2);
		world.setBlockAndMetadata(i + 8, j + 8, k + 34, Block.stoneSingleSlab.blockID, 2);
		world.setBlockAndMetadata(i + 8, j + 8, k + 35, Block.stairCompactPlanks.blockID, 2);
		world.setBlock(i + 8, j + 8, k + 36, Block.wood.blockID);
		world.setBlockAndMetadata(i + 8, j + 8, k + 37, Block.stoneBrick.blockID, 3);
		world.setBlockAndMetadata(i + 8, j + 8, k + 38, Block.stoneBrick.blockID, 3);
		world.setBlockAndMetadata(i + 8, j + 8, k + 39, Block.stoneBrick.blockID, 3);
		world.setBlockAndMetadata(i + 8, j + 8, k + 40, Block.stoneBrick.blockID, 3);
		world.setBlockAndMetadata(i + 8, j + 8, k + 41, Block.stoneBrick.blockID, 3);
		world.setBlockAndMetadata(i + 8, j + 8, k + 42, Block.stoneBrick.blockID, 3);
		world.setBlockAndMetadata(i + 8, j + 8, k + 43, Block.stoneBrick.blockID, 3);
		world.setBlockAndMetadata(i + 8, j + 8, k + 44, Block.stoneBrick.blockID, 3);
		world.setBlockAndMetadata(i + 8, j + 8, k + 45, Block.stoneBrick.blockID, 3);
		world.setBlock(i + 8, j + 8, k + 46, Block.wood.blockID);
		world.setBlock(i + 8, j + 8, k + 47, Block.fence.blockID);
		world.setBlock(i + 8, j + 9, k + 6, Block.stoneSingleSlab.blockID);
		world.setBlock(i + 8, j + 9, k + 7, Block.stoneBrick.blockID);
		world.setBlock(i + 8, j + 9, k + 8, Block.stoneBrick.blockID);
		world.setBlock(i + 8, j + 9, k + 9, Block.stoneBrick.blockID);
		world.setBlock(i + 8, j + 9, k + 10, Block.stoneSingleSlab.blockID);
		world.setBlock(i + 8, j + 9, k + 11, Block.stoneSingleSlab.blockID);
		world.setBlock(i + 8, j + 9, k + 12, Block.stoneSingleSlab.blockID);
		world.setBlock(i + 8, j + 9, k + 38, Block.stoneSingleSlab.blockID);
		world.setBlock(i + 8, j + 9, k + 39, Block.stoneSingleSlab.blockID);
		world.setBlock(i + 8, j + 9, k + 40, Block.stoneSingleSlab.blockID);
		world.setBlock(i + 8, j + 9, k + 41, Block.stoneBrick.blockID);
		world.setBlock(i + 8, j + 9, k + 42, Block.stoneBrick.blockID);
		world.setBlock(i + 8, j + 9, k + 43, Block.stoneBrick.blockID);
		world.setBlock(i + 8, j + 9, k + 44, Block.stoneSingleSlab.blockID);
		world.setBlockAndMetadata(i + 8, j + 10, k + 7, Block.stoneSingleSlab.blockID, 5);
		world.setBlock(i + 8, j + 10, k + 8, Block.stoneBrick.blockID);
		world.setBlock(i + 8, j + 10, k + 9, Block.stoneBrick.blockID);
		world.setBlock(i + 8, j + 10, k + 41, Block.stoneBrick.blockID);
		world.setBlock(i + 8, j + 10, k + 42, Block.stoneBrick.blockID);
		world.setBlockAndMetadata(i + 8, j + 10, k + 43, Block.stoneSingleSlab.blockID, 5);
		world.setBlock(i + 8, j + 11, k + 3, Block.fence.blockID);
		world.setBlock(i + 8, j + 11, k + 8, Block.stoneBrick.blockID);
		world.setBlock(i + 8, j + 11, k + 9, Block.stoneBrick.blockID);
		world.setBlock(i + 8, j + 11, k + 41, Block.stoneBrick.blockID);
		world.setBlock(i + 8, j + 11, k + 42, Block.stoneBrick.blockID);
		world.setBlock(i + 8, j + 11, k + 47, Block.fence.blockID);
		world.setBlock(i + 8, j + 12, k + 3, Block.stoneBrick.blockID);
		world.setBlock(i + 8, j + 12, k + 8, Block.stoneBrick.blockID);
		world.setBlock(i + 8, j + 12, k + 9, Block.stoneBrick.blockID);
		world.setBlock(i + 8, j + 12, k + 15, Block.stoneBrick.blockID);
		world.setBlock(i + 8, j + 12, k + 35, Block.stoneBrick.blockID);
		world.setBlock(i + 8, j + 12, k + 41, Block.stoneBrick.blockID);
		world.setBlock(i + 8, j + 12, k + 42, Block.stoneBrick.blockID);
		world.setBlock(i + 8, j + 12, k + 47, Block.stoneBrick.blockID);
		world.setBlock(i + 8, j + 13, k + 3, Block.stoneBrick.blockID);
		world.setBlockAndMetadata(i + 8, j + 13, k + 4, Block.stoneSingleSlab.blockID, 2);
		world.setBlockAndMetadata(i + 8, j + 13, k + 5, Block.stoneSingleSlab.blockID, 2);
		world.setBlockAndMetadata(i + 8, j + 13, k + 6, Block.stoneSingleSlab.blockID, 2);
		world.setBlock(i + 8, j + 13, k + 7, Block.planks.blockID);
		world.setBlock(i + 8, j + 13, k + 8, Block.planks.blockID);
		world.setBlock(i + 8, j + 13, k + 9, Block.stoneBrick.blockID);
		world.setBlock(i + 8, j + 13, k + 11, Block.planks.blockID);
		world.setBlockAndMetadata(i + 8, j + 13, k + 12, Block.stoneSingleSlab.blockID, 2);
		world.setBlockAndMetadata(i + 8, j + 13, k + 13, Block.stoneSingleSlab.blockID, 2);
		world.setBlockAndMetadata(i + 8, j + 13, k + 14, Block.stoneSingleSlab.blockID, 2);
		world.setBlock(i + 8, j + 13, k + 15, Block.stoneBrick.blockID);
		world.setBlock(i + 8, j + 13, k + 35, Block.stoneBrick.blockID);
		world.setBlockAndMetadata(i + 8, j + 13, k + 36, Block.stoneSingleSlab.blockID, 2);
